#VRML_SIM V8.3.2 utf8
WorldInfo {
  basicTimeStep 16
}
Viewpoint {
  orientation -0.00505924 -0.999245 -0.0385142 3.8261
  position 19.7618 3.02288 -24.3005
}
Background {
  skyColor [
    0.4 0.7 1
  ]
}
Ceiling {
  translation 0 3 0
  size 5 5
}
DirectionalLight {
  ambientIntensity 1
  direction -0.1 -0.5 -0.3
}
RectangleArena {
  floorSize 5 5
}
FloorLight {
  translation -2.00175 -8.88178e-16 1.89667
}
FloorLight {
  translation 2.00366 2.22044e-15 -2.13347
}
DEF Swing Robot {
  translation 0 2.2 0
  rotation 1 0 0 -1.5708
  children [
    DEF RArm Transform {
      translation 0 0.25 -0.04
      children [
        HingeJoint {
          jointParameters HingeJointParameters {
            position -0.260199
            axis 0 1 0
            anchor 0 1 0
            minStop -3.1416
            maxStop 3.1416
            dampingConstant 1
          }
          endPoint Solid {
            translation 0.0383358 0.00148816 -0.759961
            rotation -0.998356 0.0405011 -0.0405573 -1.5748
            children [
              Transform {
                translation 0 -0.755 0
                children [
                  DEF MidHJ HingeJoint {
                    jointParameters HingeJointParameters {
                      axis 0 0 1
                      anchor 0 0 1
                      minStop -3.14159
                      maxStop 3.14159
                    }
                    endPoint Solid {
                      translation 0 -0.07 0
                      children [
                        Transform {
                          translation 0 -0.07 0
                          children [
                            DEF MidHJ HingeJoint {
                              jointParameters HingeJointParameters {
                                axis 0 0 1
                                anchor 0 0 1
                                minStop -3.14159
                                maxStop 3.14159
                              }
                              endPoint Solid {
                                translation 0 -0.16 0
                                children [
                                  Transform {
                                    translation 0 -0.14 0.25
                                    children [
                                      Solid {
                                        children [
                                          DEF SeatCon Connector {
                                            translation 0 0 0.25
                                            rotation 1 0 0 -1.5708
                                            isLocked TRUE
                                            autoLock TRUE
                                            distanceTolerance 0.05
                                            numberOfRotations 0
                                            snap FALSE
                                          }
                                          Shape {
                                            appearance Appearance {
                                              material Material {
                                              }
                                            }
                                            geometry DEF Seat Box {
                                              size 0.17 0.02 0.5
                                            }
                                          }
                                        ]
                                        boundingObject USE Seat
                                        physics Physics {
                                          density -1
                                          mass 1.0366
                                        }
                                      }
                                    ]
                                  }
                                  Shape {
                                    appearance Appearance {
                                      material Material {
                                      }
                                    }
                                    geometry Cylinder {
                                      height 0.28
                                      radius 0.009
                                    }
                                  }
                                ]
                                boundingObject DEF LMIDVBAR Cylinder {
                                  height 0.28
                                  radius 0.009
                                }
                                physics Physics {
                                  density -1
                                  mass 0.1631
                                }
                              }
                            }
                          ]
                        }
                        Shape {
                          appearance Appearance {
                            material Material {
                            }
                          }
                          geometry Cylinder {
                            height 0.12
                            radius 0.009
                          }
                        }
                      ]
                      boundingObject DEF LMIDVBAR Cylinder {
                        height 0.12
                        radius 0.009
                      }
                      physics Physics {
                        density -1
                        mass 0.2475
                      }
                    }
                  }
                ]
              }
              DEF RVBar Shape {
                appearance Appearance {
                  material Material {
                  }
                }
                geometry Cylinder {
                  height 1.46
                  radius 0.009
                }
              }
            ]
            boundingObject USE RVBar
            physics Physics {
              density -1
              mass 0.948
              centerOfMass [
                0 0 0
              ]
            }
            linearVelocity -0.125755 -0.00672103 5.17038e-06
            angularVelocity -6.85054e-06 4.91392e-06 -0.15913
          }
        }
      ]
    }
    DEF LArm Transform {
      translation 0 -0.25 -0.04
      children [
        HingeJoint {
          jointParameters HingeJointParameters {
            position -0.25988
            axis 0 1 0
            anchor 0 1 0
            minStop -3.1416
            maxStop 3.1416
            dampingConstant 1
          }
          endPoint Solid {
            translation 0.03786 0.00027734 -0.756609
            rotation -0.998366 0.0403964 -0.0404134 -1.57302
            children [
              Transform {
                translation 0 -0.755 0
                children [
                  HingeJoint {
                    jointParameters HingeJointParameters {
                      axis 0 0 1
                      anchor 0 0 1
                      minStop -3.14159
                      maxStop 3.14159
                    }
                    endPoint Solid {
                      translation 0 -0.07 0
                      children [
                        Transform {
                          translation 0 -0.09 0
                          children [
                            DEF MidHJ HingeJoint {
                              jointParameters HingeJointParameters {
                                axis 0 0 1
                                anchor 0 0 1
                                minStop -3.14159
                                maxStop 3.14159
                              }
                              endPoint Solid {
                                translation 0 -0.14 0
                                children [
                                  DEF SeatCon Connector {
                                    translation 0 -0.12 0
                                    rotation 1 0 0 1.5708
                                    isLocked TRUE
                                    autoLock TRUE
                                    distanceTolerance 0.03
                                    numberOfRotations 0
                                    snap FALSE
                                  }
                                  Shape {
                                    appearance Appearance {
                                      material Material {
                                      }
                                    }
                                    geometry Cylinder {
                                      height 0.28
                                      radius 0.009
                                    }
                                  }
                                ]
                                boundingObject DEF LMIDVBAR Cylinder {
                                  height 0.28
                                  radius 0.009
                                }
                                physics Physics {
                                  density -1
                                  mass 0.1631
                                }
                              }
                            }
                          ]
                        }
                        Shape {
                          appearance Appearance {
                            material Material {
                            }
                          }
                          geometry Cylinder {
                            height 0.12
                            radius 0.009
                          }
                        }
                      ]
                      boundingObject DEF LMIDVBAR Cylinder {
                        height 0.12
                        radius 0.009
                      }
                      physics Physics {
                        density -1
                        mass 0.2475
                      }
                    }
                  }
                ]
              }
              DEF SVBar2 Shape {
                appearance Appearance {
                  material Material {
                  }
                }
                geometry Cylinder {
                  height 1.46
                  radius 0.009
                }
              }
            ]
            boundingObject USE SVBar2
            physics Physics {
              density -1
              mass 0.948
              centerOfMass [
                0 0 0
              ]
            }
            linearVelocity -0.120374 -0.0062432 4.73841e-06
            angularVelocity -6.12231e-06 5.61349e-06 -0.159131
          }
        }
      ]
    }
    DEF SHBarShape Shape {
      appearance DEF SwingApp Appearance {
        material Material {
          diffuseColor 0.7 0.4 0.8
        }
        texture ImageTexture {
        }
      }
      geometry DEF SHBar Cylinder {
        height 0.5
        radius 0.05
      }
    }
  ]
  name "Swing"
  boundingObject USE SHBarShape
  selfCollision TRUE
}
