#VRML_SIM V8.3.2 utf8
WorldInfo {
  basicTimeStep 16
}
Viewpoint {
  orientation 0.00745552 0.998053 0.0619193 3.28282
  position -4.66619 4.6961 -31.9328
}
Background {
  skyColor [
    0.4 0.7 1
  ]
}
Nao {
  hidden position_0_0 1.76895e-11
  hidden position2_0_0 -2.77877e-08
  hidden position_0_1 -6.03594e-07
  hidden position2_0_1 3.00333e-07
  hidden position_0_2 -6.6191e-07
  hidden position2_0_2 3.10221e-07
  hidden position_0_3 1.16359e-06
  hidden position_0_4 9.7018e-07
  hidden linearVelocity_0 0.269981 -0.00223048 6.11282e-07
  hidden angularVelocity_0 4.94721e-06 3.90946e-06 0.204823
  hidden translation_11 -2.63753e-07 -6.11565e-09 0.126493
  hidden rotation_11 -0.0155705 0.999879 -0.000636497 -2.7791e-08
  hidden linearVelocity_11 0.244068 -0.00243944 1.23577e-06
  hidden angularVelocity_11 4.94699e-06 3.90941e-06 0.204823
  hidden translation_18 -1.79811e-06 -0.0979997 0.10003
  hidden rotation_18 -0.345598 0.840129 -0.418026 -7.18455e-07
  hidden position_18_0 1.90699e-07
  hidden linearVelocity_18 0.257847 0.00125615 5.59783e-07
  hidden angularVelocity_18 4.54336e-06 2.4726e-06 0.204823
  hidden translation_19 0.105 -0.0149997 3.24001e-05
  hidden rotation_19 0.0448889 0.995446 0.0840981 2.86238e-06
  hidden position_19_0 1.59917e-07
  hidden linearVelocity_19 0.257888 0.0141132 6.38331e-08
  hidden angularVelocity_19 2.35288e-05 1.57772e-06 0.204822
  hidden translation_20 -6.31693e-07 2.70657e-07 3.35166e-05
  hidden rotation_20 0.254679 0.964029 0.0760727 2.9847e-06
  hidden position_20_0 4.81699e-06
  hidden linearVelocity_20 0.257341 0.0249571 -2.4368e-07
  hidden angularVelocity_20 2.31049e-05 1.08681e-06 0.204822
  hidden translation_21 0.0559497 2.718e-07 3.47777e-05
  hidden rotation_21 0.0885352 0.994968 0.0469007 4.81167e-06
  hidden position_21_0 -3.92616e-06
  hidden position_21_1 -2.61326e-11
  hidden position_21_2 1.51857e-10
  hidden linearVelocity_21 0.256424 0.0381928 -5.23365e-07
  hidden angularVelocity_21 2.01531e-06 -1.06665e-06 0.204821
  hidden translation_22 0.0689991 -0.0129997 -0.0049627
  hidden rotation_22 -1.07933e-06 -1 -8.52394e-07 -0.960004
  hidden position_22_0 3.87645e-10
  hidden linearVelocity_22 0.258823 0.0460802 -7.94336e-07
  hidden angularVelocity_22 1.62238e-06 -2.61122e-06 0.204826
  hidden translation_24 0.0140003 -3.30783e-10 -1.53457e-07
  hidden rotation_24 -1.29483e-11 -1 -2.42893e-11 -0.96
  hidden position_24_0 3.74716e-11
  hidden linearVelocity_24 0.261302 0.0466812 -8.06344e-07
  hidden angularVelocity_24 1.63171e-06 -2.61343e-06 0.204826
  hidden translation_25 0.0140003 -2.43133e-10 -1.4555e-07
  hidden rotation_25 1.45456e-14 -1 2.64766e-14 -0.96
  hidden linearVelocity_25 0.263216 0.0449953 -8.4308e-07
  hidden angularVelocity_25 1.63171e-06 -2.61343e-06 0.204826
  hidden translation_26 0.0690011 0.013 -0.00500041
  hidden rotation_26 1.95358e-13 -1 1.40972e-13 -0.96
  hidden position_26_0 7.83723e-11
  hidden linearVelocity_26 0.258825 0.0460801 -5.05823e-07
  hidden angularVelocity_26 2.01531e-06 -1.06665e-06 0.204821
  hidden translation_27 0.0140003 -3.29982e-10 -1.53456e-07
  hidden rotation_27 7.47114e-14 -1 9.1541e-14 -0.96
  hidden position_27_0 3.74715e-11
  hidden linearVelocity_27 0.261304 0.0466811 -5.27007e-07
  hidden angularVelocity_27 2.01531e-06 -1.06665e-06 0.204821
  hidden translation_28 0.0140003 -2.43441e-10 -1.45549e-07
  hidden rotation_28 1.40647e-14 -1 2.75735e-14 -0.96
  hidden linearVelocity_28 0.263218 0.0449953 -5.54568e-07
  hidden angularVelocity_28 2.01531e-06 -1.06665e-06 0.204821
  hidden translation_29 0.0490006 -7.7407e-10 -0.0260009
  hidden rotation_29 8.20169e-05 1 -0.000750038 1.51857e-10
  hidden position_29_0 2.14807e-11
  hidden linearVelocity_29 0.262238 0.0426179 -5.57343e-07
  hidden angularVelocity_29 2.01531e-06 -1.06665e-06 0.204821
  hidden translation_30 0.0140003 1.24993e-10 1.33821e-07
  hidden rotation_30 -1.36309e-14 1 2.6022e-14 -0.96
  hidden linearVelocity_30 0.261155 0.044927 -5.34684e-07
  hidden angularVelocity_30 2.01531e-06 -1.06665e-06 0.204821
  hidden translation_31 -1.85624e-06 0.0979997 0.10003
  hidden rotation_31 0.744609 0.604412 -0.283273 -1.09513e-06
  hidden position_31_0 -2.87056e-06
  hidden linearVelocity_31 0.257812 0.00125569 6.15065e-07
  hidden angularVelocity_31 5.50093e-06 5.17022e-06 0.204825
  hidden translation_32 0.105 0.0149997 3.26466e-05
  hidden rotation_32 -0.126418 0.988499 0.0829922 2.85789e-06
  hidden position_32_0 -3.16456e-06
  hidden linearVelocity_32 0.257843 0.0141124 1.22224e-07
  hidden angularVelocity_32 -1.76651e-05 5.71882e-06 0.204826
  hidden translation_33 -6.89928e-07 -2.21808e-07 3.37623e-05
  hidden rotation_33 -0.421235 0.902718 -0.0875316 3.16048e-06
  hidden position_33_0 1.00759e-07
  hidden linearVelocity_33 0.257296 0.0249562 -7.02628e-08
  hidden angularVelocity_33 -1.66419e-05 -8.32343e-06 0.204827
  hidden translation_34 0.0559497 -2.20732e-07 3.50229e-05
  hidden rotation_34 0.000104824 0.998648 0.0519838 4.78329e-06
  hidden position_34_0 -5.01638e-06
  hidden position_34_1 -2.61441e-11
  hidden position_34_2 1.51869e-10
  hidden linearVelocity_34 0.25638 0.038192 1.99537e-07
  hidden angularVelocity_34 -1.24794e-08 -6.54469e-06 0.204828
  hidden translation_35 0.068999 -0.0130002 -0.00496246
  hidden rotation_35 9.50997e-07 -1 1.33668e-07 -0.960005
  hidden position_35_0 -3.76215e-12
  hidden linearVelocity_35 0.258779 0.0460793 2.40671e-07
  hidden angularVelocity_35 5.39064e-07 -5.28617e-06 0.204825
  hidden translation_37 0.0140003 -3.27563e-10 -1.53457e-07
  hidden rotation_37 9.99273e-11 -1 9.85028e-11 -0.96
  hidden position_37_0 3.74714e-11
  hidden linearVelocity_37 0.261257 0.0466803 2.49621e-07
  hidden angularVelocity_37 5.41212e-07 -5.2855e-06 0.204825
  hidden translation_38 0.0140003 -2.40937e-10 -1.4555e-07
  hidden rotation_38 1.38243e-14 -1 2.62211e-14 -0.96
  hidden linearVelocity_38 0.263171 0.0449944 2.01023e-07
  hidden angularVelocity_38 5.41212e-07 -5.2855e-06 0.204825
  hidden translation_39 0.0690011 0.013 -0.00500041
  hidden rotation_39 1.93027e-13 -1 1.3839e-13 -0.96
  hidden position_39_0 7.83616e-11
  hidden linearVelocity_39 0.258781 0.0460795 4.5178e-07
  hidden angularVelocity_39 -1.24793e-08 -6.54469e-06 0.204828
  hidden translation_40 0.0140003 -3.27483e-10 -1.53457e-07
  hidden rotation_40 7.53125e-14 -1 9.21421e-14 -0.96
  hidden position_40_0 3.74699e-11
  hidden linearVelocity_40 0.26126 0.0466806 4.71095e-07
  hidden angularVelocity_40 -1.24793e-08 -6.54469e-06 0.204828
  hidden translation_41 0.0140003 -2.40887e-10 -1.4555e-07
  hidden rotation_41 1.43052e-14 -1 2.65367e-14 -0.96
  hidden linearVelocity_41 0.263174 0.0449947 4.17278e-07
  hidden angularVelocity_41 -1.24793e-08 -6.54469e-06 0.204828
  hidden translation_42 0.0490006 -7.6911e-10 -0.0260009
  hidden rotation_42 0.000166596 1 -0.000703786 1.51869e-10
  hidden position_42_0 2.14639e-11
  hidden linearVelocity_42 0.262194 0.0426172 3.41239e-07
  hidden angularVelocity_42 -1.24794e-08 -6.54469e-06 0.204828
  hidden translation_43 0.0140003 1.23177e-10 1.33822e-07
  hidden rotation_43 -1.33867e-14 1 2.60277e-14 -0.96
  hidden linearVelocity_43 0.261111 0.0449264 4.15013e-07
  hidden angularVelocity_43 -1.24794e-08 -6.54469e-06 0.204828
  hidden translation_44 9.05236e-07 -0.05 -0.0850203
  hidden rotation_44 0.0780128 0.941516 -0.327813 1.15397e-06
  hidden position_44_0 1.41162e-06
  hidden linearVelocity_44 0.290859 -0.00229889 3.70109e-07
  hidden angularVelocity_44 4.93447e-06 3.85035e-06 0.204823
  hidden translation_45 8.63084e-07 -3.77402e-09 -1.72071e-05
  hidden rotation_45 0.125259 0.990598 -0.0550069 1.41058e-06
  hidden position_45_0 -1.1
  hidden linearVelocity_45 0.297418 -0.00365759 4.55552e-07
  hidden angularVelocity_45 1.33598e-05 4.0904e-06 0.204823
  hidden translation_46 3.05661e-06 -1.4741e-09 -1.46258e-05
  hidden rotation_46 -4.4133e-08 1 1.13925e-07 -1.1
  hidden position_46_0 0.00522837
  hidden linearVelocity_46 0.300674 0.00956528 2.40741e-07
  hidden angularVelocity_46 1.3346e-05 4.06808e-06 0.204822
  hidden translation_47 -8.17536e-06 -1.03851e-08 -0.100018
  hidden rotation_47 1.35187e-06 1 7.75254e-07 0.00522837
  hidden position_47_0 1.07514e-07
  hidden linearVelocity_47 0.309425 0.0305531 2.14114e-06
  hidden angularVelocity_47 1.52371e-05 -5.42359e-05 0.267059
  hidden translation_48 -7.05735e-06 -5.73113e-09 -0.102913
  hidden rotation_48 0.0948576 0.993171 -0.0679161 1.07315e-07
  hidden position_48_0 9.42395e-08
  hidden linearVelocity_48 0.315692 0.0414551 4.0652e-06
  hidden angularVelocity_48 1.52396e-05 -5.42382e-05 0.267059
  hidden translation_49 5.51902e-07 -2.77553e-09 -1.18819e-05
  hidden rotation_49 0.0222265 0.997009 -0.074025 9.41505e-08
  hidden linearVelocity_49 0.314049 0.0538255 6.70818e-06
  hidden angularVelocity_49 1.50187e-05 -5.47072e-05 0.267059
  hidden translation_50 0.0199968 -0.007 -0.0410023
  hidden rotation_50 -1.01109e-10 -3.71925e-15 1 -3.14159
  hidden linearVelocity_50 0.316342 0.0553084 6.90152e-06
  hidden angularVelocity_50 1.50187e-05 -5.47072e-05 0.267059
  hidden translation_54 4.69381e-06 0.05 -0.0850158
  hidden rotation_54 0.230168 0.935197 -0.269126 9.68379e-07
  hidden position_54_0 9.60492e-08
  hidden linearVelocity_54 0.290841 -0.00229806 3.58111e-07
  hidden angularVelocity_54 4.93546e-06 3.93685e-06 0.204823
  hidden translation_55 4.65163e-06 -1.2127e-08 -1.25834e-05
  hidden rotation_55 0.0379233 0.968125 -0.247578 9.08902e-07
  hidden position_55_0 -1.1
  hidden linearVelocity_55 0.297392 -0.00365587 4.42192e-07
  hidden angularVelocity_55 1.14916e-05 4.21377e-06 0.204822
  hidden translation_56 6.84511e-06 -9.83386e-09 -1.00026e-05
  hidden rotation_56 -5.98267e-08 1 2.89168e-07 -1.1
  hidden position_56_0 0.00522837
  hidden linearVelocity_56 0.300644 0.00956788 2.31532e-07
  hidden angularVelocity_56 1.14781e-05 4.28657e-06 0.204822
  hidden translation_57 -8.17497e-06 -1.03865e-08 -0.100018
  hidden rotation_57 -5.49633e-06 1 5.64592e-06 0.00522837
  hidden position_57_0 1.07509e-07
  hidden linearVelocity_57 0.309394 0.0305557 2.18436e-06
  hidden angularVelocity_57 1.33498e-05 -5.40188e-05 0.267059
  hidden translation_58 -7.05748e-06 -5.72635e-09 -0.102913
  hidden rotation_58 -0.0962495 0.993108 0.0668792 1.0731e-07
  hidden position_58_0 -9.4905e-08
  hidden linearVelocity_58 0.315663 0.0414576 4.14456e-06
  hidden angularVelocity_58 1.33472e-05 -5.40165e-05 0.267059
  hidden translation_59 5.52146e-07 -2.77456e-09 -1.18818e-05
  hidden rotation_59 -0.104862 0.991829 0.0726588 9.46408e-08
  hidden linearVelocity_59 0.314018 0.053828 6.76895e-06
  hidden angularVelocity_59 1.30895e-05 -5.4548e-05 0.267059
  hidden translation_60 0.0199968 0.007 -0.0410023
  hidden rotation_60 -1.0112e-10 -1.09912e-14 1 -3.14159
  hidden linearVelocity_60 0.31631 0.055311 6.9781e-06
  hidden angularVelocity_60 1.30895e-05 -5.4548e-05 0.267059
  translation -0.00301676 0.778559 -0.000186279
  rotation 0.999701 0.01727 -0.0172832 -1.57016
  controller "my_controller"
  leftHandSlot [
    Transform {
      translation 0.06 0 0
      children [
        Connector {
          isLocked TRUE
          autoLock TRUE
          distanceTolerance 0.05
          axisTolerance 3.14159
          rotationTolerance 3.14159
          numberOfRotations 0
          snap FALSE
        }
      ]
    }
  ]
  rightHandSlot [
    Transform {
      translation 0.06 0 0
      children [
        Connector {
          isLocked TRUE
          autoLock TRUE
          distanceTolerance 0.05
          axisTolerance 3.14159
          rotationTolerance 3.14159
          numberOfRotations 0
          snap FALSE
        }
      ]
    }
  ]
}
Ceiling {
  translation 0 3 0
  size 5 5
}
DirectionalLight {
  ambientIntensity 1
  direction -0.1 -0.5 -0.3
}
RectangleArena {
  floorSize 5 5
}
FloorLight {
  translation -2.00175 -8.88178e-16 1.89667
}
FloorLight {
  translation 2.00366 2.22044e-15 -2.13347
}
DEF Swing Robot {
  translation 0 2.2 0
  rotation 1 0 0 -1.5708
  children [
    DEF RArm Transform {
      translation 0 0.25 -0.06
      children [
        HingeJoint {
          jointParameters HingeJointParameters {
            position -0.206367
            axis 0 1 0
            anchor 0 1 0
            minStop -3.1416
            maxStop 3.1416
            dampingConstant 1
          }
          endPoint Solid {
            translation -0.00282417 0.00647118 -0.756214
            rotation -0.999813 0.0136896 -0.0136487 -1.57452
            children [
              Transform {
                translation 0 -0.75 0
                children [
                  DEF SeatShape Solid {
                    translation 0 0 0.25
                    children [
                      DEF Left_Transform Transform {
                        translation 0.3 0.25 -0.1
                        children [
                          BallJoint {
                            jointParameters BallJointParameters {
                            }
                            endPoint Connector {
                              isLocked TRUE
                              distanceTolerance 0.05
                              axisTolerance 3
                              rotationTolerance 3.14159
                              numberOfRotations 0
                              snap FALSE
                            }
                          }
                        ]
                      }
                      DEF Right_Transform Transform {
                        translation 0.3 0.25 0.1
                        children [
                          BallJoint {
                            jointParameters BallJointParameters {
                            }
                            endPoint Connector {
                              isLocked TRUE
                              distanceTolerance 0.05
                              axisTolerance 3
                              rotationTolerance 3.14159
                              numberOfRotations 0
                              snap FALSE
                            }
                          }
                        ]
                      }
                      DEF C1 Connector {
                        translation 0 0 0.25
                        rotation 1 0 0 -1.5708
                        isLocked TRUE
                        autoLock TRUE
                        distanceTolerance 0.05
                        numberOfRotations 0
                        snap FALSE
                      }
                      DEF SeatCon Connector {
                        translation 0 0 0.25
                        rotation 1 0 0 -1.5708
                        autoLock TRUE
                        numberOfRotations 0
                      }
                      Shape {
                        appearance Appearance {
                          material Material {
                          }
                        }
                        geometry DEF SSeat Box {
                          size 0.1 0.01 0.5
                        }
                      }
                    ]
                    boundingObject USE SSeat
                    physics Physics {
                    }
                  }
                ]
              }
              DEF RVBar Shape {
                appearance Appearance {
                  material Material {
                  }
                }
                geometry Cylinder {
                  height 1.5
                  radius 0.05
                }
              }
            ]
            boundingObject USE RVBar
            physics Physics {
              centerOfMass [
                0 0 0
              ]
            }
            linearVelocity 0.161141 -0.000680795 -9.12927e-07
            angularVelocity 1.14198e-06 -3.90993e-06 0.204826
          }
        }
      ]
    }
    DEF LArm Transform {
      translation 0 -0.25 -0.06
      children [
        HingeJoint {
          jointParameters HingeJointParameters {
            position -0.205966
            axis 0 1 0
            anchor 0 1 0
            minStop -3.1416
            maxStop 3.1416
            dampingConstant 1
          }
          endPoint Solid {
            translation -0.00308407 0.00299342 -0.756521
            rotation -0.999818 0.0135142 -0.0134543 -1.57216
            children [
              DEF C1 Connector {
                translation 0 -0.75 0
                rotation 1 0 0 1.5708
                isLocked TRUE
                autoLock TRUE
                distanceTolerance 0.05
                numberOfRotations 0
                snap FALSE
              }
              DEF SVBar2 Shape {
                appearance Appearance {
                  material Material {
                  }
                }
                geometry Cylinder {
                  height 1.5
                  radius 0.05
                }
              }
            ]
            boundingObject USE SVBar2
            physics Physics {
              centerOfMass [
                0 0 0
              ]
            }
            linearVelocity 0.154942 -0.000894796 -8.74838e-07
            angularVelocity 1.12096e-06 -4.43296e-06 0.204825
          }
        }
      ]
    }
    DEF SHBarShape Shape {
      appearance DEF SwingApp Appearance {
        material Material {
          diffuseColor 0.7 0.4 0.8
        }
        texture ImageTexture {
        }
      }
      geometry DEF SHBar Cylinder {
        height 0.5
        radius 0.05
      }
    }
  ]
  name "Swing"
  boundingObject USE SHBarShape
  selfCollision TRUE
}
