#VRML_SIM V8.3.2 utf8
WorldInfo {
  basicTimeStep 16
}
Viewpoint {
  orientation 0.0208411 0.975263 0.220065 3.29814
  position -4.54773 14.3729 -28.9494
}
Background {
  skyColor [
    0.4 0.7 1
  ]
}
Nao {
  controller "my_controller"
  leftHandSlot [
    Transform {
      translation 0.06 0 0
      children [
        Connector {
          isLocked TRUE
          autoLock TRUE
          distanceTolerance 0.05
          axisTolerance 3.14159
          rotationTolerance 3.14159
          numberOfRotations 0
          snap FALSE
        }
      ]
    }
  ]
  rightHandSlot [
    Transform {
      translation 0.06 0 0
      children [
        Connector {
          isLocked TRUE
          autoLock TRUE
          distanceTolerance 0.05
          axisTolerance 3.14159
          rotationTolerance 3.14159
          numberOfRotations 0
          snap FALSE
        }
      ]
    }
  ]
}
Ceiling {
  translation 0 3 0
  size 5 5
}
DirectionalLight {
  ambientIntensity 1
  direction -0.1 -0.5 -0.3
}
RectangleArena {
  floorSize 5 5
}
FloorLight {
  translation -2.00175 -8.88178e-16 1.89667
}
FloorLight {
  translation 2.00366 2.22044e-15 -2.13347
}
DEF Swing Robot {
  translation 0 2.2 0
  rotation 1 0 0 -1.5708
  children [
    DEF RArm Transform {
      translation 0 0.25 -0.06
      children [
        HingeJoint {
          jointParameters HingeJointParameters {
            position -0.12585
            axis 0 1 0
            anchor 0 1 0
            minStop -3.1416
            maxStop 3.1416
            dampingConstant 1
          }
          endPoint Solid {
            translation -0.0636047 0.00630241 -0.753084
            rotation -0.999297 -0.0264206 0.0265937 -1.57482
            children [
              Transform {
                translation 0 -0.75 0
                children [
                  DEF SeatShape Solid {
                    translation 0 0 0.25
                    children [
                      DEF Left_Transform Transform {
                        translation 0.3 0.25 -0.1
                        children [
                          BallJoint {
                            jointParameters BallJointParameters {
                            }
                            endPoint Connector {
                              isLocked TRUE
                              distanceTolerance 0.05
                              axisTolerance 3
                              rotationTolerance 3.14159
                              numberOfRotations 0
                              snap FALSE
                            }
                          }
                        ]
                      }
                      DEF Right_Transform Transform {
                        translation 0.3 0.25 0.1
                        children [
                          BallJoint {
                            jointParameters BallJointParameters {
                            }
                            endPoint Connector {
                              isLocked TRUE
                              distanceTolerance 0.05
                              axisTolerance 3
                              rotationTolerance 3.14159
                              numberOfRotations 0
                              snap FALSE
                            }
                          }
                        ]
                      }
                      DEF C1 Connector {
                        translation 0 0 0.25
                        rotation 1 0 0 -1.5708
                        isLocked TRUE
                        autoLock TRUE
                        distanceTolerance 0.05
                        numberOfRotations 0
                        snap FALSE
                      }
                      DEF SeatCon Connector {
                        translation 0 0 0.25
                        rotation 1 0 0 -1.5708
                        autoLock TRUE
                        numberOfRotations 0
                      }
                      Shape {
                        appearance Appearance {
                          material Material {
                          }
                        }
                        geometry DEF SSeat Box {
                          size 0.1 0.01 0.5
                        }
                      }
                    ]
                    boundingObject USE SSeat
                    physics Physics {
                    }
                  }
                ]
              }
              DEF RVBar Shape {
                appearance Appearance {
                  material Material {
                  }
                }
                geometry Cylinder {
                  height 1.5
                  radius 0.05
                }
              }
            ]
            boundingObject USE RVBar
            physics Physics {
              centerOfMass [
                0 0 0
              ]
            }
            linearVelocity -0.0593407 0.00499538 1.55387e-06
            angularVelocity -2.07399e-06 -1.86063e-06 -0.075727
          }
        }
      ]
    }
    DEF LArm Transform {
      translation 0 -0.25 -0.06
      children [
        HingeJoint {
          jointParameters HingeJointParameters {
            position -0.125446
            axis 0 1 0
            anchor 0 1 0
            minStop -3.1416
            maxStop 3.1416
            dampingConstant 1
          }
          endPoint Solid {
            translation -0.0638862 0.00282138 -0.753322
            rotation -0.999285 -0.0266922 0.0267891 -1.57246
            children [
              DEF C1 Connector {
                translation 0 -0.75 0
                rotation 1 0 0 1.5708
                isLocked TRUE
                autoLock TRUE
                distanceTolerance 0.05
                numberOfRotations 0
                snap FALSE
              }
              DEF SVBar2 Shape {
                appearance Appearance {
                  material Material {
                  }
                }
                geometry Cylinder {
                  height 1.5
                  radius 0.05
                }
              }
            ]
            boundingObject USE SVBar2
            physics Physics {
              centerOfMass [
                0 0 0
              ]
            }
            linearVelocity -0.0570474 0.00489238 1.54114e-06
            angularVelocity -2.25382e-06 -1.74442e-06 -0.0757267
          }
        }
      ]
    }
    DEF SHBarShape Shape {
      appearance DEF SwingApp Appearance {
        material Material {
          diffuseColor 0.7 0.4 0.8
        }
        texture ImageTexture {
        }
      }
      geometry DEF SHBar Cylinder {
        height 0.5
        radius 0.05
      }
    }
  ]
  name "Swing"
  boundingObject USE SHBarShape
  selfCollision TRUE
}
