#VRML_SIM V8.3.2 utf8
WorldInfo {
  basicTimeStep 16
}
Viewpoint {
  orientation 0.0698463 0.996642 0.042734 5.05274
  position -14.9918 2.58071 5.39744
}
Background {
  skyColor [
    0.4 0.7 1
  ]
}
Ceiling {
  translation 0 3 0
  size 5 5
}
Nao {
  hidden position_0_0 1.87619e-09
  hidden position2_0_0 8.51608e-08
  hidden position_0_1 1.04489e-06
  hidden position2_0_1 -5.82126e-08
  hidden position_0_2 1.04587e-06
  hidden position2_0_2 -2.76202e-08
  hidden position_0_3 -4.98364e-08
  hidden position_0_4 6.72479e-07
  hidden linearVelocity_0 0.0173111 -0.000343082 -1.10136e-05
  hidden angularVelocity_0 5.28817e-06 1.16091e-07 0.0130427
  hidden translation_12 -1.09378e-07 -4.6723e-08 0.12648
  hidden rotation_12 0.0281605 0.999361 0.022017 8.52155e-08
  hidden linearVelocity_12 0.0156678 -0.000490578 -1.03459e-05
  hidden angularVelocity_12 5.28817e-06 1.1609e-07 0.0130427
  hidden translation_19 -1.14856e-05 -0.098 0.0999842
  hidden rotation_19 0.0852111 0.993468 -0.0758972 1.05176e-06
  hidden position_19_0 2.6005e-07
  hidden linearVelocity_19 0.016525 -0.000185889 -1.06962e-05
  hidden angularVelocity_19 5.28811e-06 1.16134e-07 0.0130427
  hidden translation_20 0.104993 -0.015 -8.98436e-06
  hidden rotation_20 0.0890246 0.996023 -0.00355038 4.60087e-07
  hidden position_20_0 1.22921e-08
  hidden linearVelocity_20 0.0164618 0.000629984 -1.06781e-05
  hidden angularVelocity_20 6.62664e-06 2.69562e-07 0.0130427
  hidden translation_21 -5.21709e-06 -8.47005e-09 -7.2205e-06
  hidden rotation_21 0.00298899 0.999909 0.0131817 5.0654e-07
  hidden position_21_0 6.50373e-09
  hidden linearVelocity_21 0.0163715 0.00131531 -1.0643e-05
  hidden angularVelocity_21 6.6415e-06 1.39966e-07 0.0130427
  hidden translation_22 0.0559462 -5.98842e-09 -5.10979e-06
  hidden rotation_22 -0.0183892 0.999671 0.0178642 1.67859e-07
  hidden position_22_0 -3.83457e-11
  hidden position_22_1 -3.88807e-11
  hidden position_22_2 2.2262e-10
  hidden linearVelocity_22 0.0162451 0.00215061 -1.05861e-05
  hidden angularVelocity_22 7.13436e-06 1.96455e-07 0.0130427
  hidden translation_23 0.069 -0.013 -0.00500004
  hidden rotation_23 4.49384e-13 -1 3.20596e-13 -0.96
  hidden position_23_0 6.70963e-11
  hidden linearVelocity_23 0.0163572 0.00266346 -1.06552e-05
  hidden angularVelocity_23 7.13436e-06 1.96455e-07 0.0130427
  hidden translation_24 0.014 -2.5075e-11 -2.18054e-08
  hidden rotation_24 1.72263e-13 -1 2.11332e-13 -0.96
  hidden position_24_0 5.23223e-11
  hidden linearVelocity_24 0.0165114 0.00271444 -1.07403e-05
  hidden angularVelocity_24 7.13436e-06 1.96455e-07 0.0130427
  hidden translation_25 0.014 -1.54137e-11 -3.93884e-09
  hidden rotation_25 3.02933e-14 -1 6.03762e-14 -0.96
  hidden linearVelocity_25 0.0166416 0.00261737 -1.081e-05
  hidden angularVelocity_25 7.13436e-06 1.96455e-07 0.0130427
  hidden translation_26 0.069 0.013 -0.00500004
  hidden rotation_26 4.47987e-13 -1 3.2563e-13 -0.96
  hidden position_26_0 6.70945e-11
  hidden linearVelocity_26 0.0163565 0.0026638 -1.06548e-05
  hidden angularVelocity_26 7.13436e-06 1.96455e-07 0.0130427
  hidden translation_27 0.014 -2.50749e-11 -2.18054e-08
  hidden rotation_27 1.74848e-13 -1 2.09829e-13 -0.96
  hidden position_27_0 5.23188e-11
  hidden linearVelocity_27 0.0165107 0.00271479 -1.07399e-05
  hidden angularVelocity_27 7.13436e-06 1.96455e-07 0.0130427
  hidden translation_28 0.014 -1.54137e-11 -3.93884e-09
  hidden rotation_28 3.05337e-14 -1 6.08871e-14 -0.96
  hidden linearVelocity_28 0.0166409 0.00261771 -1.08096e-05
  hidden angularVelocity_28 7.13436e-06 1.96455e-07 0.0130427
  hidden translation_29 0.049 -2.80318e-11 -0.026
  hidden rotation_29 0.000232604 0.999999 -0.00110426 2.2262e-10
  hidden position_29_0 1.86936e-11
  hidden linearVelocity_29 0.0165912 0.00246156 -1.07801e-05
  hidden angularVelocity_29 7.13436e-06 1.96455e-07 0.0130427
  hidden translation_30 0.014 -6.62413e-12 -8.05063e-09
  hidden rotation_30 -3.04661e-14 1 6.00682e-14 -0.96
  hidden linearVelocity_30 0.0165105 0.0026025 -1.07381e-05
  hidden angularVelocity_30 7.13436e-06 1.96455e-07 0.0130427
  hidden translation_31 3.64129e-06 0.098 0.0999905
  hidden rotation_31 -0.0536234 0.998192 -0.0271656 1.04776e-06
  hidden position_31_0 9.691e-09
  hidden linearVelocity_31 0.0165198 -0.000183636 -1.06942e-05
  hidden angularVelocity_31 5.28824e-06 1.16043e-07 0.0130427
  hidden translation_32 0.105003 0.015 -5.41274e-06
  hidden rotation_32 -0.0453897 0.998965 -0.00309588 2.86521e-07
  hidden position_32_0 -3.098e-07
  hidden linearVelocity_32 0.0164554 0.000632842 -1.06751e-05
  hidden angularVelocity_32 3.94939e-06 -3.74188e-08 0.0130427
  hidden translation_33 1.6368e-06 -8.47052e-09 -4.3497e-06
  hidden rotation_33 -0.00278624 0.993408 -0.1146 3.1752e-07
  hidden position_33_0 7.88136e-08
  hidden linearVelocity_33 0.0163648 0.00131831 -1.06078e-05
  hidden angularVelocity_33 4.11859e-06 -1.51349e-06 0.0130427
  hidden translation_34 0.0559512 -5.98916e-09 -3.07793e-06
  hidden rotation_34 0.028314 0.999573 0.00717416 1.10366e-07
  hidden position_34_0 7.55547e-11
  hidden position_34_1 7.55723e-11
  hidden position_34_2 1.70503e-10
  hidden linearVelocity_34 0.0162386 0.00215359 -1.04694e-05
  hidden angularVelocity_34 4.64281e-06 -1.45341e-06 0.0130427
  hidden translation_35 0.069 -0.013 -0.00500002
  hidden rotation_35 4.51435e-13 -1 3.21934e-13 -0.96
  hidden position_35_0 1.36648e-10
  hidden linearVelocity_35 0.0163506 0.00266649 -1.04521e-05
  hidden angularVelocity_35 4.64281e-06 -1.45341e-06 0.0130427
  hidden translation_36 0.014 -2.50758e-11 -3.79054e-09
  hidden rotation_36 1.68717e-13 -1 2.10671e-13 -0.96
  hidden position_36_0 4.30115e-11
  hidden linearVelocity_36 0.0165048 0.00271748 -1.05013e-05
  hidden angularVelocity_36 4.64281e-06 -1.45341e-06 0.0130427
  hidden translation_37 0.014 -1.53793e-11 2.83184e-09
  hidden rotation_37 3.24571e-14 -1 6.07068e-14 -0.96
  hidden linearVelocity_37 0.016635 0.0026204 -1.05585e-05
  hidden angularVelocity_37 4.64281e-06 -1.45341e-06 0.0130427
  hidden translation_38 0.069 0.013 -0.00500002
  hidden rotation_38 4.45688e-13 -1 3.227e-13 -0.96
  hidden position_38_0 1.36648e-10
  hidden linearVelocity_38 0.01635 0.00266677 -1.04519e-05
  hidden angularVelocity_38 4.64281e-06 -1.45341e-06 0.0130427
  hidden translation_39 0.014 -2.50757e-11 -3.79054e-09
  hidden rotation_39 1.75449e-13 -1 2.14097e-13 -0.96
  hidden position_39_0 4.30162e-11
  hidden linearVelocity_39 0.0165042 0.00271776 -1.05011e-05
  hidden angularVelocity_39 4.64281e-06 -1.45341e-06 0.0130427
  hidden translation_40 0.014 -1.53794e-11 2.83183e-09
  hidden rotation_40 3.20965e-14 -1 5.94446e-14 -0.96
  hidden linearVelocity_40 0.0166344 0.00262068 -1.05582e-05
  hidden angularVelocity_40 4.64281e-06 -1.45341e-06 0.0130427
  hidden translation_41 0.049 -2.80977e-11 -0.026
  hidden rotation_41 0.000308491 0.999999 -0.00144522 1.70503e-10
  hidden position_41_0 3.56297e-11
  hidden linearVelocity_41 0.0165847 0.00246457 -1.05579e-05
  hidden angularVelocity_41 4.64281e-06 -1.45341e-06 0.0130427
  hidden translation_42 0.014 -6.65884e-12 -4.48944e-09
  hidden rotation_42 -3.06239e-14 1 6.02335e-14 -0.96
  hidden linearVelocity_42 0.016504 0.0026055 -1.05135e-05
  hidden angularVelocity_42 4.64281e-06 -1.45341e-06 0.0130427
  hidden translation_43 9.82628e-06 -0.0499982 -0.0849551
  hidden rotation_43 0.651026 0.705479 0.280115 3.2408e-07
  hidden position_43_0 1.26784e-06
  hidden linearVelocity_43 0.0186363 -0.000239681 -1.1578e-05
  hidden angularVelocity_43 5.28941e-06 1.19421e-07 0.0130427
  hidden translation_44 1.04907e-05 1.85741e-06 4.71128e-05
  hidden rotation_44 0.885447 0.462118 -0.0493018 3.51531e-07
  hidden position_44_0 -1.1
  hidden linearVelocity_44 0.0190588 -0.00029201 -1.17667e-05
  hidden angularVelocity_44 3.62262e-06 -6.89963e-08 0.0130427
  hidden translation_45 -2.78977e-05 1.85598e-06 3.87134e-05
  hidden rotation_45 -1.76062e-07 1 -7.11421e-08 -1.1
  hidden position_45_0 1
  hidden linearVelocity_45 0.0191963 0.000563607 -1.18268e-05
  hidden angularVelocity_45 3.62393e-06 -6.61843e-08 0.0130427
  hidden translation_46 1.65784e-05 1.80944e-06 -0.0999822
  hidden rotation_46 1.83391e-08 1 -2.33979e-08 1
  hidden position_46_0 -2.73814e-07
  hidden linearVelocity_46 0.02004 0.00131739 -1.20574e-05
  hidden angularVelocity_46 3.6239e-06 -6.61097e-08 0.0130427
  hidden translation_47 -2.70372e-06 1.81902e-06 -0.102868
  hidden rotation_47 0.654449 0.755982 0.0136954 -2.76282e-07
  hidden position_47_0 -3.93886e-07
  hidden linearVelocity_47 0.0206459 0.0013948 -1.22253e-05
  hidden angularVelocity_47 3.62388e-06 -6.60614e-08 0.0130427
  hidden translation_48 -1.22458e-06 1.82328e-06 3.65323e-05
  hidden rotation_48 0.49433 0.869162 0.0139403 -2.41082e-07
  hidden linearVelocity_48 0.0210764 0.00182173 -1.23323e-05
  hidden angularVelocity_48 3.30908e-06 -1.34467e-07 0.0130427
  hidden translation_49 0.0199998 -0.00699817 -0.0409607
  hidden rotation_49 2.3247e-07 -4.49798e-09 1 -3.14159
  hidden linearVelocity_49 0.0212008 0.0017764 -1.23643e-05
  hidden angularVelocity_49 3.30908e-06 -1.34467e-07 0.0130427
  hidden translation_53 8.5707e-06 0.0499982 -0.0849553
  hidden rotation_53 -0.491384 0.870794 -0.0161204 4.46578e-07
  hidden position_53_0 1.12202e-06
  hidden linearVelocity_53 0.0186341 -0.000238821 -1.15248e-05
  hidden angularVelocity_53 5.28693e-06 1.1273e-07 0.0130427
  hidden translation_54 9.23515e-06 -1.73148e-06 4.67981e-05
  hidden rotation_54 -0.54026 0.837841 -0.0783646 5.5766e-07
  hidden position_54_0 -1.1
  hidden linearVelocity_54 0.019056 -0.000290909 -1.16773e-05
  hidden angularVelocity_54 6.86199e-06 2.90599e-07 0.0130427
  hidden translation_55 -2.84894e-05 -1.7508e-06 3.74369e-05
  hidden rotation_55 1.50932e-07 1 1.16161e-07 -1.1
  hidden position_55_0 1
  hidden linearVelocity_55 0.0191934 0.000564745 -1.17424e-05
  hidden angularVelocity_55 6.86068e-06 2.87754e-07 0.0130427
  hidden translation_56 1.59163e-05 -1.84831e-06 -0.0999812
  hidden rotation_56 -5.22114e-08 1 -3.13036e-08 1
  hidden position_56_0 -2.00667e-07
  hidden linearVelocity_56 0.0200371 0.00131851 -1.22028e-05
  hidden angularVelocity_56 6.86071e-06 2.87664e-07 0.0130427
  hidden translation_57 -3.92908e-06 -1.83864e-06 -0.102868
  hidden rotation_57 -0.812526 0.521735 0.259989 -2.22047e-07
  hidden position_57_0 3.51357e-07
  hidden linearVelocity_57 0.0206432 0.00139587 -1.25233e-05
  hidden angularVelocity_57 6.86073e-06 2.87615e-07 0.0130427
  hidden translation_58 -2.44993e-06 -1.83433e-06 3.65336e-05
  hidden rotation_58 -0.494213 0.813003 0.307865 -1.88878e-07
  hidden linearVelocity_58 0.0210734 0.00182285 -1.27693e-05
  hidden angularVelocity_58 7.17146e-06 3.55139e-07 0.0130427
  hidden translation_59 0.0199986 0.00699817 -0.0409607
  hidden rotation_59 2.35332e-07 4.52782e-09 1 -3.14159
  hidden linearVelocity_59 0.0211976 0.00177758 -1.28363e-05
  hidden angularVelocity_59 7.17146e-06 3.55139e-07 0.0130427
  translation -0.0167945 0.770415 -0.00033285
  rotation 0.996733 0.0573996 -0.0568202 -1.57196
  controller "my_controller"
  bodySlot [
    Connector {
      translation 0 0 -0.12
      rotation 0 1 0 3.14159
      name "RobotConnect"
      autoLock TRUE
      distanceTolerance 0.1
      numberOfRotations 0
    }
  ]
}
DirectionalLight {
  ambientIntensity 1
  direction -0.1 -0.5 -0.3
}
RectangleArena {
  floorSize 5 5
}
FloorLight {
  translation -2.00175 -8.88178e-16 1.89667
}
FloorLight {
  translation 2.00366 2.22044e-15 -2.13347
}
DEF Swing Robot {
  translation 0 2.2 0
  rotation 1 0 0 -1.5708
  children [
    DEF RArm Transform {
      translation 0 0.25 -0.06
      children [
        HingeJoint {
          jointParameters HingeJointParameters {
            position -0.208534
            axis 0 1 0
            anchor 0 1 0
            minStop -3.1416
            maxStop 3.1416
            dampingConstant 1
          }
          endPoint Solid {
            translation -0.0013357 0.00124866 -0.758033
            rotation -0.999783 0.0147303 -0.0147245 -1.57309
            children [
              Transform {
                translation 0 -0.75 0
                children [
                  DEF SeatShape Solid {
                    translation 0 0 0.25
                    children [
                      Connector {
                        rotation 1 0 0 -1.5708
                        name "SwingConnect"
                        autoLock TRUE
                        distanceTolerance 0.1
                        numberOfRotations 0
                      }
                      DEF SeatCon Connector {
                        translation 0 0 0.25
                        rotation 1 0 0 -1.5708
                        autoLock TRUE
                        numberOfRotations 0
                      }
                      Shape {
                        appearance Appearance {
                          material Material {
                          }
                        }
                        geometry DEF SSeat Box {
                          size 0.1 0.01 0.5
                        }
                      }
                    ]
                    boundingObject USE SSeat
                    physics Physics {
                    }
                  }
                ]
              }
              DEF RVBar Shape {
                appearance Appearance {
                  material Material {
                  }
                }
                geometry Cylinder {
                  height 1.5
                  radius 0.05
                }
              }
            ]
            boundingObject USE RVBar
            physics Physics {
              centerOfMass [
                0 0 0
              ]
            }
            linearVelocity 0.0102883 -1.04551e-05 -8.36474e-06
            angularVelocity 5.20051e-06 4.02249e-07 0.0130459
          }
        }
      ]
    }
    DEF LArm Transform {
      translation 0 -0.25 -0.06
      children [
        HingeJoint {
          jointParameters HingeJointParameters {
            position -0.208303
            axis 0 1 0
            anchor 0 1 0
            minStop -3.1416
            maxStop 3.1416
            dampingConstant 1
          }
          endPoint Solid {
            translation -0.00155506 0.000126213 -0.754721
            rotation -0.999786 0.0146264 -0.0146228 -1.57137
            children [
              DEF C1 Connector {
                translation 0 -0.75 0
                rotation 1 0 0 1.5708
                autoLock TRUE
                numberOfRotations 0
              }
              DEF SVBar2 Shape {
                appearance Appearance {
                  material Material {
                  }
                }
                geometry Cylinder {
                  height 1.5
                  radius 0.05
                }
              }
            ]
            boundingObject USE SVBar2
            physics Physics {
              centerOfMass [
                0 0 0
              ]
            }
            linearVelocity 0.00984551 -1.57648e-05 8.52817e-06
            angularVelocity -5.64955e-06 -2.54874e-07 0.013046
          }
        }
      ]
    }
    DEF SHBarShape Shape {
      appearance DEF SwingApp Appearance {
        material Material {
          diffuseColor 0.7 0.4 0.8
        }
        texture ImageTexture {
        }
      }
      geometry DEF SHBar Cylinder {
        height 0.5
        radius 0.05
      }
    }
  ]
  name "Swing"
  boundingObject USE SHBarShape
  selfCollision TRUE
}
