#VRML_SIM V8.3.2 utf8
WorldInfo {
  basicTimeStep 16
}
Viewpoint {
  orientation -0.0285933 0.990104 0.137388 2.69062
  position 18.8631 12.9005 -37.9621
}
Background {
  skyColor [
    0.4 0.7 1
  ]
}
Ceiling {
  translation 0 3 0
  size 5 5
}
DirectionalLight {
  ambientIntensity 1
  direction -0.1 -0.5 -0.3
}
RectangleArena {
  floorSize 5 5
}
Nao {
  hidden position_0_0 -1.12802e-09
  hidden position2_0_0 2.66805e-07
  hidden position_0_1 -5.84611e-09
  hidden position2_0_1 -1
  hidden position_0_2 -2.00706e-08
  hidden position2_0_2 1
  hidden position_0_3 -1.46154e-06
  hidden position_0_4 -5.62651e-08
  hidden translation_11 2.18942e-07 -3.09564e-07 0.126485
  hidden rotation_11 0.0506234 0.998709 -0.00422241 2.6715e-07
  hidden translation_18 -4.40256e-05 -0.0981168 0.0999781
  hidden rotation_18 0.0465572 0.0215721 -0.998683 0.991555
  hidden position_18_0 -0.0481369
  hidden translation_19 0.105079 -0.015097 -9.85339e-07
  hidden rotation_19 -1 5.81323e-05 8.3169e-05 0.0481447
  hidden position_19_0 1.4
  hidden translation_20 0.000199147 -0.000116568 -1.26761e-06
  hidden rotation_20 -3.63108e-07 2.55118e-06 1 1.4
  hidden position_20_0 0.00367695
  hidden translation_21 0.0558706 -0.000216314 4.30223e-07
  hidden rotation_21 0.99999 0.000769219 0.00441448 0.00366532
  hidden position_21_0 -1.42536e-10
  hidden position_21_1 -1.42596e-10
  hidden position_21_2 2.01845e-10
  hidden translation_22 0.0689251 -0.0132169 -0.00499455
  hidden rotation_22 1.32391e-05 -1 -3.22944e-05 -0.959983
  hidden position_22_1 -6.06082e-11
  hidden translation_24 0.014 1.11999e-09 -2.91219e-08
  hidden rotation_24 2.85869e-09 -1 -1.60342e-09 -0.96
  hidden position_24_0 4.97809e-11
  hidden translation_25 0.014 2.13026e-09 -1.24405e-08
  hidden rotation_25 -3.20249e-12 -1 -6.14885e-12 -0.96
  hidden translation_26 0.069 0.013 -0.00500004
  hidden rotation_26 -4.57534e-11 -1 -3.27083e-11 -0.96
  hidden position_26_0 5.92208e-11
  hidden translation_27 0.014 1.1027e-09 -2.91231e-08
  hidden rotation_27 -1.75417e-11 -1 -2.1401e-11 -0.96
  hidden position_27_0 4.98052e-11
  hidden translation_28 0.014 2.12976e-09 -1.24403e-08
  hidden rotation_28 -3.20189e-12 -1 -6.14951e-12 -0.96
  hidden translation_29 0.049 -2.91246e-09 -0.026
  hidden rotation_29 -0.022665 0.99404 0.106637 2.33884e-10
  hidden position_29_0 1.8106e-11
  hidden translation_30 0.014 -7.05561e-10 4.48721e-10
  hidden rotation_30 3.20231e-12 1 -6.1493e-12 -0.96
  hidden translation_31 -4.59526e-05 0.0981131 0.100017
  hidden rotation_31 -0.0247844 0.00809208 -0.99966 -1.00685
  hidden position_31_0 0.0546024
  hidden translation_32 0.105077 0.0150954 3.02237e-05
  hidden rotation_32 1 0.000134357 -7.04424e-05 0.0546107
  hidden position_32_0 -1.4
  hidden translation_33 0.000109071 5.81593e-05 2.64511e-05
  hidden rotation_33 1.87341e-06 6.27439e-06 -1 1.4
  hidden position_33_0 -0.0734113
  hidden translation_34 0.055913 0.000117155 1.49829e-05
  hidden rotation_34 -1 0.000116217 -0.000142907 0.0734008
  hidden position_34_0 -1.44425e-10
  hidden position_34_1 -1.44683e-10
  hidden position_34_2 2.51407e-10
  hidden translation_35 0.0689672 -0.0128835 -0.00497218
  hidden rotation_35 -5.37463e-06 -1 1.8818e-05 -0.959979
  hidden position_35_1 2.31983e-09
  hidden translation_37 0.014 -2.09684e-09 -2.89368e-08
  hidden rotation_37 -3.07844e-09 -1 -2.65869e-09 -0.96
  hidden position_37_0 5.03575e-11
  hidden translation_38 0.014 -2.62441e-09 -1.22415e-08
  hidden rotation_38 3.71987e-12 -1 7.15141e-12 -0.96
  hidden translation_39 0.0690001 0.013 -0.00500005
  hidden rotation_39 5.31548e-11 -1 3.80451e-11 -0.96
  hidden position_39_0 6.5119e-11
  hidden translation_40 0.014 -2.10011e-09 -2.89493e-08
  hidden rotation_40 2.04036e-11 -1 2.48867e-11 -0.96
  hidden position_40_0 5.03609e-11
  hidden translation_41 0.014 -2.62536e-09 -1.22554e-08
  hidden rotation_41 3.72106e-12 -1 7.15138e-12 -0.96
  hidden translation_42 0.049 7.84004e-10 -0.026
  hidden rotation_42 0.0259884 0.992062 -0.123032 2.36111e-10
  hidden position_42_0 1.95245e-11
  hidden translation_43 0.014 6.00504e-10 2.99217e-10
  hidden rotation_43 -3.72199e-12 1 7.15156e-12 -0.96
  hidden translation_44 2.94474e-05 -0.0499987 -0.0849706
  hidden rotation_44 -0.950546 0.290184 0.11071 2.03995e-06
  hidden position_44_0 2.63225e-06
  hidden translation_45 3.13441e-05 1.41203e-06 3.09333e-05
  hidden rotation_45 0.19192 0.169808 0.966608 -5.64581e-07
  hidden position_45_0 -1.1
  hidden translation_46 -1.11316e-05 1.47412e-06 3.57721e-05
  hidden rotation_46 1.83629e-06 1 -5.14747e-07 -1.1
  hidden position_46_0 1
  hidden translation_47 -1.89876e-05 -2.81213e-07 -0.0999931
  hidden rotation_47 -2.12915e-08 1 -5.21741e-08 1
  hidden position_47_0 2.79637e-07
  hidden translation_48 -8.30225e-06 -1.39531e-07 -0.102906
  hidden rotation_48 0.0555286 0.993971 -0.0945457 2.78334e-07
  hidden position_48_0 1.60085e-07
  hidden translation_49 -4.61993e-06 -7.95336e-08 -3.45897e-06
  hidden rotation_49 0.0244748 0.994542 -0.101424 2.48786e-07
  hidden translation_50 0.0199969 -0.007 -0.0410037
  hidden rotation_50 8.19185e-11 -4.48697e-13 1 -3.14159
  hidden translation_54 3.63718e-05 0.0500007 -0.0849911
  hidden rotation_54 -0.686933 0.369183 -0.625961 1.76542e-06
  hidden position_54_0 1.36345e-06
  hidden translation_55 3.82702e-05 8.21294e-07 1.04747e-05
  hidden rotation_55 0.0570192 0.578799 -0.813474 1.57601e-06
  hidden position_55_0 -1.1
  hidden translation_56 -4.20016e-06 8.85626e-07 1.53149e-05
  hidden rotation_56 1.64705e-06 1 4.42471e-07 -1.1
  hidden position_56_0 1
  hidden translation_57 -1.41404e-05 -4.64299e-07 -0.100006
  hidden rotation_57 -3.9633e-07 1 -3.64102e-07 1
  hidden position_57_0 2.79636e-07
  hidden translation_58 -8.30201e-06 -1.39568e-07 -0.102906
  hidden rotation_58 -0.0731144 0.993971 0.0817088 2.77677e-07
  hidden position_58_0 -7.09622e-08
  hidden translation_59 -4.62006e-06 -7.95384e-08 -3.45882e-06
  hidden rotation_59 -0.0137703 0.996096 0.0872004 2.48396e-07
  hidden translation_60 0.0199969 0.007 -0.0410037
  hidden rotation_60 8.18934e-11 -4.46948e-13 1 -3.14159
  translation 0 0.785 0
  rotation 1 0 0 -1.57
  controller "my_controller"
  leftHandSlot [
    Transform {
      translation 0.06 0 0
      children [
        BallJoint {
          jointParameters BallJointParameters {
          }
          endPoint Connector {
            isLocked TRUE
            autoLock TRUE
            distanceTolerance 0.05
            axisTolerance 3.14159
            rotationTolerance 3.14159
            numberOfRotations 0
            snap FALSE
          }
        }
      ]
    }
  ]
  rightHandSlot [
    Transform {
      translation 0.06 0 0
      children [
        BallJoint {
          jointParameters BallJointParameters {
          }
          endPoint Connector {
            isLocked TRUE
            autoLock TRUE
            distanceTolerance 0.05
            axisTolerance 3.14159
            rotationTolerance 3.14159
            numberOfRotations 0
            snap FALSE
          }
        }
      ]
    }
  ]
}
FloorLight {
  translation -2.00175 -8.88178e-16 1.89667
}
FloorLight {
  translation 2.00366 2.22044e-15 -2.13347
}
DEF Swing Robot {
  translation 0 2.2 0
  rotation 1 0 0 -1.5708
  children [
    DEF RArm Transform {
      translation 0 0.25 -0.06
      children [
        HingeJoint {
          jointParameters HingeJointParameters {
            position -0.204366
            axis 0 1 0
            anchor 0 1 0
            minStop -3.1416
            maxStop 3.1416
            dampingConstant 1
          }
          endPoint Solid {
            translation -0.00434402 0.00718486 -0.75793
            rotation -0.99984 0.0126792 -0.0126282 -1.57537
            children [
              Transform {
                translation 0 -0.75 0
                children [
                  DEF SeatShape Solid {
                    translation 0 0 0.25
                    children [
                      DEF Left_Transform Transform {
                        translation 0.2 0.2 -0.12
                        children [
                          BallJoint {
                            jointParameters BallJointParameters {
                            }
                            endPoint Connector {
                              isLocked TRUE
                              distanceTolerance 0.05
                              axisTolerance 3
                              rotationTolerance 3.14159
                              numberOfRotations 0
                              snap FALSE
                            }
                          }
                        ]
                      }
                      DEF Right_Transform Transform {
                        translation 0.2 0.2 0.12
                        children [
                          BallJoint {
                            jointParameters BallJointParameters {
                            }
                            endPoint Connector {
                              isLocked TRUE
                              distanceTolerance 0.05
                              axisTolerance 3
                              rotationTolerance 3.14159
                              numberOfRotations 0
                              snap FALSE
                            }
                          }
                        ]
                      }
                      DEF C1 Connector {
                        translation 0 0 0.25
                        rotation 1 0 0 -1.5708
                        isLocked TRUE
                        autoLock TRUE
                        distanceTolerance 0.05
                        numberOfRotations 0
                        snap FALSE
                      }
                      DEF SeatCon Connector {
                        translation 0 0 0.25
                        rotation 1 0 0 -1.5708
                        autoLock TRUE
                        numberOfRotations 0
                      }
                      Shape {
                        appearance Appearance {
                          material Material {
                          }
                        }
                        geometry DEF SSeat Box {
                          size 0.1 0.01 0.5
                        }
                      }
                    ]
                    boundingObject USE SSeat
                    physics Physics {
                    }
                  }
                ]
              }
              DEF RVBar Shape {
                appearance Appearance {
                  material Material {
                  }
                }
                geometry Cylinder {
                  height 1.5
                  radius 0.05
                }
              }
            ]
            boundingObject USE RVBar
            physics Physics {
              centerOfMass [
                0 0 0
              ]
            }
            linearVelocity 0.0515119 -0.000265371 -9.17183e-08
            angularVelocity 1.04407e-07 -1.58485e-06 0.0653338
          }
        }
      ]
    }
    DEF LArm Transform {
      translation 0 -0.25 -0.06
      children [
        HingeJoint {
          jointParameters HingeJointParameters {
            position -0.203944
            axis 0 1 0
            anchor 0 1 0
            minStop -3.1416
            maxStop 3.1416
            dampingConstant 1
          }
          endPoint Solid {
            translation -0.00463624 0.00364683 -0.758477
            rotation -0.999845 0.0124943 -0.012421 -1.57305
            children [
              DEF C1 Connector {
                translation 0 -0.75 0
                rotation 1 0 0 1.5708
                isLocked TRUE
                autoLock TRUE
                distanceTolerance 0.05
                numberOfRotations 0
                snap FALSE
              }
              DEF SVBar2 Shape {
                appearance Appearance {
                  material Material {
                  }
                }
                geometry Cylinder {
                  height 1.5
                  radius 0.05
                }
              }
            ]
            boundingObject USE SVBar2
            physics Physics {
              centerOfMass [
                0 0 0
              ]
            }
            linearVelocity 0.0495497 -0.000333884 -9.32548e-08
            angularVelocity 1.15328e-07 -1.73022e-06 0.0653336
          }
        }
      ]
    }
    DEF SHBarShape Shape {
      appearance DEF SwingApp Appearance {
        material Material {
          diffuseColor 0.7 0.4 0.8
        }
        texture ImageTexture {
        }
      }
      geometry DEF SHBar Cylinder {
        height 0.5
        radius 0.05
      }
    }
  ]
  name "Swing"
  boundingObject USE SHBarShape
  selfCollision TRUE
}
