#VRML_SIM V8.3.2 utf8
WorldInfo {
  basicTimeStep 16
}
Viewpoint {
  orientation -0.853527 0.0556094 0.518073 0.0645583
  position 0.209734 2.48 35.4014
}
Nao {
  hidden position_0_0 5.26385e-13
  hidden position2_0_0 1.51029e-07
  hidden position_0_1 -2.12265e-08
  hidden position2_0_1 -1
  hidden position_0_2 -2.12265e-08
  hidden position2_0_2 1
  hidden position_0_3 8.74696e-07
  hidden position_0_4 8.74691e-07
  hidden translation_11 9.82656e-07 -3.2915e-11 0.1265
  hidden rotation_11 1.22315e-05 1 3.48625e-06 1.51029e-07
  hidden translation_18 -4.55628e-06 -0.098 0.1
  hidden rotation_18 -2.02116e-09 2.41213e-08 1 -1
  hidden position_18_0 -6.97283e-08
  hidden translation_19 0.104999 -0.0150022 1.22638e-07
  hidden rotation_19 0.0732295 0.042284 -0.996418 -6.97283e-08
  hidden position_19_0 1.4
  hidden translation_20 -1.12486e-06 -1.75186e-06 9.85751e-08
  hidden rotation_20 -4.557e-09 7.53205e-09 -1 -1.4
  hidden position_20_0 2.20352e-08
  hidden translation_21 0.0559486 5.73809e-07 6.97682e-08
  hidden rotation_21 -0.0203854 0.278567 -0.960201 -2.20352e-08
  hidden position_21_0 -1.42265e-10
  hidden position_21_1 -1.4226e-10
  hidden position_21_2 -2.43841e-11
  hidden translation_22 0.069 -0.013 -0.005
  hidden rotation_22 -4.31051e-11 -1 -3.08645e-11 -0.96
  hidden position_22_0 -6.24221e-11
  hidden translation_23 0.014 2.01141e-09 -3.75705e-09
  hidden rotation_23 -1.65364e-11 -1 -2.0171e-11 -0.96
  hidden position_23_0 -6.13198e-12
  hidden translation_24 0.014 1.00571e-09 -2.27708e-09
  hidden rotation_24 -3.01723e-12 -1 -5.79642e-12 -0.96
  hidden translation_25 0.069 0.013 -0.005
  hidden rotation_25 -4.31052e-11 -1 -3.08637e-11 -0.96
  hidden position_25_0 -6.24309e-11
  hidden translation_26 0.014 2.0114e-09 -3.75705e-09
  hidden rotation_26 -1.65371e-11 -1 -2.01696e-11 -0.96
  hidden position_26_0 -6.13287e-12
  hidden translation_27 0.014 1.00571e-09 -2.27708e-09
  hidden rotation_27 -3.0166e-12 -1 -5.79564e-12 -0.96
  hidden translation_28 0.049 2.01133e-09 -0.026
  hidden rotation_28 0.202718 0.155417 -0.966825 -2.43844e-11
  hidden position_28_0 -1.51399e-11
  hidden translation_29 0.014 1.00571e-09 1.22292e-10
  hidden rotation_29 3.01731e-12 1 -5.79558e-12 -0.96
  hidden translation_30 -4.55628e-06 0.098 0.1
  hidden rotation_30 2.02116e-09 2.41213e-08 -1 -1
  hidden position_30_0 6.97274e-08
  hidden translation_31 0.104999 0.0150022 1.22638e-07
  hidden rotation_31 -0.0730366 0.0422846 0.996432 -6.97274e-08
  hidden position_31_0 -1.4
  hidden translation_32 -1.12486e-06 1.75186e-06 9.85751e-08
  hidden rotation_32 4.557e-09 7.53205e-09 1 -1.4
  hidden position_32_0 -2.20309e-08
  hidden translation_33 0.0559486 -5.73809e-07 6.97682e-08
  hidden rotation_33 0.00473944 0.278621 0.960389 -2.20309e-08
  hidden position_33_0 -1.4226e-10
  hidden position_33_1 -1.42265e-10
  hidden position_33_2 -2.43841e-11
  hidden translation_34 0.069 -0.013 -0.005
  hidden rotation_34 4.31039e-11 -1 3.08637e-11 -0.96
  hidden position_34_0 -6.24274e-11
  hidden translation_35 0.014 -2.01141e-09 -3.75705e-09
  hidden rotation_35 1.65357e-11 -1 2.01711e-11 -0.96
  hidden position_35_0 -6.13021e-12
  hidden translation_36 0.014 -1.00571e-09 -2.27708e-09
  hidden rotation_36 3.01678e-12 -1 5.79506e-12 -0.96
  hidden translation_37 0.069 0.013 -0.005
  hidden rotation_37 4.31034e-11 -1 3.08625e-11 -0.96
  hidden position_37_0 -6.24309e-11
  hidden translation_38 0.014 -2.01141e-09 -3.75705e-09
  hidden rotation_38 1.65367e-11 -1 2.01714e-11 -0.96
  hidden position_38_0 -6.13021e-12
  hidden translation_39 0.014 -1.00571e-09 -2.27708e-09
  hidden rotation_39 3.01648e-12 -1 5.79547e-12 -0.96
  hidden translation_40 0.049 -2.01133e-09 -0.026
  hidden rotation_40 -0.202728 0.155305 0.966841 -2.43837e-11
  hidden position_40_0 -1.51408e-11
  hidden translation_41 0.014 -1.00571e-09 1.22293e-10
  hidden rotation_41 -3.01719e-12 1 5.795e-12 -0.96
  hidden translation_42 6.7734e-06 -0.05 -0.0850004
  hidden rotation_42 -0.000569361 0.984166 -0.177246 8.74696e-07
  hidden position_42_0 -1.02256e-06
  hidden translation_43 7.32066e-06 -8.77549e-10 -3.91377e-07
  hidden rotation_43 -0.103165 0.994483 -0.0189939 1.02256e-06
  hidden position_43_0 -1.1
  hidden translation_44 -7.81648e-06 5.5198e-12 3.70073e-07
  hidden rotation_44 1.03162e-08 1 1.51679e-08 -1.1
  hidden position_44_0 1.5
  hidden translation_45 -1.95897e-06 4.88896e-12 -0.0999957
  hidden rotation_45 -3.52417e-09 1 -8.39946e-09 1.5
  hidden position_45_0 6.26933e-08
  hidden translation_46 -2.25367e-06 3.1136e-12 -0.102901
  hidden rotation_46 0.0390947 0.993575 -0.106207 6.26933e-08
  hidden position_46_0 5.7186e-08
  hidden translation_47 -1.26559e-06 1.97543e-12 -4.6584e-07
  hidden rotation_47 0.0495072 0.992539 -0.111424 5.7186e-08
  hidden translation_48 0.0199994 -0.007 -0.0410002
  hidden rotation_48 -6.93889e-16 -1.72085e-15 1 -3.14159
  hidden translation_52 6.77338e-06 0.05 -0.0850004
  hidden rotation_52 0.000568302 0.984168 0.177235 8.74691e-07
  hidden position_52_0 1.02248e-06
  hidden translation_53 7.32064e-06 9.15432e-10 -3.91551e-07
  hidden rotation_53 0.102554 0.994546 0.0189931 1.02248e-06
  hidden position_53_0 -1.1
  hidden translation_54 -7.81648e-06 -5.61997e-12 3.70073e-07
  hidden rotation_54 -1.03162e-08 1 -1.51679e-08 -1.1
  hidden position_54_0 1.5
  hidden translation_55 -1.95897e-06 -4.94994e-12 -0.0999957
  hidden rotation_55 3.52416e-09 1 8.39946e-09 1.5
  hidden position_55_0 6.26933e-08
  hidden translation_56 -2.25367e-06 -3.14416e-12 -0.102901
  hidden rotation_56 -0.0390947 0.993575 0.106207 6.26933e-08
  hidden position_56_0 -5.7186e-08
  hidden translation_57 -1.26559e-06 -1.99258e-12 -4.6584e-07
  hidden rotation_57 -0.0495169 0.992539 0.111424 5.7186e-08
  hidden translation_58 0.0199994 0.007 -0.0410002
  hidden rotation_58 -5.55112e-16 1.33227e-15 1 -3.14159
  translation 0 0.36 0
  rotation 1.69458e-08 0.707388 0.706825 3.14159
  controller "my_controller"
}
Background {
  skyColor [
    0.4 0.7 1
  ]
}
Ceiling {
  translation 0 3 0
  size 5 5
}
DirectionalLight {
  ambientIntensity 1
  direction -0.1 -0.5 -0.3
}
RectangleArena {
  floorSize 5 5
}
FloorLight {
  translation -2.00175 -8.88178e-16 1.89667
}
FloorLight {
  translation 2.00366 2.22044e-15 -2.13347
}
DEF Swing Robot {
  translation 0 2.2 0
  rotation 1 0 0 -1.5708
  children [
    DEF RArm Transform {
      translation 0 0.25 -0.04
      children [
        HingeJoint {
          jointParameters HingeJointParameters {
            position -0.199059
            axis 0 1 0
            anchor 0 1 0
            minStop -3.1416
            maxStop 3.1416
            dampingConstant 1
          }
          endPoint Solid {
            translation -0.00817485 0.00152674 -0.761002
            rotation -0.999899 0.0100493 -0.0100285 -1.57332
            children [
              Transform {
                translation 0 -0.755 0
                children [
                  DEF MidHJ HingeJoint {
                    jointParameters HingeJointParameters {
                      position 0.205732
                      axis 0 0 1
                      anchor 0 0 1
                      minStop -3.14159
                      maxStop 3.14159
                    }
                    endPoint Solid {
                      translation 0.0143045 -0.0686055 9.32646e-06
                      rotation 0.000171721 5.19189e-06 -1 -0.205732
                      children [
                        Solid {
                          translation -0.05 0 0
                          rotation 0 0 1 1.5708
                          children [
                            Transform {
                              translation 0 0 0.25
                              children [
                                Solid {
                                  translation 0 0.05 0
                                  rotation 1 0 0 1.5708
                                  children [
                                    Solid {
                                      translation 0 0.25 0.05
                                      rotation 1 0 0 1.5708
                                      children [
                                        Shape {
                                          appearance Appearance {
                                          }
                                          geometry Cylinder {
                                            height 0.1
                                            radius 0.009
                                          }
                                        }
                                      ]
                                    }
                                    DEF RBARH Shape {
                                      appearance Appearance {
                                        material Material {
                                        }
                                      }
                                      geometry DEF RHBar Cylinder {
                                        height 0.5
                                        radius 0.009
                                      }
                                    }
                                  ]
                                  boundingObject USE RHBar
                                  physics Physics {
                                  }
                                }
                              ]
                            }
                            Shape {
                              appearance Appearance {
                                material Material {
                                }
                              }
                              geometry Cylinder {
                                height 0.1
                                radius 0.009
                              }
                            }
                          ]
                          physics Physics {
                          }
                        }
                        Transform {
                          translation 0 -0.07 0
                          children [
                            DEF MidHJ HingeJoint {
                              jointParameters HingeJointParameters {
                                position -0.223847
                                axis 0 0 1
                                anchor 0 0 1
                                minStop -3.14159
                                maxStop 3.14159
                              }
                              endPoint Solid {
                                translation -0.0355219 -0.156046 8.9075e-06
                                rotation 6.05466e-05 1.32697e-05 1 -0.223859
                                children [
                                  Transform {
                                    translation 0 -0.14 0.25
                                    children [
                                      Solid {
                                        children [
                                          DEF SeatCon Connector {
                                            translation 0 0 0.25
                                            rotation 1 0 0 -1.5708
                                            isLocked TRUE
                                            autoLock TRUE
                                            distanceTolerance 0.05
                                            numberOfRotations 0
                                            snap FALSE
                                          }
                                          Shape {
                                            appearance Appearance {
                                              material Material {
                                              }
                                            }
                                            geometry DEF Seat Box {
                                              size 0.17 0.02 0.5
                                            }
                                          }
                                        ]
                                        boundingObject USE Seat
                                        physics Physics {
                                          density -1
                                          mass 1.0366
                                        }
                                      }
                                    ]
                                  }
                                  Shape {
                                    appearance Appearance {
                                      material Material {
                                      }
                                    }
                                    geometry Cylinder {
                                      height 0.28
                                      radius 0.009
                                    }
                                  }
                                ]
                                boundingObject DEF LMIDVBAR Cylinder {
                                  height 0.28
                                  radius 0.009
                                }
                                physics Physics {
                                  density -1
                                  mass 0.1631
                                }
                                linearVelocity -0.0194174 -0.00402391 -6.35742e-06
                                angularVelocity -3.12493e-07 8.32773e-06 -0.00450558
                              }
                            }
                          ]
                        }
                        Shape {
                          appearance Appearance {
                            material Material {
                            }
                          }
                          geometry Cylinder {
                            height 0.12
                            radius 0.009
                          }
                        }
                      ]
                      boundingObject DEF LMIDVBAR Cylinder {
                        height 0.12
                        radius 0.009
                      }
                      physics Physics {
                        density -1
                        mass 0.2475
                      }
                      linearVelocity -0.0107628 0.00365702 1.09534e-05
                      angularVelocity -5.47168e-07 0.000302345 -0.127537
                    }
                  }
                ]
              }
              DEF RVBar Shape {
                appearance Appearance {
                  material Material {
                  }
                }
                geometry Cylinder {
                  height 1.46
                  radius 0.009
                }
              }
            ]
            boundingObject USE RVBar
            physics Physics {
              density -1
              mass 0.948
              centerOfMass [
                0 0 0
              ]
            }
            linearVelocity -0.000377292 4.28912e-06 1.10414e-06
            angularVelocity -4.42928e-07 -1.16783e-06 -0.000494302
          }
        }
      ]
    }
    DEF LArm Transform {
      translation 0 -0.25 -0.04
      children [
        HingeJoint {
          jointParameters HingeJointParameters {
            position -0.197922
            axis 0 1 0
            anchor 0 1 0
            minStop -3.1416
            maxStop 3.1416
            dampingConstant 1
          }
          endPoint Solid {
            translation -0.00905608 0.000302097 -0.757542
            rotation -0.99991 0.00947682 -0.00947999 -1.5715
            children [
              Transform {
                translation 0 -0.755 0
                children [
                  HingeJoint {
                    jointParameters HingeJointParameters {
                      position 0.18662
                      axis 0 0 1
                      anchor 0 0 1
                      minStop -3.14159
                      maxStop 3.14159
                    }
                    endPoint Solid {
                      translation 0.0129832 -0.0687927 -6.47567e-06
                      rotation -2.39385e-05 2.7728e-05 1 0.18662
                      children [
                        Transform {
                          translation 0 -0.09 0
                          children [
                            DEF MidHJ HingeJoint {
                              jointParameters HingeJointParameters {
                                position -0.203916
                                axis 0 0 1
                                anchor 0 0 1
                                minStop -3.14159
                                maxStop 3.14159
                              }
                              endPoint Solid {
                                translation -0.0283571 -0.1371 -6.47804e-06
                                rotation -7.41282e-06 2.31012e-05 -1 0.203928
                                children [
                                  DEF SeatCon Connector {
                                    translation 0 -0.12 0
                                    rotation 1 0 0 1.5708
                                    isLocked TRUE
                                    autoLock TRUE
                                    distanceTolerance 0.03
                                    numberOfRotations 0
                                    snap FALSE
                                  }
                                  Shape {
                                    appearance Appearance {
                                      material Material {
                                      }
                                    }
                                    geometry Cylinder {
                                      height 0.28
                                      radius 0.009
                                    }
                                  }
                                ]
                                boundingObject DEF LMIDVBAR Cylinder {
                                  height 0.28
                                  radius 0.009
                                }
                                physics Physics {
                                  density -1
                                  mass 0.1631
                                }
                                linearVelocity -0.0188525 -0.0040205 -5.61334e-06
                                angularVelocity 3.76096e-07 7.10823e-06 -0.00450558
                              }
                            }
                          ]
                        }
                        Shape {
                          appearance Appearance {
                            material Material {
                            }
                          }
                          geometry Cylinder {
                            height 0.12
                            radius 0.009
                          }
                        }
                      ]
                      boundingObject DEF LMIDVBAR Cylinder {
                        height 0.12
                        radius 0.009
                      }
                      physics Physics {
                        density -1
                        mass 0.2475
                      }
                      linearVelocity -0.00742814 -0.00175648 -3.43704e-06
                      angularVelocity -8.24495e-07 7.67681e-05 -0.122521
                    }
                  }
                ]
              }
              DEF SVBar2 Shape {
                appearance Appearance {
                  material Material {
                  }
                }
                geometry Cylinder {
                  height 1.46
                  radius 0.009
                }
              }
            ]
            boundingObject USE SVBar2
            physics Physics {
              density -1
              mass 0.948
              centerOfMass [
                0 0 0
              ]
            }
            linearVelocity 0.000485294 -6.15854e-06 -1.18206e-06
            angularVelocity 5.49719e-07 1.21288e-06 0.000639004
          }
        }
      ]
    }
    DEF SHBarShape Shape {
      appearance DEF SwingApp Appearance {
        material Material {
          diffuseColor 0.7 0.4 0.8
        }
        texture ImageTexture {
        }
      }
      geometry DEF SHBar Cylinder {
        height 0.5
        radius 0.05
      }
    }
  ]
  name "Swing"
  boundingObject USE SHBarShape
  selfCollision TRUE
}
