#VRML_SIM V8.3.2 utf8
WorldInfo {
  basicTimeStep 16
}
Viewpoint {
  orientation 0.75099 -0.629006 -0.200911 6.05364
  position 5.44507 6.16724 31.3407
}
Nao {
  translation 1 0.334 0
  controller "my_controller"
}
Background {
  skyColor [
    0.4 0.7 1
  ]
}
Ceiling {
  translation 0 3 0
  size 5 5
}
DirectionalLight {
  ambientIntensity 1
  direction -0.1 -0.5 -0.3
}
RectangleArena {
  floorSize 5 5
}
FloorLight {
  translation -2.00175 -8.88178e-16 1.89667
}
FloorLight {
  translation 2.00366 2.22044e-15 -2.13347
}
DEF Swing Robot {
  translation 0 2.2 0
  rotation 1 0 0 -1.5708
  children [
    DEF RArm Transform {
      translation 0 0.25 -0.04
      children [
        HingeJoint {
          jointParameters HingeJointParameters {
            position -0.198462
            axis 0 1 0
            anchor 0 1 0
            minStop -3.1416
            maxStop 3.1416
            dampingConstant 1
          }
          endPoint Solid {
            translation -0.00862913 0.00150758 -0.760938
            rotation -0.999905 0.00975154 -0.00973039 -1.57328
            children [
              Transform {
                translation 0 -0.755 0
                children [
                  DEF MidHJ HingeJoint {
                    jointParameters HingeJointParameters {
                      position 0.145191
                      axis 0 0 1
                      anchor 0 0 1
                      minStop -3.14159
                      maxStop 3.14159
                    }
                    endPoint Solid {
                      translation 0.0101309 -0.0693047 4.70777e-06
                      rotation 0.000123658 1.85732e-05 -1 -0.145191
                      children [
                        Solid {
                          translation -0.05 0 0
                          rotation 0 0 1 1.5708
                          children [
                            Transform {
                              translation 0 0 0.25
                              children [
                                Solid {
                                  translation 0 0.05 0
                                  rotation 1 0 0 1.5708
                                  children [
                                    Solid {
                                      translation 0 0.25 0.05
                                      rotation 1 0 0 1.5708
                                      children [
                                        Shape {
                                          appearance Appearance {
                                          }
                                          geometry Cylinder {
                                            height 0.1
                                            radius 0.009
                                          }
                                        }
                                      ]
                                    }
                                    DEF RBARH Shape {
                                      appearance Appearance {
                                        material Material {
                                        }
                                      }
                                      geometry DEF RHBar Cylinder {
                                        height 0.5
                                        radius 0.009
                                      }
                                    }
                                  ]
                                  boundingObject USE RHBar
                                  physics Physics {
                                  }
                                }
                              ]
                            }
                            Shape {
                              appearance Appearance {
                                material Material {
                                }
                              }
                              geometry Cylinder {
                                height 0.1
                                radius 0.009
                              }
                            }
                          ]
                          physics Physics {
                          }
                        }
                        Transform {
                          translation 0 -0.07 0
                          children [
                            DEF MidHJ HingeJoint {
                              jointParameters HingeJointParameters {
                                position -0.162644
                                axis 0 0 1
                                anchor 0 0 1
                                minStop -3.14159
                                maxStop 3.14159
                              }
                              endPoint Solid {
                                translation -0.0259084 -0.157908 4.46588e-06
                                rotation 4.24854e-05 2.39434e-05 1 -0.162656
                                children [
                                  Transform {
                                    translation 0 -0.14 0.25
                                    children [
                                      Solid {
                                        children [
                                          DEF SeatCon Connector {
                                            translation 0 0 0.25
                                            rotation 1 0 0 -1.5708
                                            isLocked TRUE
                                            autoLock TRUE
                                            distanceTolerance 0.05
                                            numberOfRotations 0
                                            snap FALSE
                                          }
                                          Shape {
                                            appearance Appearance {
                                              material Material {
                                              }
                                            }
                                            geometry DEF Seat Box {
                                              size 0.17 0.02 0.5
                                            }
                                          }
                                        ]
                                        boundingObject USE Seat
                                        physics Physics {
                                          density -1
                                          mass 1.0366
                                        }
                                      }
                                    ]
                                  }
                                  Shape {
                                    appearance Appearance {
                                      material Material {
                                      }
                                    }
                                    geometry Cylinder {
                                      height 0.28
                                      radius 0.009
                                    }
                                  }
                                ]
                                boundingObject DEF LMIDVBAR Cylinder {
                                  height 0.28
                                  radius 0.009
                                }
                                physics Physics {
                                  density -1
                                  mass 0.1631
                                }
                                linearVelocity -0.0201722 -0.003073 -4.88366e-06
                                angularVelocity 2.48209e-08 -3.32661e-06 0.000869772
                              }
                            }
                          ]
                        }
                        Shape {
                          appearance Appearance {
                            material Material {
                            }
                          }
                          geometry Cylinder {
                            height 0.12
                            radius 0.009
                          }
                        }
                      ]
                      boundingObject DEF LMIDVBAR Cylinder {
                        height 0.12
                        radius 0.009
                      }
                      physics Physics {
                        density -1
                        mass 0.2475
                      }
                      linearVelocity -0.0122486 0.00443335 1.2136e-05
                      angularVelocity 1.46638e-07 0.000312142 -0.132757
                    }
                  }
                ]
              }
              DEF RVBar Shape {
                appearance Appearance {
                  material Material {
                  }
                }
                geometry Cylinder {
                  height 1.46
                  radius 0.009
                }
              }
            ]
            boundingObject USE RVBar
            physics Physics {
              density -1
              mass 0.948
              centerOfMass [
                0 0 0
              ]
            }
            linearVelocity -0.00104536 1.18246e-05 8.60693e-07
            angularVelocity -2.76587e-07 7.17038e-07 -0.00137475
          }
        }
      ]
    }
    DEF LArm Transform {
      translation 0 -0.25 -0.04
      children [
        HingeJoint {
          jointParameters HingeJointParameters {
            position -0.197522
            axis 0 1 0
            anchor 0 1 0
            minStop -3.1416
            maxStop 3.1416
            dampingConstant 1
          }
          endPoint Solid {
            translation -0.00935938 0.000289622 -0.757518
            rotation -0.999914 0.00927686 -0.00927993 -1.57148
            children [
              Transform {
                translation 0 -0.755 0
                children [
                  HingeJoint {
                    jointParameters HingeJointParameters {
                      position 0.131787
                      axis 0 0 1
                      anchor 0 0 1
                      minStop -3.14159
                      maxStop 3.14159
                    }
                    endPoint Solid {
                      translation 0.00919384 -0.0693968 -3.27583e-06
                      rotation -1.4489e-05 3.62785e-05 1 0.131787
                      children [
                        Transform {
                          translation 0 -0.09 0
                          children [
                            DEF MidHJ HingeJoint {
                              jointParameters HingeJointParameters {
                                position -0.148618
                                axis 0 0 1
                                anchor 0 0 1
                                minStop -3.14159
                                maxStop 3.14159
                              }
                              endPoint Solid {
                                translation -0.0207362 -0.138457 -3.25695e-06
                                rotation -4.0534e-06 3.06175e-05 -1 0.14863
                                children [
                                  DEF SeatCon Connector {
                                    translation 0 -0.12 0
                                    rotation 1 0 0 1.5708
                                    isLocked TRUE
                                    autoLock TRUE
                                    distanceTolerance 0.03
                                    numberOfRotations 0
                                    snap FALSE
                                  }
                                  Shape {
                                    appearance Appearance {
                                      material Material {
                                      }
                                    }
                                    geometry Cylinder {
                                      height 0.28
                                      radius 0.009
                                    }
                                  }
                                ]
                                boundingObject DEF LMIDVBAR Cylinder {
                                  height 0.28
                                  radius 0.009
                                }
                                physics Physics {
                                  density -1
                                  mass 0.1631
                                }
                                linearVelocity -0.0202818 -0.003074 -4.23921e-06
                                angularVelocity 4.59775e-07 -2.67066e-06 0.000869772
                              }
                            }
                          ]
                        }
                        Shape {
                          appearance Appearance {
                            material Material {
                            }
                          }
                          geometry Cylinder {
                            height 0.12
                            radius 0.009
                          }
                        }
                      ]
                      boundingObject DEF LMIDVBAR Cylinder {
                        height 0.12
                        radius 0.009
                      }
                      physics Physics {
                        density -1
                        mass 0.2475
                      }
                      linearVelocity -0.00906094 -0.00134536 -2.63255e-06
                      angularVelocity -1.21043e-06 7.42252e-05 -0.12749
                    }
                  }
                ]
              }
              DEF SVBar2 Shape {
                appearance Appearance {
                  material Material {
                  }
                }
                geometry Cylinder {
                  height 1.46
                  radius 0.009
                }
              }
            ]
            boundingObject USE SVBar2
            physics Physics {
              density -1
              mass 0.948
              centerOfMass [
                0 0 0
              ]
            }
            linearVelocity -0.000120117 1.35967e-06 -9.75487e-07
            angularVelocity 4.28921e-07 -7.01394e-07 -0.00015765
          }
        }
      ]
    }
    DEF SHBarShape Shape {
      appearance DEF SwingApp Appearance {
        material Material {
          diffuseColor 0.7 0.4 0.8
        }
        texture ImageTexture {
        }
      }
      geometry DEF SHBar Cylinder {
        height 0.5
        radius 0.05
      }
    }
  ]
  name "Swing"
  boundingObject USE SHBarShape
  selfCollision TRUE
}
