#VRML_SIM V8.3.2 utf8
WorldInfo {
  basicTimeStep 16
}
Viewpoint {
  orientation 0.0982104 -0.980141 -0.172271 4.19642
  position 30.8731 12.9855 -16.9923
}
Background {
  skyColor [
    0.4 0.7 1
  ]
}
Ceiling {
  translation 0 3 0
  size 5 5
}
DirectionalLight {
  ambientIntensity 1
  direction -0.1 -0.5 -0.3
}
RectangleArena {
  floorSize 5 5
}
Nao {
  hidden position_0_0 3.29665e-13
  hidden position2_0_0 1.48039e-07
  hidden position_0_1 -4.86403e-08
  hidden position2_0_1 -0.5
  hidden position_0_2 -4.86298e-08
  hidden position2_0_2 0.5
  hidden position_0_3 8.76277e-07
  hidden position_0_4 8.76272e-07
  hidden translation_11 1.02166e-06 -2.99641e-11 0.1265
  hidden rotation_11 1.13295e-05 1 2.22361e-06 1.48039e-07
  hidden translation_18 -4.55627e-06 -0.098 0.1
  hidden rotation_18 -9.36323e-09 9.90645e-08 1 -0.5
  hidden position_18_0 1.13657e-08
  hidden translation_19 0.104998 -0.0150012 1.22675e-07
  hidden rotation_19 -0.0919969 0.829875 -0.550313 -1.13657e-08
  hidden position_19_0 0.5
  hidden translation_20 -1.82704e-06 -9.98118e-07 9.86044e-08
  hidden rotation_20 -5.74023e-09 2.26473e-08 -1 -0.5
  hidden position_20_0 -6.61998e-09
  hidden translation_21 0.0559485 -2.99705e-13 6.97891e-08
  hidden rotation_21 0.106692 0.975356 -0.193126 -6.61998e-09
  hidden position_21_0 -1.5455e-10
  hidden position_21_1 -1.54541e-10
  hidden position_21_2 -1.94502e-11
  hidden translation_22 0.069 -0.013 -0.005
  hidden rotation_22 -5.40952e-16 -1 0 -0.96
  hidden position_22_1 -6.76055e-11
  hidden translation_24 0.014 -1.11022e-15 -4.09099e-09
  hidden rotation_24 1.57778e-16 -1 5.40952e-16 -0.96
  hidden position_24_0 -5.90106e-12
  hidden translation_25 0.014 -4.71845e-16 -2.46857e-09
  hidden rotation_25 -1.50264e-16 -1 1.05185e-16 -0.96
  hidden translation_26 0.069 0.013 -0.005
  hidden rotation_26 -8.4148e-16 -1 1.20211e-16 -0.96
  hidden position_26_0 -6.76144e-11
  hidden translation_27 0.014 -1.13798e-15 -4.09099e-09
  hidden rotation_27 5.55978e-16 -1 6.61163e-16 -0.96
  hidden position_27_0 -5.89573e-12
  hidden translation_28 0.014 -4.44089e-16 -2.46857e-09
  hidden rotation_28 2.55449e-16 -1 -4.50793e-17 -0.96
  hidden translation_29 0.049 -1.05471e-15 -0.026
  hidden rotation_29 1.14159e-05 1 0 -1.94502e-11
  hidden position_29_0 -1.63949e-11
  hidden translation_30 0.014 -5.55112e-16 1.22457e-10
  hidden rotation_30 -1.20211e-16 1 1.20211e-16 -0.96
  hidden translation_31 -4.55627e-06 0.098 0.1
  hidden rotation_31 9.35796e-09 9.90439e-08 -1 -0.5
  hidden position_31_0 -1.13648e-08
  hidden translation_32 0.104998 0.0150012 1.22675e-07
  hidden rotation_32 0.091217 0.829935 0.550353 -1.13648e-08
  hidden position_32_0 -0.5
  hidden translation_33 -1.82704e-06 9.98118e-07 9.86044e-08
  hidden rotation_33 5.74023e-09 2.26473e-08 1 -0.5
  hidden position_33_0 6.64759e-09
  hidden translation_34 0.0559485 2.80276e-13 6.97891e-08
  hidden rotation_34 -0.139928 0.971304 0.192324 -6.64759e-09
  hidden position_34_0 -1.54544e-10
  hidden position_34_1 -1.54552e-10
  hidden position_34_2 -1.9452e-11
  hidden translation_35 0.069 -0.013 -0.005
  hidden rotation_35 1.20211e-16 -1 -2.40423e-16 -0.96
  hidden position_35_1 -6.76108e-11
  hidden translation_37 0.014 9.71445e-16 -4.09099e-09
  hidden rotation_37 -4.13227e-16 -1 -9.01586e-16 -0.96
  hidden position_37_0 -5.89662e-12
  hidden translation_38 0.014 4.71845e-16 -2.46857e-09
  hidden rotation_38 -4.2074e-16 -1 4.50793e-16 -0.96
  hidden translation_39 0.069 0.013 -0.005
  hidden rotation_39 -1.17206e-15 -1 2.40423e-16 -0.96
  hidden position_39_0 -6.76179e-11
  hidden translation_40 0.014 9.15934e-16 -4.09099e-09
  hidden rotation_40 4.4328e-16 -1 1.80317e-16 -0.96
  hidden position_40_0 -5.89484e-12
  hidden translation_41 0.014 4.996e-16 -2.46857e-09
  hidden rotation_41 -1.05185e-16 -1 6.01057e-17 -0.96
  hidden translation_42 0.049 9.71445e-16 -0.026
  hidden rotation_42 0 1 -5.70732e-06 -1.94529e-11
  hidden position_42_0 -1.6394e-11
  hidden translation_43 0.014 4.996e-16 1.22457e-10
  hidden rotation_43 2.40423e-16 1 5.71004e-16 -0.96
  hidden translation_44 6.75079e-06 -0.05 -0.0850003
  hidden rotation_44 -0.000573493 0.98406 -0.177836 8.76277e-07
  hidden position_44_0 -1.02561e-06
  hidden translation_45 7.29805e-06 -7.24223e-10 -3.43888e-07
  hidden rotation_45 -0.110262 0.993722 -0.0189466 1.02561e-06
  hidden position_45_0 -1.1
  hidden translation_46 -7.81648e-06 4.3039e-12 3.70193e-07
  hidden rotation_46 1.03165e-08 1 1.51676e-08 -1.1
  hidden position_46_0 1
  hidden translation_47 -1.95891e-06 4.31873e-12 -0.0999957
  hidden rotation_47 -7.80945e-09 1 -1.03309e-08 1
  hidden position_47_0 4.60755e-08
  hidden translation_48 -2.37547e-06 2.75852e-12 -0.1029
  hidden rotation_48 -0.0226032 0.988072 -0.152323 4.60755e-08
  hidden position_48_0 4.45782e-08
  hidden translation_49 -1.33399e-06 1.71315e-12 1.97963e-07
  hidden rotation_49 0.0153191 0.988466 -0.150664 4.45782e-08
  hidden translation_50 0.0199994 -0.007 -0.0409999
  hidden rotation_50 1.38778e-16 -1.66533e-15 1 -3.14159
  hidden translation_54 6.75077e-06 0.05 -0.0850003
  hidden rotation_54 0.000572558 0.984062 0.177826 8.76272e-07
  hidden position_54_0 1.02556e-06
  hidden translation_55 7.29803e-06 7.58618e-10 -3.44047e-07
  hidden rotation_55 0.109947 0.993757 0.0189455 1.02556e-06
  hidden position_55_0 -1.1
  hidden translation_56 -7.81648e-06 -4.40442e-12 3.70193e-07
  hidden rotation_56 -1.03164e-08 1 -1.51676e-08 -1.1
  hidden position_56_0 1
  hidden translation_57 -1.95891e-06 -4.37911e-12 -0.0999957
  hidden rotation_57 7.80945e-09 1 1.0331e-08 1
  hidden position_57_0 4.60755e-08
  hidden translation_58 -2.37547e-06 -2.78892e-12 -0.1029
  hidden rotation_58 0.0226031 0.988072 0.152323 4.60755e-08
  hidden position_58_0 -4.4579e-08
  hidden translation_59 -1.33399e-06 -1.73023e-12 1.97963e-07
  hidden rotation_59 -0.0164428 0.988449 0.150662 4.4579e-08
  hidden translation_60 0.0199994 0.007 -0.0409999
  hidden rotation_60 3.33067e-16 1.36002e-15 1 -3.14159
  translation -0.391008 0.0582662 -8.39094e-07
  rotation 0.559154 0.586261 -0.586212 -2.12198
  controller "my_controller"
  leftHandSlot [
    Transform {
      translation 0.06 0 0
      children [
        BallJoint {
          jointParameters BallJointParameters {
          }
          endPoint Connector {
            isLocked TRUE
            autoLock TRUE
            distanceTolerance 0.05
            axisTolerance 3.14159
            rotationTolerance 3.14159
            numberOfRotations 0
            snap FALSE
          }
        }
      ]
    }
  ]
  rightHandSlot [
    Transform {
      translation 0.06 0 0
      children [
        BallJoint {
          jointParameters BallJointParameters {
          }
          endPoint Connector {
            isLocked TRUE
            autoLock TRUE
            distanceTolerance 0.05
            axisTolerance 3.14159
            rotationTolerance 3.14159
            numberOfRotations 0
            snap FALSE
          }
        }
      ]
    }
  ]
}
FloorLight {
  translation -2.00175 -8.88178e-16 1.89667
}
FloorLight {
  translation 2.00366 2.22044e-15 -2.13347
}
DEF Swing Robot {
  translation 0 2.2 0
  rotation 1 0 0 -1.5708
  children [
    DEF RArm Transform {
      translation 0 0.25 -0.06
      children [
        HingeJoint {
          jointParameters HingeJointParameters {
            position -0.208871
            axis 0 1 0
            anchor 0 1 0
            minStop -3.1416
            maxStop 3.1416
            dampingConstant 1
          }
          endPoint Solid {
            translation -0.000927318 0.00675978 -0.756955
            rotation -0.999778 0.0149353 -0.0148953 -1.57492
            children [
              Transform {
                translation 0 -0.75 0
                children [
                  DEF SeatShape Solid {
                    translation 0 0 0.25
                    children [
                      DEF Left_Transform Transform {
                        translation 0.3 0.25 -0.1
                        children [
                          BallJoint {
                            jointParameters BallJointParameters {
                            }
                            endPoint Connector {
                              isLocked TRUE
                              distanceTolerance 0.05
                              axisTolerance 3
                              rotationTolerance 3.14159
                              numberOfRotations 0
                              snap FALSE
                            }
                          }
                        ]
                      }
                      DEF Right_Transform Transform {
                        translation 0.3 0.25 0.1
                        children [
                          BallJoint {
                            jointParameters BallJointParameters {
                            }
                            endPoint Connector {
                              isLocked TRUE
                              distanceTolerance 0.05
                              axisTolerance 3
                              rotationTolerance 3.14159
                              numberOfRotations 0
                              snap FALSE
                            }
                          }
                        ]
                      }
                      DEF C1 Connector {
                        translation 0 0 0.25
                        rotation 1 0 0 -1.5708
                        isLocked TRUE
                        autoLock TRUE
                        distanceTolerance 0.05
                        numberOfRotations 0
                        snap FALSE
                      }
                      DEF SeatCon Connector {
                        translation 0 0 0.25
                        rotation 1 0 0 -1.5708
                        autoLock TRUE
                        numberOfRotations 0
                      }
                      Shape {
                        appearance Appearance {
                          material Material {
                          }
                        }
                        geometry DEF SSeat Box {
                          size 0.1 0.01 0.5
                        }
                      }
                    ]
                    boundingObject USE SSeat
                    physics Physics {
                    }
                  }
                ]
              }
              DEF RVBar Shape {
                appearance Appearance {
                  material Material {
                  }
                }
                geometry Cylinder {
                  height 1.5
                  radius 0.05
                }
              }
            ]
            boundingObject USE RVBar
            physics Physics {
              centerOfMass [
                0 0 0
              ]
            }
            linearVelocity -0.00763154 -4.40869e-07 -9.12215e-13
            angularVelocity 2.87187e-11 1.69302e-07 -0.00969116
          }
        }
      ]
    }
    DEF LArm Transform {
      translation 0 -0.25 -0.06
      children [
        HingeJoint {
          jointParameters HingeJointParameters {
            position -0.208471
            axis 0 1 0
            anchor 0 1 0
            minStop -3.1416
            maxStop 3.1416
            dampingConstant 1
          }
          endPoint Solid {
            translation -0.00118567 0.00329002 -0.757377
            rotation -0.999783 0.0147637 -0.0147011 -1.5726
            children [
              DEF C1 Connector {
                translation 0 -0.75 0
                rotation 1 0 0 1.5708
                isLocked TRUE
                autoLock TRUE
                distanceTolerance 0.05
                numberOfRotations 0
                snap FALSE
              }
              DEF SVBar2 Shape {
                appearance Appearance {
                  material Material {
                  }
                }
                geometry Cylinder {
                  height 1.5
                  radius 0.05
                }
              }
            ]
            boundingObject USE SVBar2
            physics Physics {
              centerOfMass [
                0 0 0
              ]
            }
            linearVelocity -0.00733937 1.09319e-05 2.26306e-10
            angularVelocity -5.06925e-11 1.89743e-07 -0.00969113
          }
        }
      ]
    }
    DEF SHBarShape Shape {
      appearance DEF SwingApp Appearance {
        material Material {
          diffuseColor 0.7 0.4 0.8
        }
        texture ImageTexture {
        }
      }
      geometry DEF SHBar Cylinder {
        height 0.5
        radius 0.05
      }
    }
  ]
  name "Swing"
  boundingObject USE SHBarShape
  selfCollision TRUE
}
