#VRML_SIM V8.3.2 utf8
WorldInfo {
  basicTimeStep 8
}
Viewpoint {
  orientation 0.869482 0.446332 -0.211634 6.25513
  position -0.534606 2.49498 59.3218
  follow "solid"
}
Background {
  skyColor [
    0.4 0.7 1
  ]
}
Ceiling {
  translation 0 3 0
  size 5 5
}
DirectionalLight {
  ambientIntensity 1
  direction -0.1 -0.5 -0.3
}
RectangleArena {
  floorSize 5 5
}
Nao {
  hidden position_0_0 -6.51389e-10
  hidden position2_0_0 -3.11776e-06
  hidden position_0_1 0.404897
  hidden position2_0_1 1.21865e-05
  hidden position_0_2 0.400088
  hidden position2_0_2 5.9161e-07
  hidden position_0_3 8.72819e-06
  hidden position_0_4 2.22135e-05
  hidden linearVelocity_0 0.000728549 -8.9786e-05 3.89128e-07
  hidden angularVelocity_0 3.63543e-07 2.12336e-06 0.000886888
  hidden translation_12 3.33195e-05 3.37555e-07 0.126716
  hidden rotation_12 0.00634588 0.99998 0.000437415 -1.05626e-06
  hidden linearVelocity_12 0.000634327 -0.000151334 5.74321e-07
  hidden angularVelocity_12 3.63515e-07 2.1233e-06 0.000886898
  hidden translation_19 4.34252e-05 -0.0980008 0.100091
  hidden rotation_19 0.000786909 0.999996 0.00257743 0.00488223
  hidden position_19_0 -0.0481311
  hidden linearVelocity_19 0.000676494 -0.000105609 4.4792e-07
  hidden angularVelocity_19 3.63976e-07 2.12178e-06 0.000886904
  hidden translation_20 0.105102 -0.0150009 -2.73908e-05
  hidden rotation_20 -0.0146967 0.999892 0.000966399 1.84142e-07
  hidden position_20_0 6.60357e-07
  hidden linearVelocity_20 0.000646764 -5.84805e-05 3.47221e-07
  hidden angularVelocity_20 -8.46925e-08 1.81502e-06 0.000886905
  hidden translation_21 8.73706e-05 -6.89985e-07 -1.79895e-05
  hidden rotation_21 0.00404318 0.999945 -0.00966991 2.08282e-07
  hidden position_21_0 0.00430494
  hidden linearVelocity_21 0.000619492 -2.0058e-05 2.81619e-07
  hidden angularVelocity_21 2.62991e-07 1.30646e-06 0.000886906
  hidden translation_22 0.0560595 -8.0294e-07 -1.81681e-05
  hidden rotation_22 0.00347135 0.998616 0.0524862 6.27256e-08
  hidden position_22_0 2.65652e-05
  hidden position_22_1 -1.07315e-10
  hidden position_22_2 1.88296e-09
  hidden linearVelocity_22 0.000585286 2.62641e-05 2.23971e-07
  hidden angularVelocity_22 4.18216e-07 1.41262e-06 0.000886907
  hidden translation_23 0.0690621 -0.0130006 -0.00503438
  hidden rotation_23 -6.88083e-13 -1 -4.16533e-13 -0.96
  hidden position_23_1 5.22643e-10
  hidden linearVelocity_23 0.00057579 6.07127e-05 1.7358e-07
  hidden angularVelocity_23 4.18216e-07 1.41262e-06 0.000886907
  hidden translation_25 0.0140183 -1.33667e-08 -1.21514e-05
  hidden rotation_25 -2.82602e-13 -1 -2.33e-13 -0.96
  hidden position_25_0 4.5972e-10
  hidden linearVelocity_25 0.000583463 6.86828e-05 1.57267e-07
  hidden angularVelocity_25 4.18216e-07 1.41262e-06 0.000886907
  hidden translation_26 0.0140184 1.26025e-07 -1.20996e-05
  hidden rotation_26 -7.06843e-14 -1 -7.62742e-14 -0.96
  hidden linearVelocity_26 0.000594392 6.69686e-05 1.54843e-07
  hidden angularVelocity_26 4.18216e-07 1.41262e-06 0.000886907
  hidden translation_27 0.0690618 0.0129996 -0.00503432
  hidden rotation_27 -6.94311e-13 -1 -4.19117e-13 -0.96
  hidden position_27_0 6.67177e-10
  hidden linearVelocity_27 0.000575663 6.07397e-05 1.73597e-07
  hidden angularVelocity_27 4.18216e-07 1.41262e-06 0.000886907
  hidden translation_28 0.0140183 -1.33666e-08 -1.21514e-05
  hidden rotation_28 -2.86223e-13 -1 -2.35494e-13 -0.96
  hidden position_28_0 4.59925e-10
  hidden linearVelocity_28 0.000583336 6.87099e-05 1.57284e-07
  hidden angularVelocity_28 4.18216e-07 1.41262e-06 0.000886907
  hidden translation_29 0.0140184 1.26025e-07 -1.20996e-05
  hidden rotation_29 -6.99631e-14 -1 -7.60939e-14 -0.96
  hidden linearVelocity_29 0.000594265 6.69956e-05 1.5486e-07
  hidden angularVelocity_29 4.18216e-07 1.41262e-06 0.000886907
  hidden translation_30 0.0490267 -2.29537e-07 -0.0260569
  hidden rotation_30 -5.81194e-05 0.999997 0.0025643 1.65475e-10
  hidden position_30_0 1.9428e-10
  hidden linearVelocity_30 0.000596268 5.59938e-05 1.7144e-07
  hidden angularVelocity_30 4.18216e-07 1.41262e-06 0.000886907
  hidden translation_31 0.0140214 -1.57232e-07 4.99028e-06
  hidden rotation_31 3.60334e-14 1 -1.0248e-13 -0.96
  hidden linearVelocity_31 0.000586928 6.19231e-05 1.664e-07
  hidden angularVelocity_31 4.18216e-07 1.41262e-06 0.000886907
  hidden translation_32 4.05646e-05 0.0980005 0.100093
  hidden rotation_32 0.000229261 0.999992 0.00388918 7.46657e-05
  hidden position_32_0 0.0545944
  hidden linearVelocity_32 0.000675419 -0.000105471 4.48019e-07
  hidden angularVelocity_32 3.63063e-07 2.12483e-06 0.000886904
  hidden translation_33 0.105105 0.0149989 -2.79711e-05
  hidden rotation_33 -0.00540838 0.99991 0.0122451 1.81648e-07
  hidden position_33_0 -8.50391e-07
  hidden linearVelocity_33 0.000645222 -5.84417e-05 3.47588e-07
  hidden angularVelocity_33 -9.00205e-08 1.81186e-06 0.000886905
  hidden translation_34 9.0404e-05 -1.02828e-06 -1.84418e-05
  hidden rotation_34 -0.00401186 0.998921 0.0462659 2.06087e-07
  hidden position_34_0 -0.0754382
  hidden linearVelocity_34 0.000617735 -2.0145e-05 2.51082e-07
  hidden angularVelocity_34 -4.30003e-07 2.30404e-06 0.000886909
  hidden translation_35 0.0560634 -1.32333e-06 -1.87181e-05
  hidden rotation_35 0.00940233 0.999169 -0.0396483 6.1624e-08
  hidden position_35_0 -1.07898e-10
  hidden position_35_1 -1.07894e-10
  hidden position_35_2 1.90963e-09
  hidden linearVelocity_35 0.000583345 2.60113e-05 1.15088e-07
  hidden angularVelocity_35 -2.54084e-07 2.42552e-06 0.000886911
  hidden translation_36 0.0690643 -0.0130009 -0.00503558
  hidden rotation_36 -6.46137e-13 -1 -4.50252e-13 -0.96
  hidden position_36_1 2.19513e-09
  hidden linearVelocity_36 0.000573687 6.04258e-05 1.82044e-08
  hidden angularVelocity_36 -2.54084e-07 2.42552e-06 0.000886911
  hidden translation_38 0.0140189 -7.64062e-08 -1.25591e-05
  hidden rotation_38 -2.63519e-13 -1 -2.44029e-13 -0.96
  hidden position_38_0 4.53724e-10
  hidden linearVelocity_38 0.000581321 6.84332e-05 -1.50704e-09
  hidden angularVelocity_38 -2.54084e-07 2.42552e-06 0.000886911
  hidden translation_39 0.014019 1.54947e-07 -1.25073e-05
  hidden rotation_39 -6.55152e-14 -1 -7.9039e-14 -0.96
  hidden linearVelocity_39 0.000592259 6.67713e-05 6.17161e-09
  hidden angularVelocity_39 -2.54084e-07 2.42552e-06 0.000886911
  hidden translation_40 0.0690638 0.0129993 -0.00503541
  hidden rotation_40 -6.54131e-13 -1 -4.5452e-13 -0.96
  hidden position_40_0 6.09493e-10
  hidden linearVelocity_40 0.000573533 6.04354e-05 1.81341e-08
  hidden angularVelocity_40 -2.54084e-07 2.42552e-06 0.000886911
  hidden translation_41 0.0140189 -7.64061e-08 -1.25591e-05
  hidden rotation_41 -2.6726e-13 -1 -2.45291e-13 -0.96
  hidden position_41_0 4.53631e-10
  hidden linearVelocity_41 0.000581168 6.84428e-05 -1.57737e-09
  hidden angularVelocity_41 -2.54084e-07 2.42552e-06 0.000886911
  hidden translation_42 0.014019 1.54947e-07 -1.25073e-05
  hidden rotation_42 -6.3111e-14 -1 -8.11427e-14 -0.96
  hidden linearVelocity_42 0.000592106 6.67809e-05 6.10128e-09
  hidden angularVelocity_42 -2.54084e-07 2.42552e-06 0.000886911
  hidden translation_43 0.0490275 -4.72437e-07 -0.0260588
  hidden rotation_43 -0.000214106 0.999997 0.00255208 1.64701e-10
  hidden position_43_0 1.79741e-10
  hidden linearVelocity_43 0.000594175 5.57964e-05 3.67347e-08
  hidden angularVelocity_43 -2.54084e-07 2.42552e-06 0.000886911
  hidden translation_44 0.0140221 -2.22507e-07 5.15957e-06
  hidden rotation_44 4.13227e-14 1 -9.80324e-14 -0.96
  hidden linearVelocity_44 0.000584806 6.16812e-05 1.79566e-08
  hidden angularVelocity_44 -2.54084e-07 2.42552e-06 0.000886911
  hidden translation_45 -1.24956e-05 -0.0500023 -0.085171
  hidden rotation_45 0.00608782 0.967873 0.251367 5.0602e-06
  hidden position_45_0 1.34636e-07
  hidden linearVelocity_45 0.000805313 -4.11121e-05 2.48516e-07
  hidden angularVelocity_45 3.48426e-07 2.14648e-06 0.000886804
  hidden translation_46 3.77418e-06 -1.84711e-06 -4.28101e-05
  hidden rotation_46 0.0348166 0.995551 0.087558 4.05307e-06
  hidden position_46_0 -0.650463
  hidden linearVelocity_46 0.00083272 -3.0697e-05 2.40837e-07
  hidden angularVelocity_46 -2.9995e-06 -1.66689e-07 0.000886737
  hidden translation_47 8.55641e-05 -4.23232e-06 -0.000216852
  hidden rotation_47 1.40573e-05 1 3.31409e-05 -0.650366
  hidden position_47_0 1.37006
  hidden linearVelocity_47 0.000835188 2.38485e-05 2.65562e-07
  hidden angularVelocity_47 -2.99895e-06 -1.66792e-07 0.000886761
  hidden translation_48 -0.000344747 -2.22279e-05 -0.10021
  hidden rotation_48 8.07233e-06 1 -1.3454e-06 1.45999
  hidden position_48_0 1.37265e-06
  hidden linearVelocity_48 0.000893085 5.75748e-05 4.6758e-07
  hidden angularVelocity_48 -2.99855e-06 -1.64821e-07 0.000886257
  hidden translation_49 -2.28141e-06 -6.07292e-07 -0.103091
  hidden rotation_49 0.0653184 0.997823 -0.00905202 1.83332e-07
  hidden position_49_0 2.49238e-07
  hidden linearVelocity_49 0.000933017 4.5568e-05 6.00314e-07
  hidden angularVelocity_49 -2.99855e-06 -1.64824e-07 0.000886257
  hidden translation_50 0.000111268 -1.3501e-06 -0.000150455
  hidden rotation_50 0.183303 0.982716 -0.0258515 5.73256e-08
  hidden linearVelocity_50 0.00097173 6.02295e-05 7.34623e-07
  hidden angularVelocity_50 -3.01936e-06 -1.60498e-07 0.000886257
  hidden translation_53 0.0198572 -0.00700007 -0.0412775
  hidden rotation_53 -2.74986e-08 -8.28858e-10 1 -3.14159
  hidden linearVelocity_53 0.000978449 5.38076e-05 7.56308e-07
  hidden angularVelocity_53 -3.01936e-06 -1.60497e-07 0.000886257
  hidden translation_57 -8.25301e-06 0.0500015 -0.085172
  hidden rotation_57 0.0190821 0.967499 -0.252155 6.60544e-06
  hidden position_57_0 -1.35674e-06
  hidden linearVelocity_57 0.000804948 -4.10319e-05 2.36064e-07
  hidden angularVelocity_57 3.78067e-07 2.10638e-06 0.00088681
  hidden translation_58 9.13972e-06 1.54849e-06 -4.41188e-05
  hidden rotation_58 -0.000997476 0.999847 -0.0174537 4.86478e-06
  hidden position_58_0 -0.650463
  hidden linearVelocity_58 0.000832299 -3.05926e-05 2.18312e-07
  hidden angularVelocity_58 -3.353e-06 -4.67121e-07 0.000886744
  hidden translation_59 9.26499e-05 -1.13077e-06 -0.000222739
  hidden rotation_59 1.89028e-05 1 3.58765e-05 -0.650366
  hidden position_59_0 1.37006
  hidden linearVelocity_59 0.000834828 2.39507e-05 2.50072e-07
  hidden angularVelocity_59 -3.35316e-06 -4.63372e-07 0.000886773
  hidden translation_60 -0.000343514 -1.61035e-05 -0.100208
  hidden rotation_60 8.20738e-06 1 -1.34086e-06 1.45999
  hidden position_60_0 1.37404e-06
  hidden linearVelocity_60 0.000892724 5.76757e-05 4.86504e-07
  hidden angularVelocity_60 -3.35276e-06 -4.6137e-07 0.00088627
  hidden translation_61 -2.19556e-06 -7.61486e-07 -0.10309
  hidden rotation_61 -0.0774109 0.996999 0.000429629 1.82939e-07
  hidden position_61_0 -1.06315e-07
  hidden linearVelocity_61 0.000932669 4.56785e-05 6.31234e-07
  hidden angularVelocity_61 -3.35275e-06 -4.61358e-07 0.00088627
  hidden translation_62 0.000110812 -1.45311e-06 -0.000150116
  hidden rotation_62 -0.0978213 0.995203 0.00167015 5.56573e-08
  hidden linearVelocity_62 0.000971363 6.03245e-05 7.84627e-07
  hidden angularVelocity_62 -3.33705e-06 -4.64612e-07 0.00088627
  hidden translation_65 0.0198558 0.00700003 -0.041279
  hidden rotation_65 2.74126e-08 -6.8298e-10 1 -3.14159
  hidden linearVelocity_65 0.00097806 5.38823e-05 8.06424e-07
  hidden angularVelocity_65 -3.33705e-06 -4.64611e-07 0.00088627
  translation -0.058492 0.759546 -0.00814147
  rotation 0.914692 0.28667 -0.284883 -1.65615
  controller "humancontroller2"
  bodySlot [
    Receiver {
      name "Robot_Receiver"
    }
  ]
  leftFootSlot [
    InertialUnit {
    }
    Gyro {
      name ""
    }
  ]
  rightFootSlot [
    DEF Right_Foot_Gyro Gyro {
      rotation 1 0 0 1.5708
      name "Right_Foot_Gyro"
    }
    InertialUnit {
      name "Right_Foot_IU"
    }
  ]
  leftHandSlot [
    Transform {
      translation 0.06 0 0
      children [
        BallJoint {
          jointParameters BallJointParameters {
            springConstant 1
          }
          endPoint Connector {
            isLocked TRUE
            autoLock TRUE
            distanceTolerance 0.05
            axisTolerance 3.14159
            rotationTolerance 3.14159
            numberOfRotations 0
            snap FALSE
          }
        }
      ]
    }
  ]
  rightHandSlot [
    Transform {
      translation 0.06 0 0
      children [
        BallJoint {
          jointParameters BallJointParameters {
            springConstant 1
          }
          endPoint Connector {
            isLocked TRUE
            autoLock TRUE
            distanceTolerance 0.05
            axisTolerance 3.14159
            rotationTolerance 3.14159
            numberOfRotations 0
            snap FALSE
          }
        }
      ]
    }
  ]
}
FloorLight {
  translation -2.00175 -8.88178e-16 1.89667
}
FloorLight {
  translation 2.00366 2.22044e-15 -2.13347
}
DEF Swing Robot {
  translation 0 2.2 0
  rotation 1 0 0 -1.5708
  children [
    DEF RArm Transform {
      translation 0 0.25 -0.06
      children [
        HingeJoint {
          jointParameters HingeJointParameters {
            position -0.203216
            axis 0 1 0
            anchor 0 1 0
            minStop -3.1416
            maxStop 3.1416
            dampingConstant 1
          }
          endPoint Solid {
            translation -0.00579489 0.0100633 -0.754989
            rotation -0.999854 0.0122221 -0.0119465 -1.57486
            children [
              Transform {
                translation 0 -0.75 0
                children [
                  DEF SeatShape Solid {
                    translation 0 0 0.25
                    children [
                      DEF Mid_bar Transform {
                        translation 0.05 0.05 0
                        children [
                          SolidBox {
                            size 0.08 0.05 0.01
                            physics Physics {
                            }
                          }
                        ]
                      }
                      Emitter {
                        name "SeatEmitter"
                      }
                      DEF Seat_IU InertialUnit {
                        name "Seat_IU"
                      }
                      Gyro {
                        name "Seat_Gyro"
                      }
                      DEF Right_bar Transform {
                        translation 0 0.04 0.1
                        children [
                          SolidBox {
                            size 0.1 0.05 0.01
                            physics Physics {
                            }
                          }
                        ]
                      }
                      DEF Left_bar Transform {
                        translation 0 0.04 -0.1
                        children [
                          SolidBox {
                            size 0.1 0.05 0.01
                            physics Physics {
                            }
                          }
                        ]
                      }
                      DEF Front_bar Transform {
                        translation 0.065 0.075 0
                        children [
                          SolidBox {
                            size 0.06 0.01 0.5
                            physics Physics {
                            }
                          }
                        ]
                      }
                      DEF C1 Connector {
                        translation 0 0 0.25
                        rotation 1 0 0 -1.5708
                        isLocked TRUE
                        autoLock TRUE
                        distanceTolerance 0.05
                        numberOfRotations 0
                        snap FALSE
                      }
                      DEF SeatCon Connector {
                        translation 0 0 0.25
                        rotation 1 0 0 -1.5708
                        autoLock TRUE
                        numberOfRotations 0
                      }
                      Shape {
                        appearance Appearance {
                          material Material {
                          }
                        }
                        geometry DEF SSeat Box {
                          size 0.1 0.01 0.5
                        }
                      }
                    ]
                    boundingObject USE SSeat
                    physics Physics {
                    }
                  }
                ]
              }
              DEF RVBar Shape {
                appearance Appearance {
                  material Material {
                  }
                }
                geometry Cylinder {
                  height 1.5
                  radius 0.05
                }
              }
            ]
            boundingObject USE RVBar
            physics Physics {
              centerOfMass [
                0 0 0
              ]
            }
            linearVelocity 0.000467424 -1.62038e-06 3.68142e-09
            angularVelocity -5.6337e-09 -1.72761e-08 0.000578424
          }
        }
      ]
    }
    DEF LArm Transform {
      translation 0 -0.25 -0.06
      children [
        HingeJoint {
          jointParameters HingeJointParameters {
            position -0.20311
            axis 0 1 0
            anchor 0 1 0
            minStop -3.1416
            maxStop 3.1416
            dampingConstant 0.287
          }
          endPoint Solid {
            translation -0.00469 0.00221418 -0.769567
            rotation -0.999855 0.0120278 -0.012031 -1.57548
            children [
              DEF C1 Connector {
                translation 0 -0.75 0
                rotation 1 0 0 1.5708
                isLocked TRUE
                autoLock TRUE
                distanceTolerance 0.05
                numberOfRotations 0
                snap FALSE
              }
              DEF SVBar2 Shape {
                appearance Appearance {
                  material Material {
                  }
                }
                geometry Cylinder {
                  height 1.5
                  radius 0.05
                }
              }
            ]
            boundingObject USE SVBar2
            physics Physics {
              centerOfMass [
                0 0 0
              ]
            }
            linearVelocity 0.00044535 -2.704e-06 4.18931e-09
            angularVelocity -5.52519e-09 4.23345e-09 0.000578668
          }
        }
      ]
    }
    DEF SHBarShape Shape {
      appearance DEF SwingApp Appearance {
        material Material {
          diffuseColor 0.7 0.4 0.8
        }
        texture ImageTexture {
        }
      }
      geometry DEF SHBar Cylinder {
        height 0.5
        radius 0.05
      }
    }
  ]
  name "Swing"
  boundingObject USE SHBarShape
  controller "swingcontroller"
  selfCollision TRUE
}
