#VRML_SIM V8.3.2 utf8
WorldInfo {
  basicTimeStep 8
}
Viewpoint {
  orientation 0.539045 -0.83018 -0.142234 5.71388
  position 25.6292 19.1505 50.0194
  follow "NAO_H25_V50"
}
Background {
  skyColor [
    0.4 0.7 1
  ]
}
Ceiling {
  translation 0 3 0
  size 5 5
}
DirectionalLight {
  ambientIntensity 1
  direction -0.1 -0.5 -0.3
}
RectangleArena {
  floorSize 5 5
}
Nao {
  hidden position_0_0 -6.77983e-10
  hidden position2_0_0 -2.94576e-06
  hidden position_0_1 0.404897
  hidden position2_0_1 1.22078e-05
  hidden position_0_2 0.400088
  hidden position2_0_2 5.74613e-07
  hidden position_0_3 8.00138e-06
  hidden position_0_4 2.14753e-05
  hidden linearVelocity_0 1.04681 -0.420833 0.00665272
  hidden angularVelocity_0 0.0144058 0.0282068 1.66389
  hidden translation_12 3.48552e-05 3.4811e-07 0.126718
  hidden rotation_12 0.00810184 0.999967 0.000552565 -8.84271e-07
  hidden linearVelocity_12 0.838032 -0.392184 0.00797493
  hidden angularVelocity_12 0.0144059 0.0282066 1.66388
  hidden translation_19 4.47325e-05 -0.0980008 0.100093
  hidden rotation_19 0.000784711 0.999996 0.00258202 0.00488179
  hidden position_19_0 -0.048131
  hidden linearVelocity_19 0.956319 -0.38026 0.00674777
  hidden angularVelocity_19 0.0144075 0.0282062 1.66386
  hidden translation_20 0.105103 -0.0150009 -2.63248e-05
  hidden rotation_20 0.0123364 0.999914 0.00440843 1.29335e-07
  hidden position_20_0 7.20738e-07
  hidden linearVelocity_20 0.972983 -0.277393 0.00485913
  hidden angularVelocity_20 0.014408 0.0282059 1.66385
  hidden translation_21 8.79636e-05 -6.85882e-07 -1.71324e-05
  hidden rotation_21 0.0044289 0.999941 -0.00992141 1.47901e-07
  hidden position_21_0 0.00430492
  hidden linearVelocity_21 0.981888 -0.189675 0.00329469
  hidden angularVelocity_21 0.0144081 0.0282062 1.66384
  hidden translation_22 0.0560599 -8.00035e-07 -1.75613e-05
  hidden rotation_22 -0.0102786 0.997424 0.0709941 4.26769e-08
  hidden position_22_0 2.65653e-05
  hidden position_22_1 -9.51625e-11
  hidden position_22_2 1.82911e-09
  hidden linearVelocity_22 0.990508 -0.0821239 0.00139624
  hidden angularVelocity_22 0.0144082 0.0282061 1.66383
  hidden translation_23 0.0690621 -0.0130006 -0.00503438
  hidden rotation_23 -9.05196e-13 -1 -5.74318e-13 -0.96
  hidden position_23_1 5.26304e-10
  hidden linearVelocity_23 1.01989 -0.0218255 0.000119005
  hidden angularVelocity_23 0.0144082 0.0282061 1.66383
  hidden translation_25 0.0140183 -1.33565e-08 -1.2149e-05
  hidden rotation_25 -3.66164e-13 -1 -3.3515e-13 -0.96
  hidden position_25_0 4.47099e-10
  hidden linearVelocity_25 1.04056 -0.0199995 -9.09387e-05
  hidden angularVelocity_25 0.0144082 0.0282061 1.66383
  hidden translation_26 0.0140184 1.2603e-07 -1.20993e-05
  hidden rotation_26 -8.57108e-14 -1 -1.05576e-13 -0.96
  hidden linearVelocity_26 1.05391 -0.0358862 6.29379e-05
  hidden angularVelocity_26 0.0144082 0.0282061 1.66383
  hidden translation_27 0.0690618 0.0129996 -0.00503432
  hidden rotation_27 -9.11823e-13 -1 -5.7721e-13 -0.96
  hidden position_27_0 6.70835e-10
  hidden linearVelocity_27 1.01902 -0.0213794 0.0001191
  hidden angularVelocity_27 0.0144082 0.0282061 1.66383
  hidden translation_28 0.0140183 -1.33564e-08 -1.2149e-05
  hidden rotation_28 -3.70432e-13 -1 -3.38155e-13 -0.96
  hidden position_28_0 4.47304e-10
  hidden linearVelocity_28 1.03969 -0.0195534 -9.08441e-05
  hidden angularVelocity_28 0.0144082 0.0282061 1.66383
  hidden translation_29 0.0140184 1.2603e-07 -1.20993e-05
  hidden rotation_29 -8.53501e-14 -1 -1.05561e-13 -0.96
  hidden linearVelocity_29 1.05304 -0.0354401 6.30324e-05
  hidden angularVelocity_29 0.0144082 0.0282061 1.66383
  hidden translation_30 0.0490267 -2.29527e-07 -0.0260569
  hidden rotation_30 -0.000305238 0.999988 0.00487828 1.11629e-10
  hidden position_30_0 1.94068e-10
  hidden linearVelocity_30 1.04268 -0.0535966 0.000460598
  hidden angularVelocity_30 0.0144082 0.0282061 1.66383
  hidden translation_31 0.0140214 -1.57227e-07 4.99134e-06
  hidden rotation_31 5.17924e-14 1 -1.32255e-13 -0.96
  hidden linearVelocity_31 1.03677 -0.0337045 0.000174363
  hidden angularVelocity_31 0.0144082 0.0282061 1.66383
  hidden translation_32 4.18719e-05 0.0980005 0.100095
  hidden rotation_32 0.000378693 0.999993 0.00368341 7.42226e-05
  hidden position_32_0 0.0545945
  hidden linearVelocity_32 0.950044 -0.377114 0.0067495
  hidden angularVelocity_32 0.0144041 0.0282064 1.66386
  hidden translation_33 0.105106 0.0149989 -2.69086e-05
  hidden rotation_33 0.0147192 0.999718 0.0186608 1.27055e-07
  hidden position_33_0 -9.10598e-07
  hidden linearVelocity_33 0.964783 -0.273432 0.00486396
  hidden angularVelocity_33 0.0144046 0.0282061 1.66385
  hidden translation_34 9.10011e-05 -1.02417e-06 -1.75875e-05
  hidden rotation_34 -0.00453082 0.998694 0.0508975 1.45886e-07
  hidden position_34_0 -0.0754382
  hidden linearVelocity_34 0.973083 -0.18557 0.00330242
  hidden angularVelocity_34 0.0144047 0.0282065 1.66384
  hidden translation_35 0.0560638 -1.32042e-06 -1.81133e-05
  hidden rotation_35 0.00222006 0.998872 -0.0474377 4.16239e-08
  hidden position_35_0 -9.39746e-11
  hidden position_35_1 -9.38478e-11
  hidden position_35_2 1.85604e-09
  hidden linearVelocity_35 0.981438 -0.078098 0.00140763
  hidden angularVelocity_35 0.0144046 0.0282064 1.66383
  hidden translation_36 0.0690643 -0.0130009 -0.00503558
  hidden rotation_36 -8.61417e-13 -1 -6.08285e-13 -0.96
  hidden position_36_1 2.19916e-09
  hidden linearVelocity_36 1.01047 -0.0176277 0.000130556
  hidden angularVelocity_36 0.0144046 0.0282064 1.66383
  hidden translation_38 0.0140189 -7.6396e-08 -1.25567e-05
  hidden rotation_38 -3.47291e-13 -1 -3.4651e-13 -0.96
  hidden position_38_0 4.41173e-10
  hidden linearVelocity_38 1.03114 -0.0157026 -8.09595e-05
  hidden angularVelocity_38 0.0144046 0.0282064 1.66383
  hidden translation_39 0.014019 1.54952e-07 -1.2507e-05
  hidden rotation_39 -8.06619e-14 -1 -1.08806e-13 -0.96
  hidden linearVelocity_39 1.04456 -0.0315259 7.12095e-05
  hidden angularVelocity_39 0.0144046 0.0282064 1.66383
  hidden translation_40 0.0690638 0.0129993 -0.00503541
  hidden rotation_40 -8.7053e-13 -1 -6.12312e-13 -0.96
  hidden position_40_0 6.13527e-10
  hidden linearVelocity_40 1.0096 -0.0171815 0.000130646
  hidden angularVelocity_40 0.0144046 0.0282064 1.66383
  hidden translation_41 0.0140189 -7.63959e-08 -1.25567e-05
  hidden rotation_41 -3.51078e-13 -1 -3.47712e-13 -0.96
  hidden position_41_0 4.41081e-10
  hidden linearVelocity_41 1.03026 -0.0152564 -8.08688e-05
  hidden angularVelocity_41 0.0144046 0.0282064 1.66383
  hidden translation_42 0.014019 1.54952e-07 -1.2507e-05
  hidden rotation_42 -7.83779e-14 -1 -1.10219e-13 -0.96
  hidden linearVelocity_42 1.04369 -0.0310797 7.13003e-05
  hidden angularVelocity_42 0.0144046 0.0282064 1.66383
  hidden translation_43 0.0490275 -4.72427e-07 -0.0260588
  hidden rotation_43 -0.000550405 0.999988 0.00486974 1.11111e-10
  hidden position_43_0 1.79619e-10
  hidden linearVelocity_43 1.03342 -0.0492891 0.000469002
  hidden angularVelocity_43 0.0144046 0.0282064 1.66383
  hidden translation_44 0.0140221 -2.22502e-07 5.16063e-06
  hidden rotation_44 5.65595e-14 1 -1.27913e-13 -0.96
  hidden linearVelocity_44 1.02742 -0.0294244 0.000184045
  hidden angularVelocity_44 0.0144046 0.0282064 1.66383
  hidden translation_45 -1.57744e-05 -0.0500023 -0.0851757
  hidden rotation_45 0.00606461 0.972291 0.233694 4.33841e-06
  hidden position_45_0 5.58501e-07
  hidden linearVelocity_45 1.21596 -0.446195 0.00561415
  hidden angularVelocity_45 0.0144017 0.0282071 1.66393
  hidden translation_46 3.3744e-07 -1.87192e-06 -4.774e-05
  hidden rotation_46 0.0398139 0.994262 0.0992844 3.63207e-06
  hidden position_46_0 -0.856427
  hidden linearVelocity_46 1.26745 -0.464652 0.00547796
  hidden angularVelocity_46 0.0143966 0.0282104 1.66397
  hidden translation_47 0.000125529 -4.2593e-06 -0.000200804
  hidden rotation_47 8.14432e-06 1 2.6469e-05 -0.85633
  hidden position_47_0 0.525084
  hidden linearVelocity_47 1.08746 -0.624551 0.00220879
  hidden angularVelocity_47 0.0251169 0.0490586 -4.73833
  hidden translation_48 -7.08699e-05 -2.22185e-05 -0.100395
  hidden rotation_48 1.74274e-05 1 4.58956e-06 0.615014
  hidden position_48_0 1.34516e-06
  hidden linearVelocity_48 1.00274 -0.759476 -0.0013422
  hidden angularVelocity_48 0.0145242 0.0287425 1.51248
  hidden translation_49 -2.52605e-06 -6.02543e-07 -0.10309
  hidden rotation_49 0.0550614 0.998372 -0.0148852 1.55913e-07
  hidden position_49_0 2.39066e-07
  hidden linearVelocity_49 1.07373 -0.756223 -0.00208409
  hidden angularVelocity_49 0.0145239 0.0287423 1.51248
  hidden translation_50 0.000111131 -1.34743e-06 -0.000149795
  hidden rotation_50 0.198063 0.979168 -0.0447346 4.72316e-08
  hidden linearVelocity_50 1.12792 -0.710847 -0.00346627
  hidden angularVelocity_50 0.0145233 0.0287421 1.51248
  hidden translation_53 0.0198571 -0.00700007 -0.0412772
  hidden rotation_53 -2.74985e-08 -8.28858e-10 1 -3.14159
  hidden linearVelocity_53 1.14246 -0.717475 -0.00347943
  hidden angularVelocity_53 0.0145233 0.028742 1.51248
  hidden translation_57 -1.14897e-05 0.0500015 -0.0851766
  hidden rotation_57 0.0226105 0.970797 -0.238835 5.87255e-06
  hidden position_57_0 -9.27027e-07
  hidden linearVelocity_57 1.21352 -0.444947 0.00562599
  hidden angularVelocity_57 0.0144126 0.0282113 1.66394
  hidden translation_58 5.74505e-06 1.52641e-06 -4.89309e-05
  hidden rotation_58 0.000391134 0.999793 -0.0203296 4.43532e-06
  hidden position_58_0 -0.860197
  hidden linearVelocity_58 1.26441 -0.463098 0.00550085
  hidden angularVelocity_58 0.0144245 0.0282185 1.66399
  hidden translation_59 0.000134458 -1.15502e-06 -0.000204488
  hidden rotation_59 1.15185e-05 1 2.88657e-05 -0.8601
  hidden position_59_0 0.52548
  hidden linearVelocity_59 1.08515 -0.62378 0.00223689
  hidden angularVelocity_59 0.0251742 0.0490676 -4.73832
  hidden translation_60 -7.13899e-05 -1.60941e-05 -0.100393
  hidden rotation_60 1.7705e-05 1 4.71212e-06 0.61541
  hidden position_60_0 1.34655e-06
  hidden linearVelocity_60 1.00107 -0.759006 -0.00132821
  hidden angularVelocity_60 0.0145414 0.0287491 1.51679
  hidden translation_61 -2.44021e-06 -7.56734e-07 -0.103089
  hidden rotation_61 -0.0682007 0.997656 0.00555153 1.55506e-07
  hidden position_61_0 -9.61707e-08
  hidden linearVelocity_61 1.07239 -0.755572 -0.00207528
  hidden angularVelocity_61 0.0145416 0.0287492 1.51679
  hidden translation_62 0.000110675 -1.45044e-06 -0.000149456
  hidden rotation_62 -0.102501 0.99456 0.018568 4.55518e-08
  hidden linearVelocity_62 1.12638 -0.709784 -0.00346027
  hidden angularVelocity_62 0.0145423 0.0287494 1.51679
  hidden translation_65 0.0198557 0.00700003 -0.0412787
  hidden rotation_65 2.74127e-08 -6.8298e-10 1 -3.14159
  hidden linearVelocity_65 1.14073 -0.716257 -0.00347466
  hidden angularVelocity_65 0.0145423 0.0287494 1.51679
  translation -0.669469 0.942392 -0.00773165
  rotation 0.997569 -0.0486504 0.0498887 -1.56977
  controller "humancontroller"
  bodySlot [
    Receiver {
      name "Robot_Receiver"
    }
  ]
  leftFootSlot [
    InertialUnit {
    }
    Gyro {
      name ""
    }
  ]
  rightFootSlot [
    DEF Right_Foot_Gyro Gyro {
      rotation 1 0 0 1.5708
      name "Right_Foot_Gyro"
    }
    InertialUnit {
      name "Right_Foot_IU"
    }
  ]
  leftHandSlot [
    Transform {
      translation 0.06 0 0
      children [
        BallJoint {
          jointParameters BallJointParameters {
            springConstant 1
          }
          endPoint Connector {
            isLocked TRUE
            autoLock TRUE
            distanceTolerance 0.05
            axisTolerance 3.14159
            rotationTolerance 3.14159
            numberOfRotations 0
            snap FALSE
          }
        }
      ]
    }
  ]
  rightHandSlot [
    Transform {
      translation 0.06 0 0
      children [
        BallJoint {
          jointParameters BallJointParameters {
            springConstant 1
          }
          endPoint Connector {
            isLocked TRUE
            autoLock TRUE
            distanceTolerance 0.05
            axisTolerance 3.14159
            rotationTolerance 3.14159
            numberOfRotations 0
            snap FALSE
          }
        }
      ]
    }
  ]
}
FloorLight {
  translation -2.00175 -8.88178e-16 1.89667
}
FloorLight {
  translation 2.00366 2.22044e-15 -2.13347
}
DEF Swing Robot {
  translation 0 2.2 0
  rotation 1 0 0 -1.5708
  children [
    DEF RArm Transform {
      translation 0 0.25 -0.06
      children [
        HingeJoint {
          jointParameters HingeJointParameters {
            position 0.262147
            axis 0 1 0
            anchor 0 1 0
            minStop -3.1416
            maxStop 3.1416
            dampingConstant 1
          }
          endPoint Solid {
            translation -0.343928 0.0100206 -0.672005
            rotation -0.953389 -0.212801 0.21393 -1.62229
            children [
              Transform {
                translation 0 -0.75 0
                children [
                  DEF SeatShape Solid {
                    translation 0 0 0.25
                    children [
                      DEF Mid_bar Transform {
                        translation 0.05 0.05 0
                        children [
                          SolidBox {
                            size 0.08 0.05 0.01
                            physics Physics {
                            }
                          }
                        ]
                      }
                      Emitter {
                        name "SeatEmitter"
                      }
                      DEF Seat_IU InertialUnit {
                        name "Seat_IU"
                      }
                      Gyro {
                        name "Seat_Gyro"
                      }
                      DEF Right_bar Transform {
                        translation 0 0.04 0.1
                        children [
                          SolidBox {
                            size 0.1 0.05 0.01
                            physics Physics {
                            }
                          }
                        ]
                      }
                      DEF Left_bar Transform {
                        translation 0 0.04 -0.1
                        children [
                          SolidBox {
                            size 0.1 0.05 0.01
                            physics Physics {
                            }
                          }
                        ]
                      }
                      DEF Front_bar Transform {
                        translation 0.065 0.075 0
                        children [
                          SolidBox {
                            size 0.06 0.01 0.5
                            physics Physics {
                            }
                          }
                        ]
                      }
                      DEF C1 Connector {
                        translation 0 0 0.25
                        rotation 1 0 0 -1.5708
                        isLocked TRUE
                        autoLock TRUE
                        distanceTolerance 0.05
                        numberOfRotations 0
                        snap FALSE
                      }
                      DEF SeatCon Connector {
                        translation 0 0 0.25
                        rotation 1 0 0 -1.5708
                        autoLock TRUE
                        numberOfRotations 0
                      }
                      Shape {
                        appearance Appearance {
                          material Material {
                          }
                        }
                        geometry DEF SSeat Box {
                          size 0.1 0.01 0.5
                        }
                      }
                    ]
                    boundingObject USE SSeat
                    physics Physics {
                    }
                  }
                ]
              }
              DEF RVBar Shape {
                appearance Appearance {
                  material Material {
                  }
                }
                geometry Cylinder {
                  height 1.5
                  radius 0.05
                }
              }
            ]
            boundingObject USE RVBar
            physics Physics {
              centerOfMass [
                0 0 0
              ]
            }
            linearVelocity 0.501185 -0.256531 -0.00019304
            angularVelocity 0.000185033 -3.06694e-05 0.696631
          }
        }
      ]
    }
    DEF LArm Transform {
      translation 0 -0.25 -0.06
      children [
        HingeJoint {
          jointParameters HingeJointParameters {
            position 0.262253
            axis 0 1 0
            anchor 0 1 0
            minStop -3.1416
            maxStop 3.1416
            dampingConstant 0.287
          }
          endPoint Solid {
            translation -0.349477 0.00216986 -0.685518
            rotation -0.953397 -0.212845 0.213847 -1.62296
            children [
              DEF C1 Connector {
                translation 0 -0.75 0
                rotation 1 0 0 1.5708
                isLocked TRUE
                autoLock TRUE
                distanceTolerance 0.05
                numberOfRotations 0
                snap FALSE
              }
              DEF SVBar2 Shape {
                appearance Appearance {
                  material Material {
                  }
                }
                geometry Cylinder {
                  height 1.5
                  radius 0.05
                }
              }
            ]
            boundingObject USE SVBar2
            physics Physics {
              centerOfMass [
                0 0 0
              ]
            }
            linearVelocity 0.476496 -0.246049 -0.000149279
            angularVelocity 0.000271952 -5.40035e-05 0.69676
          }
        }
      ]
    }
    DEF SHBarShape Shape {
      appearance DEF SwingApp Appearance {
        material Material {
          diffuseColor 0.7 0.4 0.8
        }
        texture ImageTexture {
        }
      }
      geometry DEF SHBar Cylinder {
        height 0.5
        radius 0.05
      }
    }
  ]
  name "Swing"
  boundingObject USE SHBarShape
  controller "swingcontroller"
  selfCollision TRUE
}
