#VRML_SIM V8.3.2 utf8
WorldInfo {
  basicTimeStep 8
}
Viewpoint {
  orientation 0.000928583 -0.96044 -0.278487 3.16986
  position 1.60036 30.803 -48.0915
}
Background {
  skyColor [
    0.4 0.7 1
  ]
}
Ceiling {
  translation 0 3 0
  size 5 5
}
DirectionalLight {
  ambientIntensity 1
  direction -0.1 -0.5 -0.3
}
RectangleArena {
  floorSize 5 5
}
Nao {
  hidden position_0_0 -1.16814e-09
  hidden position2_0_0 -1.97104e-06
  hidden position_0_1 0.400014
  hidden position2_0_1 -3.82824e-07
  hidden position_0_2 0.400013
  hidden position2_0_2 2.81114e-07
  hidden position_0_3 7.32813e-06
  hidden position_0_4 1.01408e-05
  hidden linearVelocity_0 -1.31519 0.382208 -0.0018955
  hidden angularVelocity_0 -0.0205499 0.0105893 -2.89265
  hidden translation_12 -3.77768e-05 1.10364e-06 0.126641
  hidden rotation_12 -0.0147196 0.999891 0.000592576 -1.97124e-06
  hidden linearVelocity_12 -0.961872 0.478806 -0.00404691
  hidden angularVelocity_12 -0.0205499 0.0105893 -2.89265
  hidden translation_19 0.000215464 -0.0981668 0.100064
  hidden rotation_19 -0.754538 0.656257 -0.000142184 0.400104
  hidden position_19_0 -0.0481311
  hidden linearVelocity_19 -1.1532 0.371768 -0.00308342
  hidden angularVelocity_19 -0.0205498 0.0105897 -2.89265
  hidden translation_20 0.105319 -0.0151607 2.5006e-05
  hidden rotation_20 -1 0.000126721 0.000138732 0.048144
  hidden position_20_0 4.135e-07
  hidden linearVelocity_20 -1.13534 0.192025 -0.00385175
  hidden angularVelocity_20 -0.0205492 0.0105898 -2.89265
  hidden translation_21 -0.000144423 -0.000412138 2.16427e-05
  hidden rotation_21 0.969377 0.238203 0.0597267 4.22995e-06
  hidden position_21_0 0.0043049
  hidden linearVelocity_21 -1.12471 0.0397936 -0.0044697
  hidden angularVelocity_21 -0.0205492 0.0105898 -2.89265
  hidden translation_22 0.0558301 -0.000414153 3.17988e-05
  hidden rotation_22 0.999975 0.000484311 0.00700344 0.00429281
  hidden position_22_0 2.65656e-05
  hidden position_22_1 -8.37054e-11
  hidden position_22_2 1.44456e-09
  hidden linearVelocity_22 -1.11539 -0.147079 -0.00520128
  hidden angularVelocity_22 -0.0205494 0.0105898 -2.89265
  hidden translation_23 0.0688388 -0.0134163 -0.0049592
  hidden rotation_23 2.43598e-05 -1 -6.29125e-05 -0.959982
  hidden position_23_1 4.31368e-10
  hidden linearVelocity_23 -1.13337 -0.255708 -0.00546267
  hidden angularVelocity_23 -0.0205494 0.0105898 -2.89265
  hidden translation_25 0.0140192 7.04682e-06 -6.78875e-06
  hidden rotation_25 1.43286e-09 -1 -3.63964e-09 -0.96
  hidden position_25_0 3.54067e-10
  hidden linearVelocity_25 -1.16641 -0.263752 -0.00525831
  hidden angularVelocity_25 -0.0205494 0.0105898 -2.89265
  hidden translation_26 0.0140198 4.98763e-06 -8.63632e-06
  hidden rotation_26 -3.51556e-11 -1 -6.75269e-11 -0.96
  hidden linearVelocity_26 -1.19198 -0.239588 -0.00499192
  hidden angularVelocity_26 -0.0205494 0.0105898 -2.89265
  hidden translation_27 0.0690715 0.0130107 -0.00502396
  hidden rotation_27 -5.02199e-10 -1 -3.59773e-10 -0.96
  hidden position_27_0 5.76524e-10
  hidden linearVelocity_27 -1.15895 -0.259526 -0.0052939
  hidden angularVelocity_27 -0.0205494 0.0105898 -2.89265
  hidden translation_28 0.0140192 7.04725e-06 -6.78905e-06
  hidden rotation_28 -1.92697e-10 -1 -2.3508e-10 -0.96
  hidden position_28_0 3.54213e-10
  hidden linearVelocity_28 -1.192 -0.26757 -0.00508954
  hidden angularVelocity_28 -0.0205494 0.0105898 -2.89265
  hidden translation_29 0.0140198 4.98683e-06 -8.6365e-06
  hidden rotation_29 -3.51667e-11 -1 -6.75511e-11 -0.96
  hidden linearVelocity_29 -1.21756 -0.243406 -0.00482315
  hidden angularVelocity_29 -0.0205494 0.0105898 -2.89265
  hidden translation_30 0.0490396 1.69491e-05 -0.0260446
  hidden rotation_30 -0.0392896 0.981555 0.187098 1.46782e-09
  hidden position_30_0 1.64166e-10
  hidden linearVelocity_30 -1.19198 -0.208443 -0.00487991
  hidden angularVelocity_30 -0.0205494 0.0105898 -2.89265
  hidden translation_31 0.0140205 -2.52133e-06 9.23167e-06
  hidden rotation_31 3.51388e-11 1 -6.7499e-11 -0.96
  hidden linearVelocity_31 -1.17748 -0.241263 -0.00509911
  hidden angularVelocity_31 -0.0205494 0.0105898 -2.89265
  hidden translation_32 0.000203269 0.0981784 0.100114
  hidden rotation_32 0.857115 0.515111 0.00371451 0.40457
  hidden position_32_0 0.0545948
  hidden linearVelocity_32 -1.15069 0.375734 -0.00307413
  hidden angularVelocity_32 -0.02055 0.010589 -2.89265
  hidden translation_33 0.105303 0.0151821 4.72339e-05
  hidden rotation_33 1 0.000212436 -0.000215822 0.05461
  hidden position_33_0 -9.02702e-07
  hidden linearVelocity_33 -1.11998 0.198333 -0.00392159
  hidden angularVelocity_33 -0.0205506 0.0105889 -2.89265
  hidden translation_34 -2.15929e-05 0.000240854 3.91849e-05
  hidden rotation_34 -0.497513 0.867147 -0.0231908 1.15864e-05
  hidden position_34_0 -0.0754383
  hidden linearVelocity_34 -1.10072 0.0467092 -0.00459761
  hidden angularVelocity_34 -0.0205506 0.0105889 -2.89265
  hidden translation_35 0.0559538 0.000242512 3.55054e-05
  hidden rotation_35 -1 0.000156782 -0.00033854 0.0754274
  hidden position_35_0 -9.15711e-11
  hidden position_35_1 -9.39192e-11
  hidden position_35_2 1.47154e-09
  hidden linearVelocity_35 -1.08157 -0.139819 -0.00539752
  hidden angularVelocity_35 -0.0205504 0.010589 -2.89265
  hidden translation_36 0.0689653 -0.0127634 -0.00495371
  hidden rotation_36 -1.4371e-05 -1 4.19912e-05 -0.959958
  hidden position_36_1 2.11518e-09
  hidden linearVelocity_36 -1.1182 -0.254309 -0.00554716
  hidden angularVelocity_36 -0.0205504 0.010589 -2.89265
  hidden translation_38 0.0140191 -6.9844e-06 -6.89371e-06
  hidden rotation_38 -2.661e-09 -1 -2.42336e-09 -0.96
  hidden position_38_0 3.48328e-10
  hidden linearVelocity_38 -1.15093 -0.264045 -0.00535042
  hidden angularVelocity_38 -0.0205504 0.010589 -2.89265
  hidden translation_39 0.0140201 -4.73786e-06 -8.6381e-06
  hidden rotation_39 3.43883e-11 -1 6.60679e-11 -0.96
  hidden linearVelocity_39 -1.17791 -0.241252 -0.00507852
  hidden angularVelocity_39 -0.0205504 0.010589 -2.89265
  hidden translation_40 0.0690687 0.0129938 -0.00500928
  hidden rotation_40 4.90945e-10 -1 3.51755e-10 -0.96
  hidden position_40_0 5.28811e-10
  hidden linearVelocity_40 -1.09486 -0.249448 -0.00569294
  hidden angularVelocity_40 -0.0205504 0.010589 -2.89265
  hidden translation_41 0.0140191 -6.98471e-06 -6.89395e-06
  hidden rotation_41 1.88403e-10 -1 2.29833e-10 -0.96
  hidden position_41_0 3.48223e-10
  hidden linearVelocity_41 -1.12759 -0.259183 -0.0054962
  hidden angularVelocity_41 -0.0205504 0.010589 -2.89265
  hidden translation_42 0.0140201 -4.73718e-06 -8.63823e-06
  hidden rotation_42 3.4377e-11 -1 6.60472e-11 -0.96
  hidden linearVelocity_42 -1.15457 -0.236389 -0.0052243
  hidden angularVelocity_42 -0.0205504 0.010589 -2.89265
  hidden translation_43 0.0490393 -1.70903e-05 -0.0260447
  hidden rotation_43 0.0389473 0.981872 -0.1855 1.44821e-09
  hidden position_43_0 1.52156e-10
  hidden linearVelocity_43 -1.15516 -0.204985 -0.0051093
  hidden angularVelocity_43 -0.0205504 0.010589 -2.89265
  hidden translation_44 0.0140205 2.25334e-06 9.33752e-06
  hidden rotation_44 -3.43653e-11 1 6.60419e-11 -0.96
  hidden linearVelocity_44 -1.13881 -0.236989 -0.00533879
  hidden angularVelocity_44 -0.0205504 0.010589 -2.89265
  hidden translation_45 0.000128026 -0.0499911 -0.0850943
  hidden rotation_45 -0.275588 0.958556 -0.0722533 9.40456e-06
  hidden position_45_0 -1.38969e-06
  hidden linearVelocity_45 -1.60048 0.306297 -0.000121834
  hidden angularVelocity_45 -0.0205443 0.0106019 -2.89264
  hidden translation_46 0.000118725 1.01386e-05 4.29244e-05
  hidden rotation_46 -0.129173 0.981583 -0.140744 8.87254e-06
  hidden position_46_0 -0.943289
  hidden linearVelocity_46 -1.69459 0.300334 0.00055253
  hidden angularVelocity_46 -0.0205373 0.010617 -2.89263
  hidden translation_47 0.000142522 5.29187e-06 0.000114224
  hidden rotation_47 -1.72618e-06 1 1.27472e-05 -0.943289
  hidden position_47_0 0.932566
  hidden linearVelocity_47 -1.68727 0.200631 -2.93706e-05
  hidden angularVelocity_47 0.00337602 0.00174986 -1.18948
  hidden translation_48 -0.000839611 -2.64292e-06 -0.100849
  hidden rotation_48 -4.93175e-06 1 2.14587e-05 0.932566
  hidden position_48_0 9.87307e-07
  hidden linearVelocity_48 -2.05821 -0.00690788 0.00314954
  hidden angularVelocity_48 -0.0872592 0.0354394 -7.59114
  hidden translation_49 -1.71224e-05 -1.48992e-06 -0.103967
  hidden rotation_49 0.103783 0.993496 -0.0468406 9.82337e-07
  hidden position_49_0 2.04472e-07
  hidden linearVelocity_49 -2.41036 -0.0934589 0.00679332
  hidden angularVelocity_49 -0.0872592 0.0354394 -7.59114
  hidden translation_50 0.000611988 -1.12284e-06 -0.000833787
  hidden rotation_50 0.0165719 0.997995 -0.0610773 7.16264e-07
  hidden linearVelocity_50 -2.63545 -0.374125 0.0080943
  hidden angularVelocity_50 -0.0872591 0.0354394 -7.59114
  hidden translation_53 0.0198904 -0.00700021 -0.04121
  hidden rotation_53 -2.60689e-08 -8.50457e-10 1 -3.14159
  hidden linearVelocity_53 -2.71209 -0.355992 0.00905564
  hidden angularVelocity_53 -0.0872591 0.0354394 -7.59114
  hidden translation_57 0.000113377 0.0500069 -0.0851007
  hidden rotation_57 -0.156376 0.982274 -0.10337 1.08005e-05
  hidden position_57_0 -1.10856e-06
  hidden linearVelocity_57 -1.60006 0.308005 -0.000140514
  hidden angularVelocity_57 -0.0205555 0.0105723 -2.89265
  hidden translation_58 0.000104608 7.96006e-06 3.57996e-05
  hidden rotation_58 -0.0206592 0.995206 -0.0955891 1.08421e-05
  hidden position_58_0 -0.942762
  hidden linearVelocity_58 -1.694 0.302628 0.000510257
  hidden angularVelocity_58 -0.0205849 0.0105555 -2.89264
  hidden translation_59 0.000125807 4.84727e-06 0.000103528
  hidden rotation_59 -2.13526e-06 1 1.309e-05 -0.942762
  hidden position_59_0 0.932566
  hidden linearVelocity_59 -1.68659 0.203494 -3.53464e-05
  hidden angularVelocity_59 0.00339936 0.00163474 -1.18379
  hidden translation_60 -0.000834776 -2.82868e-06 -0.100864
  hidden rotation_60 -5.62372e-06 1 2.13524e-05 0.932566
  hidden position_60_0 9.86946e-07
  hidden linearVelocity_60 -2.05731 -0.00356215 0.00315112
  hidden angularVelocity_60 -0.0872426 0.0353424 -7.58545
  hidden translation_61 -1.69453e-05 -1.50269e-06 -0.103968
  hidden rotation_61 -0.116073 0.992534 0.0374587 9.8111e-07
  hidden position_61_0 4.20796e-09
  hidden linearVelocity_61 -2.40928 -0.0899001 0.00679666
  hidden angularVelocity_61 -0.0872427 0.0353424 -7.58545
  hidden translation_62 0.00061249 -1.1072e-06 -0.000833971
  hidden rotation_62 -0.00416653 0.998796 0.0488738 7.15745e-07
  hidden linearVelocity_62 -2.63435 -0.370092 0.00810422
  hidden angularVelocity_62 -0.0872429 0.0353424 -7.58545
  hidden translation_65 0.0198892 0.00699983 -0.0412113
  hidden rotation_65 2.87693e-08 -7.04472e-10 1 -3.14159
  hidden linearVelocity_65 -2.7109 -0.351767 0.00906624
  hidden angularVelocity_65 -0.0872429 0.0353424 -7.58545
  translation -0.265226 0.786779 -0.007111
  rotation 0.980772 0.131229 -0.14445 -1.58272
  controller "my_controller"
  bodySlot [
    Receiver {
      name "Robot_Receiver"
    }
  ]
  leftFootSlot [
    InertialUnit {
    }
    Gyro {
      name ""
    }
  ]
  rightFootSlot [
    DEF Right_Foot_Gyro Gyro {
      rotation 1 0 0 1.5708
      name "Right_Foot_Gyro"
    }
    InertialUnit {
      name "Right_Foot_IU"
    }
  ]
  leftHandSlot [
    Transform {
      translation 0.06 0 0
      children [
        BallJoint {
          jointParameters BallJointParameters {
            springConstant 1
          }
          endPoint Connector {
            isLocked TRUE
            autoLock TRUE
            distanceTolerance 0.05
            axisTolerance 3.14159
            rotationTolerance 3.14159
            numberOfRotations 0
            snap FALSE
          }
        }
      ]
    }
  ]
  rightHandSlot [
    Transform {
      translation 0.06 0 0
      children [
        BallJoint {
          jointParameters BallJointParameters {
            springConstant 1
          }
          endPoint Connector {
            isLocked TRUE
            autoLock TRUE
            distanceTolerance 0.05
            axisTolerance 3.14159
            rotationTolerance 3.14159
            numberOfRotations 0
            snap FALSE
          }
        }
      ]
    }
  ]
}
FloorLight {
  translation -2.00175 -8.88178e-16 1.89667
}
FloorLight {
  translation 2.00366 2.22044e-15 -2.13347
}
DEF Swing Robot {
  translation 0 2.2 0
  rotation 1 0 0 -1.5708
  children [
    DEF RArm Transform {
      translation 0 0.25 -0.06
      children [
        HingeJoint {
          jointParameters HingeJointParameters {
            position -0.00843432
            axis 0 1 0
            anchor 0 1 0
            minStop -3.1416
            maxStop 3.1416
            dampingConstant 1
          }
          endPoint Solid {
            translation -0.152309 0.00872284 -0.745031
            rotation -0.992811 -0.0843252 0.0849439 -1.58364
            children [
              Transform {
                translation 0 -0.75 0
                children [
                  DEF SeatShape Solid {
                    translation 0 0 0.25
                    children [
                      DEF back_bar Transform {
                        translation -0.055 0.075 0
                        children [
                          SolidBox {
                            size 0.01 0.01 0.5
                            physics Physics {
                            }
                          }
                        ]
                      }
                      Emitter {
                        name "SeatEmitter"
                      }
                      DEF Seat_IU InertialUnit {
                        name "Seat_IU"
                      }
                      Gyro {
                        name "Seat_Gyro"
                      }
                      DEF Right_bar Transform {
                        translation 0 0.04 0.1
                        children [
                          SolidBox {
                            size 0.1 0.01 0.01
                            physics Physics {
                            }
                          }
                        ]
                      }
                      DEF Left_bar Transform {
                        translation 0 0.04 -0.1
                        children [
                          SolidBox {
                            size 0.1 0.01 0.01
                            physics Physics {
                            }
                          }
                        ]
                      }
                      DEF Front_bar Transform {
                        translation 0.055 0.075 0
                        children [
                          SolidBox {
                            size 0.01 0.01 0.5
                            physics Physics {
                            }
                          }
                        ]
                      }
                      DEF C1 Connector {
                        translation 0 0 0.25
                        rotation 1 0 0 -1.5708
                        isLocked TRUE
                        autoLock TRUE
                        distanceTolerance 0.05
                        numberOfRotations 0
                        snap FALSE
                      }
                      DEF SeatCon Connector {
                        translation 0 0 0.25
                        rotation 1 0 0 -1.5708
                        autoLock TRUE
                        numberOfRotations 0
                      }
                      Shape {
                        appearance Appearance {
                          material Material {
                          }
                        }
                        geometry DEF SSeat Box {
                          size 0.1 0.01 0.5
                        }
                      }
                    ]
                    boundingObject USE SSeat
                    physics Physics {
                    }
                  }
                ]
              }
              DEF RVBar Shape {
                appearance Appearance {
                  material Material {
                  }
                }
                geometry Cylinder {
                  height 1.5
                  radius 0.05
                }
              }
            ]
            boundingObject USE RVBar
            physics Physics {
              centerOfMass [
                0 0 0
              ]
            }
            linearVelocity -0.907904 0.18036 1.56255e-05
            angularVelocity -1.74078e-05 2.53116e-05 -1.16099
          }
        }
      ]
    }
    DEF LArm Transform {
      translation 0 -0.25 -0.06
      children [
        HingeJoint {
          jointParameters HingeJointParameters {
            position -0.00804463
            axis 0 1 0
            anchor 0 1 0
            minStop -3.1416
            maxStop 3.1416
            dampingConstant 1
          }
          endPoint Solid {
            translation -0.153066 0.00437211 -0.748259
            rotation -0.992766 -0.0846829 0.0851159 -1.58194
            children [
              DEF C1 Connector {
                translation 0 -0.75 0
                rotation 1 0 0 1.5708
                isLocked TRUE
                autoLock TRUE
                distanceTolerance 0.05
                numberOfRotations 0
                snap FALSE
              }
              DEF SVBar2 Shape {
                appearance Appearance {
                  material Material {
                  }
                }
                geometry Cylinder {
                  height 1.5
                  radius 0.05
                }
              }
            ]
            boundingObject USE SVBar2
            physics Physics {
              centerOfMass [
                0 0 0
              ]
            }
            linearVelocity -0.869429 0.174132 1.60887e-05
            angularVelocity -1.95849e-05 2.0531e-05 -1.161
          }
        }
      ]
    }
    DEF SHBarShape Shape {
      appearance DEF SwingApp Appearance {
        material Material {
          diffuseColor 0.7 0.4 0.8
        }
        texture ImageTexture {
        }
      }
      geometry DEF SHBar Cylinder {
        height 0.5
        radius 0.05
      }
    }
  ]
  name "Swing"
  boundingObject USE SHBarShape
  controller "swingcontroller"
  selfCollision TRUE
}
