#VRML_SIM V8.3.2 utf8
WorldInfo {
  basicTimeStep 16
}
Viewpoint {
  orientation 0.0334947 -0.980929 -0.19146 3.51339
  position 18.5289 20.6428 -45.7708
}
Background {
  skyColor [
    0.4 0.7 1
  ]
}
Ceiling {
  translation 0 3 0
  size 5 5
}
DirectionalLight {
  ambientIntensity 1
  direction -0.1 -0.5 -0.3
}
RectangleArena {
  floorSize 5 5
}
Nao {
  hidden position_0_0 -9.76044e-10
  hidden position2_0_0 -2.20832e-07
  hidden position_0_1 0.400002
  hidden position2_0_1 -5.02591e-08
  hidden position_0_2 0.400002
  hidden position2_0_2 3.48283e-08
  hidden position_0_3 8.25278e-07
  hidden position_0_4 2.2275e-06
  hidden linearVelocity_0 6.23089e-05 4.0542e-05 1.14419e-06
  hidden angularVelocity_0 -5.66709e-07 -5.35829e-06 -0.000137584
  hidden translation_11 -8.2099e-06 -4.18219e-07 0.12646
  hidden rotation_11 -0.0820556 0.996618 0.0044048 -2.21581e-07
  hidden linearVelocity_11 7.94563e-05 4.38152e-05 8.53707e-07
  hidden angularVelocity_11 -5.66641e-07 -5.35828e-06 -0.000137587
  hidden translation_18 0.000204485 -0.098167 0.100009
  hidden rotation_18 -0.754549 0.656244 -0.000144115 0.400104
  hidden position_18_0 -0.0481308
  hidden linearVelocity_18 6.94073e-05 3.99648e-05 1.09267e-06
  hidden angularVelocity_18 -5.6688e-07 -5.35832e-06 -0.000137583
  hidden translation_19 0.105208 -0.0151675 3.60788e-05
  hidden rotation_19 -1 0.00010017 0.000130249 0.048144
  hidden position_19_0 6.0444e-08
  hidden linearVelocity_19 6.93153e-05 3.14289e-05 1.41132e-06
  hidden angularVelocity_19 7.6645e-07 -5.2224e-06 -0.000137488
  hidden translation_20 -0.000236735 -0.00041904 3.21963e-05
  hidden rotation_20 -0.995487 0.0938319 -0.0141563 -4.11602e-06
  hidden position_20_0 0.00430464
  hidden linearVelocity_20 6.91016e-05 2.41228e-05 1.68851e-06
  hidden angularVelocity_20 7.66712e-07 -5.22618e-06 -0.000137487
  hidden translation_21 0.0557151 -0.000419849 3.667e-05
  hidden rotation_21 0.999976 0.000373715 0.0069645 0.00429279
  hidden position_21_0 2.65657e-05
  hidden position_21_1 -6.58133e-11
  hidden position_21_2 5.59891e-10
  hidden linearVelocity_21 6.87365e-05 1.51308e-05 2.03113e-06
  hidden angularVelocity_21 1.24049e-06 -5.17789e-06 -0.000137453
  hidden translation_22 0.0687702 -0.0134216 -0.00495028
  hidden rotation_22 2.43598e-05 -1 -6.29125e-05 -0.959982
  hidden position_22_1 8.44157e-11
  hidden linearVelocity_22 6.73407e-05 1.00753e-05 2.21869e-06
  hidden angularVelocity_22 1.24049e-06 -5.1779e-06 -0.000137453
  hidden translation_24 0.014 1.1889e-08 -5.22384e-08
  hidden rotation_24 1.57063e-09 -1 -3.47157e-09 -0.96
  hidden position_24_0 1.37873e-10
  hidden linearVelocity_24 6.57043e-05 9.83943e-06 2.22237e-06
  hidden angularVelocity_24 1.24049e-06 -5.1779e-06 -0.000137453
  hidden translation_25 0.014 8.25902e-09 -1.77606e-08
  hidden rotation_25 -1.0011e-11 -1 -1.92239e-11 -0.96
  hidden linearVelocity_25 6.45646e-05 1.1111e-05 2.17025e-06
  hidden angularVelocity_25 1.24049e-06 -5.1779e-06 -0.000137453
  hidden translation_26 0.0690001 0.013 -0.00500011
  hidden rotation_26 -1.43035e-10 -1 -1.02383e-10 -0.96
  hidden position_26_0 2.29395e-10
  hidden linearVelocity_26 6.6217e-05 9.8949e-06 2.22278e-06
  hidden angularVelocity_26 1.24055e-06 -5.1781e-06 -0.000137454
  hidden translation_27 0.014 1.18709e-08 -5.22435e-08
  hidden rotation_27 -5.48578e-11 -1 -6.69249e-11 -0.96
  hidden position_27_0 1.37892e-10
  hidden linearVelocity_27 6.45806e-05 9.6591e-06 2.22646e-06
  hidden angularVelocity_27 1.24055e-06 -5.1781e-06 -0.000137454
  hidden translation_28 0.014 8.25784e-09 -1.7762e-08
  hidden rotation_28 -1.00083e-11 -1 -1.92254e-11 -0.96
  hidden linearVelocity_28 6.3441e-05 1.09307e-05 2.17434e-06
  hidden angularVelocity_28 1.24055e-06 -5.1781e-06 -0.000137454
  hidden translation_29 0.049 1.73959e-08 -0.026
  hidden rotation_29 -0.0280446 0.990705 0.133108 5.87038e-10
  hidden position_29_0 6.52649e-11
  hidden linearVelocity_29 6.47619e-05 1.25438e-05 2.11675e-06
  hidden angularVelocity_29 1.24049e-06 -5.17789e-06 -0.000137453
  hidden translation_30 0.014 -2.1206e-11 -4.03968e-09
  hidden rotation_30 1.00152e-11 1 -1.9212e-11 -0.96
  hidden linearVelocity_30 6.53287e-05 1.0908e-05 2.18089e-06
  hidden angularVelocity_30 1.24049e-06 -5.17789e-06 -0.000137453
  hidden translation_31 0.000193928 0.0981777 0.100055
  hidden rotation_31 0.857123 0.515098 0.00371695 0.40457
  hidden position_31_0 0.0545945
  hidden linearVelocity_31 7.04521e-05 3.90682e-05 1.12167e-06
  hidden angularVelocity_31 -5.66663e-07 -5.3583e-06 -0.000137583
  hidden translation_32 0.105193 0.0151899 5.50167e-05
  hidden rotation_32 1 0.000189771 -0.000207075 0.05461
  hidden position_32_0 -3.3857e-07
  hidden linearVelocity_32 7.12187e-05 3.03185e-05 1.44139e-06
  hidden angularVelocity_32 7.44905e-07 -5.1517e-06 -0.000137591
  hidden translation_33 -0.000112876 0.000249139 4.84349e-05
  hidden rotation_33 -0.552492 0.833475 -0.00852075 1.04394e-05
  hidden position_33_0 -0.0754383
  hidden linearVelocity_33 7.14634e-05 2.29657e-05 1.70123e-06
  hidden angularVelocity_33 6.52794e-07 -4.55688e-06 -0.000137338
  hidden translation_34 0.0558392 0.000249722 3.96363e-05
  hidden rotation_34 -1 0.00015063 -0.000336168 0.0754274
  hidden position_34_0 -5.39221e-11
  hidden position_34_1 -5.49908e-11
  hidden position_34_2 6.06408e-10
  hidden linearVelocity_34 7.15588e-05 1.39715e-05 2.00026e-06
  hidden angularVelocity_34 1.16932e-06 -4.47553e-06 -0.000137341
  hidden translation_35 0.0688941 -0.012752 -0.00493038
  hidden rotation_35 -1.4371e-05 -1 4.19912e-05 -0.959958
  hidden position_35_1 1.81576e-09
  hidden linearVelocity_35 6.93158e-05 8.66039e-06 2.16804e-06
  hidden angularVelocity_35 1.16932e-06 -4.47553e-06 -0.000137341
  hidden translation_37 0.014 -1.21311e-08 -5.20755e-08
  hidden rotation_37 -2.79336e-09 -1 -2.58482e-09 -0.96
  hidden position_37_0 1.37606e-10
  hidden linearVelocity_37 6.77246e-05 8.30958e-06 2.17429e-06
  hidden angularVelocity_37 1.16932e-06 -4.47553e-06 -0.000137341
  hidden translation_38 0.014 -9.36425e-09 -1.75687e-08
  hidden rotation_38 1.02352e-11 -1 1.96666e-11 -0.96
  hidden linearVelocity_38 6.65355e-05 9.4989e-06 2.13096e-06
  hidden angularVelocity_38 1.16932e-06 -4.47553e-06 -0.000137341
  hidden translation_39 0.0690001 0.013 -0.00500011
  hidden rotation_39 1.46223e-10 -1 1.04689e-10 -0.96
  hidden position_39_0 2.29375e-10
  hidden linearVelocity_39 7.05521e-05 8.69914e-06 2.17155e-06
  hidden angularVelocity_39 1.16932e-06 -4.47553e-06 -0.000137341
  hidden translation_40 0.014 -1.21244e-08 -5.20922e-08
  hidden rotation_40 5.61122e-11 -1 6.84488e-11 -0.96
  hidden position_40_0 1.37622e-10
  hidden linearVelocity_40 6.89609e-05 8.34841e-06 2.1778e-06
  hidden angularVelocity_40 1.16932e-06 -4.47553e-06 -0.000137341
  hidden translation_41 0.014 -9.36462e-09 -1.75813e-08
  hidden rotation_41 1.02346e-11 -1 1.96669e-11 -0.96
  hidden linearVelocity_41 6.77718e-05 9.53777e-06 2.13448e-06
  hidden angularVelocity_41 1.16932e-06 -4.47553e-06 -0.000137341
  hidden translation_42 0.049 -1.64794e-08 -0.026
  hidden rotation_42 0.0286938 0.990247 -0.136335 5.86449e-10
  hidden position_42_0 6.52311e-11
  hidden linearVelocity_42 6.78136e-05 1.11027e-05 2.08255e-06
  hidden angularVelocity_42 1.16932e-06 -4.47553e-06 -0.000137341
  hidden translation_43 0.014 1.12869e-09 -4.48041e-09
  hidden rotation_43 -1.02375e-11 1 1.96667e-11 -0.96
  hidden linearVelocity_43 6.84614e-05 9.50929e-06 2.13741e-06
  hidden angularVelocity_43 1.16932e-06 -4.47553e-06 -0.000137341
  hidden translation_44 4.00909e-05 -0.0499987 -0.084959
  hidden rotation_44 -0.566602 0.8233 -0.033745 3.46271e-06
  hidden position_44_0 9.51949e-07
  hidden linearVelocity_44 4.86626e-05 3.81349e-05 1.35721e-06
  hidden angularVelocity_44 -5.66889e-07 -5.36449e-06 -0.000137576
  hidden translation_45 4.28509e-05 1.30776e-06 4.52573e-05
  hidden rotation_45 -0.133668 0.967804 -0.213282 2.62844e-06
  hidden position_45_0 -0.799998
  hidden linearVelocity_45 4.46331e-05 3.81472e-05 1.3612e-06
  hidden angularVelocity_45 3.99078e-06 -3.65296e-06 -0.00013742
  hidden translation_46 1.09871e-05 1.39592e-06 5.72746e-05
  hidden rotation_46 2.34046e-06 1 -1.02621e-06 -0.799998
  hidden position_46_0 1.49998
  hidden linearVelocity_46 4.2569e-05 2.95678e-05 1.54104e-06
  hidden angularVelocity_46 3.99052e-06 -3.65919e-06 -0.00013741
  hidden translation_47 -3.67182e-05 -3.78883e-07 -0.0999841
  hidden rotation_47 1.79445e-09 1 -6.01216e-08 1.49998
  hidden position_47_0 4.95765e-07
  hidden linearVelocity_47 1.89142e-05 3.05836e-05 9.79833e-07
  hidden angularVelocity_47 1.25784e-05 -2.59466e-06 -0.000416989
  hidden translation_48 -9.37379e-06 -1.9076e-07 -0.102916
  hidden rotation_48 0.100151 0.99309 -0.0611777 4.932e-07
  hidden position_48_0 1.84328e-07
  hidden linearVelocity_48 1.43032e-06 3.98141e-05 3.94335e-07
  hidden angularVelocity_48 1.25784e-05 -2.59474e-06 -0.00041699
  hidden translation_49 -5.17029e-06 -1.07126e-07 -1.01492e-05
  hidden rotation_49 0.0257239 0.997318 -0.0685214 4.22423e-07
  hidden linearVelocity_49 -1.78866e-05 3.65896e-05 -1.59224e-07
  hidden angularVelocity_49 1.28215e-05 -2.68079e-06 -0.000416983
  hidden translation_50 0.0199943 -0.00699994 -0.0410061
  hidden rotation_50 -2.10805e-08 -8.5598e-10 1 -3.14159
  hidden linearVelocity_50 -2.03729e-05 4.00999e-05 -2.61306e-07
  hidden angularVelocity_50 1.28215e-05 -2.68079e-06 -0.000416983
  hidden translation_54 4.7384e-05 0.0500013 -0.0849784
  hidden rotation_54 -0.407526 0.888514 -0.210866 3.25411e-06
  hidden position_54_0 5.56597e-07
  hidden linearVelocity_54 4.89197e-05 3.77643e-05 1.38756e-06
  hidden angularVelocity_54 -5.66886e-07 -5.36142e-06 -0.000137585
  hidden translation_55 5.01428e-05 1.35852e-06 2.59004e-05
  hidden rotation_55 0.00658285 0.945246 -0.326292 3.78337e-06
  hidden position_55_0 -0.799998
  hidden linearVelocity_55 4.48582e-05 3.76761e-05 1.41556e-06
  hidden angularVelocity_55 3.49979e-06 -3.8303e-06 -0.000137454
  hidden translation_56 1.19283e-05 1.44892e-06 3.67851e-05
  hidden rotation_56 2.41384e-06 1 1.24679e-07 -0.799998
  hidden position_56_0 1.49998
  hidden linearVelocity_56 4.26562e-05 2.91025e-05 1.62913e-06
  hidden angularVelocity_56 3.4991e-06 -3.83208e-06 -0.000137453
  hidden translation_57 -3.91769e-05 -5.62022e-07 -0.0999987
  hidden rotation_57 -3.67915e-07 1 -1.40524e-07 1.49998
  hidden position_57_0 4.95771e-07
  hidden linearVelocity_57 1.89949e-05 3.01118e-05 1.10588e-06
  hidden angularVelocity_57 1.20876e-05 -2.7668e-06 -0.000417032
  hidden translation_58 -9.37357e-06 -1.90831e-07 -0.102916
  hidden rotation_58 -0.113695 0.992196 0.0511922 4.92652e-07
  hidden position_58_0 -1.17309e-08
  hidden linearVelocity_58 1.49506e-06 3.93447e-05 5.37197e-07
  hidden angularVelocity_58 1.20877e-05 -2.76675e-06 -0.000417033
  hidden translation_59 -5.16997e-06 -1.0713e-07 -1.01493e-05
  hidden rotation_59 0.00347046 0.998367 0.0570273 4.21978e-07
  hidden linearVelocity_59 -1.78017e-05 3.61174e-05 1.35475e-08
  hidden angularVelocity_59 1.21778e-05 -2.79855e-06 -0.000417031
  hidden translation_60 0.0199933 0.00700006 -0.0410075
  hidden rotation_60 3.37474e-08 -7.0999e-10 1 -3.14159
  hidden linearVelocity_60 -2.02614e-05 3.96255e-05 -8.4535e-08
  hidden angularVelocity_60 1.21778e-05 -2.79855e-06 -0.000417031
  translation -0.0917984 0.767234 -0.00972781
  rotation 0.968221 0.191385 -0.160996 -1.60475
  controller "my_controller"
  leftHandSlot [
    Transform {
      translation 0.06 0 0
      children [
        BallJoint {
          jointParameters BallJointParameters {
            springConstant 1
          }
          endPoint Connector {
            isLocked TRUE
            autoLock TRUE
            distanceTolerance 0.05
            axisTolerance 3.14159
            rotationTolerance 3.14159
            numberOfRotations 0
            snap FALSE
          }
        }
      ]
    }
  ]
  rightHandSlot [
    Transform {
      translation 0.06 0 0
      children [
        BallJoint {
          jointParameters BallJointParameters {
            springConstant 1
          }
          endPoint Connector {
            isLocked TRUE
            autoLock TRUE
            distanceTolerance 0.05
            axisTolerance 3.14159
            rotationTolerance 3.14159
            numberOfRotations 0
            snap FALSE
          }
        }
      ]
    }
  ]
}
FloorLight {
  translation -2.00175 -8.88178e-16 1.89667
}
FloorLight {
  translation 2.00366 2.22044e-15 -2.13347
}
DEF Swing Robot {
  translation 0 2.2 0
  rotation 1 0 0 -1.5708
  children [
    DEF RArm Transform {
      translation 0 0.25 -0.06
      children [
        HingeJoint {
          jointParameters HingeJointParameters {
            position -0.141091
            axis 0 1 0
            anchor 0 1 0
            minStop -3.1416
            maxStop 3.1416
            dampingConstant 1
          }
          endPoint Solid {
            translation -0.0523175 0.00787239 -0.75584
            rotation -0.999642 -0.0187952 0.0190192 -1.57567
            children [
              Transform {
                translation 0 -0.75 0
                children [
                  DEF SeatShape Solid {
                    translation 0 0 0.25
                    children [
                      DEF Right_bar Transform {
                        translation 0 0.04 0.1
                        children [
                          SolidBox {
                            size 0.1 0.01 0.01
                            physics Physics {
                            }
                          }
                        ]
                      }
                      DEF Left_bar Transform {
                        translation 0 0.04 -0.1
                        children [
                          SolidBox {
                            size 0.1 0.01 0.01
                            physics Physics {
                            }
                          }
                        ]
                      }
                      DEF Front_bar Transform {
                        translation 0.055 0.08 0
                        children [
                          SolidBox {
                            size 0.01 0.01 0.5
                            physics Physics {
                            }
                          }
                        ]
                      }
                      DEF C1 Connector {
                        translation 0 0 0.25
                        rotation 1 0 0 -1.5708
                        isLocked TRUE
                        autoLock TRUE
                        distanceTolerance 0.05
                        numberOfRotations 0
                        snap FALSE
                      }
                      DEF SeatCon Connector {
                        translation 0 0 0.25
                        rotation 1 0 0 -1.5708
                        autoLock TRUE
                        numberOfRotations 0
                      }
                      Shape {
                        appearance Appearance {
                          material Material {
                          }
                        }
                        geometry DEF SSeat Box {
                          size 0.1 0.01 0.5
                        }
                      }
                    ]
                    boundingObject USE SSeat
                    physics Physics {
                    }
                  }
                ]
              }
              DEF RVBar Shape {
                appearance Appearance {
                  material Material {
                  }
                }
                geometry Cylinder {
                  height 1.5
                  radius 0.05
                }
              }
            ]
            boundingObject USE RVBar
            physics Physics {
              centerOfMass [
                0 0 0
              ]
            }
            linearVelocity 2.03794e-05 1.65356e-05 4.17464e-07
            angularVelocity -7.31467e-07 -3.13286e-06 3.23585e-05
          }
        }
      ]
    }
    DEF LArm Transform {
      translation 0 -0.25 -0.06
      children [
        HingeJoint {
          jointParameters HingeJointParameters {
            position -0.140689
            axis 0 1 0
            anchor 0 1 0
            minStop -3.1416
            maxStop 3.1416
            dampingConstant 1
          }
          endPoint Solid {
            translation -0.0526344 0.00350177 -0.758927
            rotation -0.999634 -0.0190512 0.0191995 -1.57388
            children [
              DEF C1 Connector {
                translation 0 -0.75 0
                rotation 1 0 0 1.5708
                isLocked TRUE
                autoLock TRUE
                distanceTolerance 0.05
                numberOfRotations 0
                snap FALSE
              }
              DEF SVBar2 Shape {
                appearance Appearance {
                  material Material {
                  }
                }
                geometry Cylinder {
                  height 1.5
                  radius 0.05
                }
              }
            ]
            boundingObject USE SVBar2
            physics Physics {
              centerOfMass [
                0 0 0
              ]
            }
            linearVelocity 1.90513e-05 1.5996e-05 4.02997e-07
            angularVelocity -7.55849e-07 -3.12703e-06 3.25145e-05
          }
        }
      ]
    }
    DEF SHBarShape Shape {
      appearance DEF SwingApp Appearance {
        material Material {
          diffuseColor 0.7 0.4 0.8
        }
        texture ImageTexture {
        }
      }
      geometry DEF SHBar Cylinder {
        height 0.5
        radius 0.05
      }
    }
  ]
  name "Swing"
  boundingObject USE SHBarShape
  selfCollision TRUE
}
