#VRML_SIM V8.3.2 utf8
WorldInfo {
  basicTimeStep 8
}
Viewpoint {
  orientation -0.133517 0.91539 0.379782 2.50282
  position 26.6818 42.1902 -32.0516
  follow "NAO_H25_V50"
}
Background {
  skyColor [
    0.4 0.7 1
  ]
}
Ceiling {
  translation 0 3 0
  size 5 5
}
DirectionalLight {
  ambientIntensity 1
  direction -0.1 -0.5 -0.3
}
RectangleArena {
  floorSize 5 5
}
Nao {
  hidden position_0_0 -2.64011e-10
  hidden position2_0_0 -1.79828e-06
  hidden position_0_1 0.400016
  hidden position2_0_1 -3.56258e-07
  hidden position_0_2 0.400015
  hidden position2_0_2 2.57401e-07
  hidden position_0_3 1.88917e-06
  hidden position_0_4 1.40899e-05
  hidden linearVelocity_0 -0.668445 -0.0998246 -3.01064e-05
  hidden angularVelocity_0 -0.000138353 0.000146743 -0.538832
  hidden translation_12 -3.66666e-05 6.21072e-07 0.126662
  hidden rotation_12 -0.0158912 0.999874 0.00014678 -1.79849e-06
  hidden linearVelocity_12 -0.600747 -0.108576 -4.98499e-05
  hidden angularVelocity_12 -0.000138354 0.000146743 -0.538832
  hidden translation_19 0.000221225 -0.0981673 0.10007
  hidden rotation_19 -0.754535 0.65626 -0.00014147 0.400104
  hidden position_19_0 -0.048131
  hidden linearVelocity_19 -0.641269 -0.112901 -4.0654e-05
  hidden angularVelocity_19 -0.000138349 0.000146737 -0.538832
  hidden translation_20 0.105335 -0.0151598 2.29627e-05
  hidden rotation_20 -1 0.000130897 0.000140233 0.048144
  hidden position_20_0 6.31412e-07
  hidden linearVelocity_20 -0.65109 -0.145013 -4.69049e-05
  hidden angularVelocity_20 -0.000138898 0.000146944 -0.538832
  hidden translation_21 -0.000130691 -0.000411216 1.96749e-05
  hidden rotation_21 0.95625 0.285547 0.0636326 4.28815e-06
  hidden position_21_0 0.00430492
  hidden linearVelocity_21 -0.660191 -0.171945 -5.19248e-05
  hidden angularVelocity_21 -0.000138906 0.000146923 -0.538832
  hidden translation_22 0.0558462 -0.000413473 3.05853e-05
  hidden rotation_22 0.999975 0.000502286 0.00701 0.00429281
  hidden position_22_0 2.65658e-05
  hidden position_22_1 1.29955e-10
  hidden position_22_2 1.68244e-09
  hidden linearVelocity_22 -0.672009 -0.204765 -5.78513e-05
  hidden angularVelocity_22 -0.000138713 0.000146851 -0.538832
  hidden translation_23 0.0688477 -0.0134157 -0.00496037
  hidden rotation_23 2.43598e-05 -1 -6.29125e-05 -0.959982
  hidden position_23_1 6.31443e-10
  hidden linearVelocity_23 -0.682886 -0.222089 -5.97888e-05
  hidden angularVelocity_23 -0.000138713 0.000146851 -0.538832
  hidden translation_25 0.0140216 8.00575e-06 -7.64827e-06
  hidden rotation_25 1.40952e-09 -1 -3.6681e-09 -0.96
  hidden position_25_0 4.14152e-10
  hidden linearVelocity_25 -0.689145 -0.221084 -5.79075e-05
  hidden angularVelocity_25 -0.000138713 0.000146851 -0.538832
  hidden translation_26 0.0140223 5.70765e-06 -9.78488e-06
  hidden rotation_26 -3.94187e-11 -1 -7.57077e-11 -0.96
  hidden linearVelocity_26 -0.691805 -0.215082 -5.55857e-05
  hidden angularVelocity_26 -0.000138713 0.000146851 -0.538832
  hidden translation_27 0.0690806 0.0130121 -0.00502719
  hidden rotation_27 -5.62927e-10 -1 -4.03623e-10 -0.96
  hidden position_27_0 7.75932e-10
  hidden linearVelocity_27 -0.68758 -0.221003 -5.8284e-05
  hidden angularVelocity_27 -0.000138713 0.000146851 -0.538832
  hidden translation_28 0.0140216 8.00624e-06 -7.64863e-06
  hidden rotation_28 -2.16052e-10 -1 -2.63552e-10 -0.96
  hidden position_28_0 4.14325e-10
  hidden linearVelocity_28 -0.693838 -0.219998 -5.64026e-05
  hidden angularVelocity_28 -0.000138713 0.000146851 -0.538832
  hidden translation_29 0.0140223 5.70674e-06 -9.7851e-06
  hidden rotation_29 -3.9432e-11 -1 -7.57367e-11 -0.96
  hidden linearVelocity_29 -0.696499 -0.213996 -5.40809e-05
  hidden angularVelocity_29 -0.000138713 0.000146851 -0.538832
  hidden translation_30 0.0490447 1.91949e-05 -0.0260504
  hidden rotation_30 -0.0379119 0.98283 0.180575 1.70545e-09
  hidden position_30_0 2.16482e-10
  hidden linearVelocity_30 -0.689581 -0.20978 -5.47079e-05
  hidden angularVelocity_30 -0.000138713 0.000146851 -0.538832
  hidden translation_31 0.0140231 -2.91408e-06 1.03546e-05
  hidden rotation_31 3.93825e-11 1 -7.57244e-11 -0.96
  hidden linearVelocity_31 -0.689444 -0.216471 -5.65697e-05
  hidden angularVelocity_31 -0.000138713 0.000146851 -0.538832
  hidden translation_32 0.000207718 0.0981782 0.100119
  hidden rotation_32 0.857114 0.515114 0.0037137 0.40457
  hidden position_32_0 0.0545945
  hidden linearVelocity_32 -0.640693 -0.113095 -4.0835e-05
  hidden angularVelocity_32 -0.000138357 0.000146752 -0.538832
  hidden translation_33 0.105318 0.0151805 4.54009e-05
  hidden rotation_33 1 0.000216156 -0.000217309 0.05461
  hidden position_33_0 -1.14029e-06
  hidden linearVelocity_33 -0.64817 -0.145904 -4.78727e-05
  hidden angularVelocity_33 -0.000138941 0.000146936 -0.538832
  hidden translation_34 -8.08375e-06 0.000239199 3.74245e-05
  hidden rotation_34 -0.489332 0.87156 -0.0306225 1.17787e-05
  hidden position_34_0 -0.0754383
  hidden linearVelocity_34 -0.655751 -0.173385 -5.34324e-05
  hidden angularVelocity_34 -0.000138943 0.000146932 -0.538832
  hidden translation_35 0.0559698 0.000241011 3.45732e-05
  hidden rotation_35 -1 0.000157826 -0.000338926 0.0754274
  hidden position_35_0 1.05833e-10
  hidden position_35_1 1.05208e-10
  hidden position_35_2 1.71337e-09
  hidden linearVelocity_35 -0.665852 -0.206841 -5.99746e-05
  hidden angularVelocity_35 -0.000138696 0.000146854 -0.538832
  hidden translation_36 0.0689744 -0.012765 -0.00495675
  hidden rotation_36 -1.4371e-05 -1 4.19912e-05 -0.959958
  hidden position_36_1 2.30775e-09
  hidden linearVelocity_36 -0.680367 -0.223886 -6.09004e-05
  hidden angularVelocity_36 -0.000138696 0.000146854 -0.538832
  hidden translation_38 0.0140215 -7.82345e-06 -7.84739e-06
  hidden rotation_38 -2.63899e-09 -1 -2.39655e-09 -0.96
  hidden position_38_0 4.09219e-10
  hidden linearVelocity_38 -0.6867 -0.223225 -5.90933e-05
  hidden angularVelocity_38 -0.000138696 0.000146854 -0.538832
  hidden translation_39 0.0140228 -5.24225e-06 -9.76819e-06
  hidden rotation_39 3.8406e-11 -1 7.37839e-11 -0.96
  hidden linearVelocity_39 -0.689707 -0.217377 -5.6724e-05
  hidden angularVelocity_39 -0.000138696 0.000146854 -0.538832
  hidden translation_40 0.0690774 0.0129928 -0.00501064
  hidden rotation_40 5.48095e-10 -1 3.93023e-10 -0.96
  hidden position_40_0 7.21979e-10
  hidden linearVelocity_40 -0.676022 -0.224817 -6.22683e-05
  hidden angularVelocity_40 -0.000138696 0.000146854 -0.538832
  hidden translation_41 0.0140215 -7.8238e-06 -7.84764e-06
  hidden rotation_41 2.104e-10 -1 2.56645e-10 -0.96
  hidden position_41_0 4.09099e-10
  hidden linearVelocity_41 -0.682354 -0.224157 -6.0461e-05
  hidden angularVelocity_41 -0.000138696 0.000146854 -0.538832
  hidden translation_42 0.0140228 -5.24149e-06 -9.76832e-06
  hidden rotation_42 3.83945e-11 -1 7.37623e-11 -0.96
  hidden linearVelocity_42 -0.685361 -0.218308 -5.80917e-05
  hidden angularVelocity_42 -0.000138696 0.000146854 -0.538832
  hidden translation_43 0.0490442 -1.92351e-05 -0.0260506
  hidden rotation_43 0.0372821 0.983401 -0.177574 1.68967e-09
  hidden position_43_0 2.0293e-10
  hidden linearVelocity_43 -0.683197 -0.212809 -5.7148e-05
  hidden angularVelocity_43 -0.000138696 0.000146854 -0.538832
  hidden translation_44 0.0140231 2.4466e-06 1.05472e-05
  hidden rotation_44 -3.83605e-11 1 7.37819e-11 -0.96
  hidden linearVelocity_44 -0.682682 -0.219484 -5.91026e-05
  hidden angularVelocity_44 -0.000138696 0.000146854 -0.538832
  hidden translation_45 0.000215308 -0.0499849 -0.0851474
  hidden rotation_45 -0.322942 0.887835 -0.327807 1.26178e-05
  hidden position_45_0 -5.36198e-06
  hidden linearVelocity_45 -0.722949 -0.0922378 -1.57757e-05
  hidden angularVelocity_45 -0.000138223 0.000148087 -0.538833
  hidden translation_46 0.000204131 1.61451e-05 6.92009e-06
  hidden rotation_46 -0.178928 0.918738 -0.352002 1.22835e-05
  hidden position_46_0 -1.18827
  hidden linearVelocity_46 -0.739563 -0.0864473 -1.16337e-05
  hidden angularVelocity_46 -0.000138097 0.000148475 -0.538833
  hidden translation_47 0.000100677 -2.83469e-05 0.000166878
  hidden rotation_47 -7.08037e-06 1 -2.47101e-06 -1.18827
  hidden position_47_0 -0.0675847
  hidden linearVelocity_47 -0.750023 -0.120133 -1.6906e-05
  hidden angularVelocity_47 -0.000154829 9.04901e-05 -0.520068
  hidden translation_48 0.000268136 -1.19391e-06 -0.101235
  hidden rotation_48 -1.66718e-05 1 -0.000299257 -0.0675847
  hidden position_48_0 1.11892e-06
  hidden linearVelocity_48 -0.766429 -0.154374 2.12368e-05
  hidden angularVelocity_48 -0.000371047 -0.00066907 -0.27643
  hidden translation_49 -2.1555e-05 -4.78765e-07 -0.104023
  hidden rotation_49 0.0954748 0.994332 -0.0467702 1.11365e-06
  hidden position_49_0 2.55783e-07
  hidden linearVelocity_49 -0.772853 -0.16598 5.79616e-05
  hidden angularVelocity_49 -0.000371043 -0.000669072 -0.27643
  hidden translation_50 0.000642216 -8.36746e-08 -0.000878968
  hidden rotation_50 0.0188807 0.997741 -0.0644708 7.67433e-07
  hidden linearVelocity_50 -0.770919 -0.178991 8.68185e-05
  hidden angularVelocity_50 -0.000370913 -0.000668792 -0.27643
  hidden translation_53 0.0198768 -0.00700006 -0.0412393
  hidden rotation_53 -2.67739e-08 -8.54278e-10 1 -3.14159
  hidden linearVelocity_53 -0.773322 -0.180598 9.39354e-05
  hidden angularVelocity_53 -0.000370913 -0.000668792 -0.27643
  hidden translation_57 4.46408e-05 0.0500241 -0.0851394
  hidden rotation_57 -0.129203 0.877766 -0.461339 1.19572e-05
  hidden position_57_0 2.10665e-06
  hidden linearVelocity_57 -0.722814 -0.0921967 -1.53469e-05
  hidden angularVelocity_57 -0.000138393 0.00014577 -0.538833
  hidden translation_58 3.43873e-05 2.48629e-05 1.4459e-05
  hidden rotation_58 -0.0104549 0.903564 -0.428325 1.10094e-05
  hidden position_58_0 -1.18827
  hidden linearVelocity_58 -0.739377 -0.0863321 -1.07608e-05
  hidden angularVelocity_58 -0.000138851 0.000145663 -0.538833
  hidden translation_59 8.68209e-05 -2.44714e-05 0.000175256
  hidden rotation_59 -7.28323e-06 1 -2.16264e-06 -1.18827
  hidden position_59_0 -0.0675847
  hidden linearVelocity_59 -0.749824 -0.120015 -1.53492e-05
  hidden angularVelocity_59 -0.000155612 8.70375e-05 -0.520067
  hidden translation_60 0.000283337 -1.40606e-06 -0.10124
  hidden rotation_60 -9.07191e-06 1 -0.000293952 -0.0675848
  hidden position_60_0 1.12113e-06
  hidden linearVelocity_60 -0.766227 -0.154259 2.31977e-05
  hidden angularVelocity_60 -0.000372435 -0.000673677 -0.276429
  hidden translation_61 -2.15418e-05 -5.09434e-07 -0.104025
  hidden rotation_61 -0.105246 0.993662 0.0394945 1.11476e-06
  hidden position_61_0 -5.09045e-08
  hidden linearVelocity_61 -0.772657 -0.165864 6.01515e-05
  hidden angularVelocity_61 -0.000372439 -0.000673675 -0.276429
  hidden translation_62 0.000642968 -8.2787e-08 -0.000879663
  hidden rotation_62 -0.00820834 0.998486 0.0543873 7.70577e-07
  hidden linearVelocity_62 -0.770714 -0.178879 8.92333e-05
  hidden angularVelocity_62 -0.00037257 -0.000673958 -0.276429
  hidden translation_65 0.0198756 0.007 -0.0412409
  hidden rotation_65 2.81707e-08 -7.0833e-10 1 -3.14159
  hidden linearVelocity_65 -0.773106 -0.18049 9.63925e-05
  hidden angularVelocity_65 -0.00037257 -0.000673958 -0.276429
  translation 0.187737 0.807038 -0.0120854
  rotation 0.997165 -0.0528476 0.0535676 -1.57047
  controller "my_controller"
  bodySlot [
    Receiver {
      name "Robot_Receiver"
    }
  ]
  leftFootSlot [
    InertialUnit {
    }
    Gyro {
      name ""
    }
  ]
  rightFootSlot [
    DEF Right_Foot_Gyro Gyro {
      rotation 1 0 0 1.5708
      name "Right_Foot_Gyro"
    }
    InertialUnit {
      name "Right_Foot_IU"
    }
  ]
  leftHandSlot [
    Transform {
      translation 0.06 0 0
      children [
        BallJoint {
          jointParameters BallJointParameters {
            springConstant 1
          }
          endPoint Connector {
            isLocked TRUE
            autoLock TRUE
            distanceTolerance 0.05
            axisTolerance 3.14159
            rotationTolerance 3.14159
            numberOfRotations 0
            snap FALSE
          }
        }
      ]
    }
  ]
  rightHandSlot [
    Transform {
      translation 0.06 0 0
      children [
        BallJoint {
          jointParameters BallJointParameters {
            springConstant 1
          }
          endPoint Connector {
            isLocked TRUE
            autoLock TRUE
            distanceTolerance 0.05
            axisTolerance 3.14159
            rotationTolerance 3.14159
            numberOfRotations 0
            snap FALSE
          }
        }
      ]
    }
  ]
}
FloorLight {
  translation -2.00175 -8.88178e-16 1.89667
}
FloorLight {
  translation 2.00366 2.22044e-15 -2.13347
}
DEF Swing Robot {
  translation 0 2.2 0
  rotation 1 0 0 -1.5708
  children [
    DEF RArm Transform {
      translation 0 0.25 -0.06
      children [
        HingeJoint {
          jointParameters HingeJointParameters {
            position -0.334733
            axis 0 1 0
            anchor 0 1 0
            minStop -3.1416
            maxStop 3.1416
            dampingConstant 1
          }
          endPoint Solid {
            translation 0.0929104 0.00993678 -0.747516
            rotation -0.993986 0.077485 -0.0773776 -1.58009
            children [
              Transform {
                translation 0 -0.75 0
                children [
                  DEF SeatShape Solid {
                    translation 0 0 0.25
                    children [
                      Emitter {
                        name "SeatEmitter"
                      }
                      DEF Seat_IU InertialUnit {
                        name "Seat_IU"
                      }
                      Gyro {
                        name "Seat_Gyro"
                      }
                      DEF Right_bar Transform {
                        translation 0 0.04 0.1
                        children [
                          SolidBox {
                            size 0.1 0.05 0.01
                            physics Physics {
                            }
                          }
                        ]
                      }
                      DEF Left_bar Transform {
                        translation 0 0.04 -0.1
                        children [
                          SolidBox {
                            size 0.1 0.05 0.01
                            physics Physics {
                            }
                          }
                        ]
                      }
                      DEF Front_bar Transform {
                        translation 0.065 0.08 0
                        children [
                          SolidBox {
                            size 0.07 0.01 0.5
                            physics Physics {
                            }
                          }
                        ]
                      }
                      DEF C1 Connector {
                        translation 0 0 0.25
                        rotation 1 0 0 -1.5708
                        isLocked TRUE
                        autoLock TRUE
                        distanceTolerance 0.05
                        numberOfRotations 0
                        snap FALSE
                      }
                      DEF SeatCon Connector {
                        translation 0 0 0.25
                        rotation 1 0 0 -1.5708
                        autoLock TRUE
                        numberOfRotations 0
                      }
                      Shape {
                        appearance Appearance {
                          material Material {
                          }
                        }
                        geometry DEF SSeat Box {
                          size 0.1 0.01 0.5
                        }
                      }
                    ]
                    boundingObject USE SSeat
                    physics Physics {
                    }
                  }
                ]
              }
              DEF RVBar Shape {
                appearance Appearance {
                  material Material {
                  }
                }
                geometry Cylinder {
                  height 1.5
                  radius 0.05
                }
              }
            ]
            boundingObject USE RVBar
            physics Physics {
              centerOfMass [
                0 0 0
              ]
            }
            linearVelocity -0.416334 -0.0546467 -8.85706e-06
            angularVelocity 7.65183e-06 1.66694e-05 -0.520533
          }
        }
      ]
    }
    DEF LArm Transform {
      translation 0 -0.25 -0.06
      children [
        HingeJoint {
          jointParameters HingeJointParameters {
            position -0.334671
            axis 0 1 0
            anchor 0 1 0
            minStop -3.1416
            maxStop 3.1416
            dampingConstant 1
          }
          endPoint Solid {
            translation 0.0963302 0.00155958 -0.76337
            rotation -0.993997 0.0772249 -0.077505 -1.58101
            children [
              DEF C1 Connector {
                translation 0 -0.75 0
                rotation 1 0 0 1.5708
                isLocked TRUE
                autoLock TRUE
                distanceTolerance 0.05
                numberOfRotations 0
                snap FALSE
              }
              DEF SVBar2 Shape {
                appearance Appearance {
                  material Material {
                  }
                }
                geometry Cylinder {
                  height 1.5
                  radius 0.05
                }
              }
            ]
            boundingObject USE SVBar2
            physics Physics {
              centerOfMass [
                0 0 0
              ]
            }
            linearVelocity -0.397233 -0.0511469 -9.40864e-06
            angularVelocity 1.48437e-05 -9.96235e-06 -0.520568
          }
        }
      ]
    }
    DEF SHBarShape Shape {
      appearance DEF SwingApp Appearance {
        material Material {
          diffuseColor 0.7 0.4 0.8
        }
        texture ImageTexture {
        }
      }
      geometry DEF SHBar Cylinder {
        height 0.5
        radius 0.05
      }
    }
  ]
  name "Swing"
  boundingObject USE SHBarShape
  controller "swingcontroller"
  selfCollision TRUE
}
