#VRML_SIM V8.3.2 utf8
WorldInfo {
  basicTimeStep 8
}
Viewpoint {
  orientation -0.133517 0.91539 0.379782 2.50282
  position 26.6234 41.9967 -31.9115
  follow "NAO_H25_V50"
}
Background {
  skyColor [
    0.4 0.7 1
  ]
}
Ceiling {
  translation 0 3 0
  size 5 5
}
DirectionalLight {
  ambientIntensity 1
  direction -0.1 -0.5 -0.3
}
RectangleArena {
  floorSize 5 5
}
Nao {
  hidden position_0_0 -3.06269e-10
  hidden position2_0_0 -1.87596e-06
  hidden position_0_1 0.400016
  hidden position2_0_1 -3.69816e-07
  hidden position_0_2 0.400015
  hidden position2_0_2 2.73499e-07
  hidden position_0_3 2.04005e-06
  hidden position_0_4 1.41416e-05
  hidden linearVelocity_0 -0.0108855 0.088824 -0.010246
  hidden angularVelocity_0 -0.0907595 0.00882016 0.77789
  hidden translation_12 -3.74378e-05 6.12147e-07 0.126659
  hidden rotation_12 -0.0150516 0.999887 0.000163227 -1.87616e-06
  hidden linearVelocity_12 -0.107701 0.107396 -0.021771
  hidden angularVelocity_12 -0.0907605 0.00882028 0.777892
  hidden translation_19 0.000219803 -0.0981673 0.10007
  hidden rotation_19 -0.754536 0.656259 -0.000141692 0.400104
  hidden position_19_0 -0.0481309
  hidden linearVelocity_19 -0.0485712 0.114259 -0.0149439
  hidden angularVelocity_19 -0.0907598 0.0088209 0.777893
  hidden translation_20 0.105332 -0.0151602 2.37606e-05
  hidden rotation_20 -1 0.000129734 0.000139815 0.048144
  hidden position_20_0 5.70511e-07
  hidden linearVelocity_20 -0.0315239 0.161 -0.013494
  hidden angularVelocity_20 -0.0907591 0.00882076 0.777895
  hidden translation_21 -0.000133485 -0.000411573 2.03496e-05
  hidden rotation_21 0.960091 0.272457 0.0631804 4.27092e-06
  hidden position_21_0 0.0043049
  hidden linearVelocity_21 -0.0160357 0.199456 -0.0121301
  hidden angularVelocity_21 -0.0907592 0.00882093 0.777896
  hidden translation_22 0.0558431 -0.000413764 3.10341e-05
  hidden rotation_22 0.999975 0.000497283 0.00700822 0.00429281
  hidden position_22_0 2.65657e-05
  hidden position_22_1 6.7151e-11
  hidden position_22_2 1.61253e-09
  hidden linearVelocity_22 0.00386177 0.245927 -0.010342
  hidden angularVelocity_22 -0.0907595 0.00882119 0.777897
  hidden translation_23 0.0688461 -0.0134159 -0.00496012
  hidden rotation_23 2.43598e-05 -1 -6.29125e-05 -0.959982
  hidden position_23_1 5.6386e-10
  hidden linearVelocity_23 0.0211241 0.270935 -0.00861362
  hidden angularVelocity_23 -0.0907595 0.00882119 0.777897
  hidden translation_25 0.0140212 7.83825e-06 -7.47609e-06
  hidden rotation_25 1.416e-09 -1 -3.66022e-09 -0.96
  hidden position_25_0 3.96266e-10
  hidden linearVelocity_25 0.0300695 0.269124 -0.00754927
  hidden angularVelocity_25 -0.0907595 0.00882119 0.777897
  hidden translation_26 0.0140218 5.59645e-06 -9.56837e-06
  hidden rotation_26 -3.82333e-11 -1 -7.34338e-11 -0.96
  hidden linearVelocity_26 0.0333871 0.26032 -0.00706167
  hidden angularVelocity_26 -0.0907595 0.00882119 0.777897
  hidden translation_27 0.0690789 0.0130118 -0.00502658
  hidden rotation_27 -5.46122e-10 -1 -3.91527e-10 -0.96
  hidden position_27_0 7.08367e-10
  hidden linearVelocity_27 0.0277006 0.267849 -0.00781094
  hidden angularVelocity_27 -0.0907595 0.00882119 0.777897
  hidden translation_28 0.0140212 7.83873e-06 -7.47644e-06
  hidden rotation_28 -2.09573e-10 -1 -2.55673e-10 -0.96
  hidden position_28_0 3.96431e-10
  hidden linearVelocity_28 0.0366459 0.266038 -0.0067466
  hidden angularVelocity_28 -0.0907595 0.00882119 0.777897
  hidden translation_29 0.0140218 5.59556e-06 -9.56859e-06
  hidden rotation_29 -3.82465e-11 -1 -7.34626e-11 -0.96
  hidden linearVelocity_29 0.0399635 0.257233 -0.006259
  hidden angularVelocity_29 -0.0907595 0.00882119 0.777897
  hidden translation_30 0.0490438 1.87821e-05 -0.0260493
  hidden rotation_30 -0.0383495 0.982431 0.182642 1.63563e-09
  hidden position_30_0 1.99077e-10
  hidden linearVelocity_30 0.0296628 0.252173 -0.00740308
  hidden angularVelocity_30 -0.0907595 0.00882119 0.777897
  hidden translation_31 0.0140226 -2.86307e-06 1.0153e-05
  hidden rotation_31 3.82091e-11 1 -7.34516e-11 -0.96
  hidden linearVelocity_31 0.0300476 0.261824 -0.00746839
  hidden angularVelocity_31 -0.0907595 0.00882119 0.777897
  hidden translation_32 0.00020629 0.0981782 0.100119
  hidden rotation_32 0.857114 0.515113 0.00371396 0.40457
  hidden position_32_0 0.0545946
  hidden linearVelocity_32 -0.0500658 0.10638 -0.0150277
  hidden angularVelocity_32 -0.090759 0.00882106 0.777892
  hidden translation_33 0.105315 0.0151809 4.61689e-05
  hidden rotation_33 1 0.000215119 -0.000216877 0.05461
  hidden position_33_0 -1.07227e-06
  hidden linearVelocity_33 -0.0365103 0.152235 -0.0139751
  hidden angularVelocity_33 -0.0907598 0.00882167 0.777893
  hidden translation_34 -1.08337e-05 0.000239598 3.81017e-05
  hidden rotation_34 -0.491612 0.870356 -0.0282596 1.17245e-05
  hidden position_34_0 -0.0754383
  hidden linearVelocity_34 -0.0231996 0.191204 -0.0128713
  hidden angularVelocity_34 -0.0907598 0.00882193 0.777895
  hidden translation_35 0.0559667 0.000241332 3.50314e-05
  hidden rotation_35 -1 0.000157535 -0.000338816 0.0754274
  hidden position_35_0 5.0549e-11
  hidden position_35_1 5.02908e-11
  hidden position_35_2 1.64193e-09
  hidden linearVelocity_35 -0.00571168 0.238867 -0.0113782
  hidden angularVelocity_35 -0.0907601 0.00882215 0.777895
  hidden translation_36 0.0689728 -0.0127647 -0.00495615
  hidden rotation_36 -1.4371e-05 -1 4.19912e-05 -0.959958
  hidden position_36_1 2.24208e-09
  hidden linearVelocity_36 0.0167187 0.262552 -0.00903168
  hidden angularVelocity_36 -0.0907601 0.00882215 0.777895
  hidden translation_38 0.0140211 -7.66124e-06 -7.67317e-06
  hidden rotation_38 -2.64538e-09 -1 -2.40432e-09 -0.96
  hidden position_38_0 3.91006e-10
  hidden linearVelocity_38 0.0257712 0.26087 -0.00795625
  hidden angularVelocity_38 -0.0907601 0.00882215 0.777895
  hidden translation_39 0.0140223 -5.1344e-06 -9.5529e-06
  hidden rotation_39 3.72369e-11 -1 7.15397e-11 -0.96
  hidden linearVelocity_39 0.0295822 0.252023 -0.00741057
  hidden angularVelocity_39 -0.0907601 0.00882215 0.777895
  hidden translation_40 0.0690758 0.012993 -0.00501037
  hidden rotation_40 5.31526e-10 -1 3.81084e-10 -0.96
  hidden position_40_0 6.56283e-10
  hidden linearVelocity_40 0.0104487 0.263191 -0.0097704
  hidden angularVelocity_40 -0.0907601 0.00882215 0.777895
  hidden translation_41 0.0140211 -7.66158e-06 -7.67341e-06
  hidden rotation_41 2.0401e-10 -1 2.48872e-10 -0.96
  hidden position_41_0 3.90893e-10
  hidden linearVelocity_41 0.0195012 0.261509 -0.00869498
  hidden angularVelocity_41 -0.0907601 0.00882215 0.777895
  hidden translation_42 0.0140223 -5.13365e-06 -9.55302e-06
  hidden rotation_42 3.72252e-11 -1 7.15186e-11 -0.96
  hidden linearVelocity_42 0.0233118 0.252662 -0.00814933
  hidden angularVelocity_42 -0.0907601 0.00882215 0.777895
  hidden translation_43 0.0490433 -1.88354e-05 -0.0260495
  hidden rotation_43 0.0377462 0.982983 -0.179774 1.61834e-09
  hidden position_43_0 1.85939e-10
  hidden linearVelocity_43 0.0197642 0.245525 -0.0084818
  hidden angularVelocity_43 -0.0907601 0.00882215 0.777895
  hidden translation_44 0.0140226 2.39702e-06 1.03445e-05
  hidden rotation_44 -3.72017e-11 1 7.15393e-11 -0.96
  hidden linearVelocity_44 0.0196115 0.255289 -0.00861113
  hidden angularVelocity_44 -0.0907601 0.00882215 0.777895
  hidden translation_45 0.000210395 -0.0499849 -0.0851413
  hidden rotation_45 -0.322334 0.891857 -0.31732 1.26682e-05
  hidden position_45_0 -5.37942e-06
  hidden linearVelocity_45 0.0671641 0.0747065 -0.000951795
  hidden angularVelocity_45 -0.0907521 0.00881507 0.777876
  hidden translation_46 0.000199532 1.6183e-05 9.80821e-06
  hidden rotation_46 -0.179537 0.91902 -0.350955 1.22751e-05
  hidden position_46_0 -1.2191
  hidden linearVelocity_46 0.0906714 0.0652551 0.00192559
  hidden angularVelocity_46 -0.0907396 0.00881028 0.777862
  hidden translation_47 8.81359e-05 -2.83153e-05 0.000171105
  hidden rotation_47 -6.87929e-06 1 -2.54424e-06 -1.2191
  hidden position_47_0 -0.0190761
  hidden linearVelocity_47 0.0600015 0.0221647 0.000852477
  hidden angularVelocity_47 0.0271016 0.00143241 -1.16525
  hidden translation_48 0.000209801 -1.1861e-06 -0.101243
  hidden rotation_48 -8.34263e-05 0.999999 -0.00106378 -0.0190761
  hidden position_48_0 1.05905e-06
  hidden linearVelocity_48 -0.0265392 -0.170776 -0.00229916
  hidden angularVelocity_48 0.144899 -0.00592813 -3.10814
  hidden translation_49 -2.05845e-05 -4.75356e-07 -0.104022
  hidden rotation_49 0.0990144 0.993981 -0.0468902 1.0539e-06
  hidden position_49_0 2.29238e-07
  hidden linearVelocity_49 -0.105947 -0.297151 -0.00574784
  hidden angularVelocity_49 0.144899 -0.00592811 -3.10815
  hidden translation_50 0.00064243 -8.25142e-08 -0.000878098
  hidden rotation_50 0.0180651 0.997828 -0.0633401 7.40909e-07
  hidden linearVelocity_50 -0.0923559 -0.444386 -0.00482159
  hidden angularVelocity_50 0.144899 -0.00592802 -3.10815
  hidden translation_53 0.0198771 -0.00700006 -0.041239
  hidden rotation_53 -2.66233e-08 -8.5425e-10 1 -3.14159
  hidden linearVelocity_53 -0.120234 -0.460786 -0.006088
  hidden angularVelocity_53 0.144899 -0.00592801 -3.10815
  hidden translation_57 3.99317e-05 0.050024 -0.0851329
  hidden rotation_57 -0.129022 0.875982 -0.464768 1.19802e-05
  hidden position_57_0 2.152e-06
  hidden linearVelocity_57 0.0666192 0.0713411 -0.000966127
  hidden angularVelocity_57 -0.0907604 0.00881869 0.777883
  hidden translation_58 2.99939e-05 2.47477e-05 1.7713e-05
  hidden rotation_58 -0.0103537 0.902529 -0.430506 1.09726e-05
  hidden position_58_0 -1.2191
  hidden linearVelocity_58 0.0899038 0.0609125 0.00190754
  hidden angularVelocity_58 -0.0907681 0.00881659 0.777873
  hidden translation_59 7.42161e-05 -2.45929e-05 0.000179426
  hidden rotation_59 -7.08071e-06 1 -2.22169e-06 -1.2191
  hidden position_59_0 -0.0190761
  hidden linearVelocity_59 0.0591616 0.0178198 0.0008356
  hidden angularVelocity_59 0.0270697 0.00144818 -1.16523
  hidden translation_60 0.000224778 -1.39823e-06 -0.101248
  hidden rotation_60 -5.64371e-05 0.999999 -0.00104517 -0.0190762
  hidden position_60_0 1.06126e-06
  hidden linearVelocity_60 -0.0273455 -0.175164 -0.00231504
  hidden angularVelocity_60 0.144872 -0.00590275 -3.10813
  hidden translation_61 -2.05712e-05 -5.05997e-07 -0.104024
  hidden rotation_61 -0.109206 0.993242 0.0392921 1.05505e-06
  hidden position_61_0 -2.43409e-08
  hidden linearVelocity_61 -0.106732 -0.301377 -0.00576349
  hidden angularVelocity_61 0.144872 -0.00590271 -3.10813
  hidden translation_62 0.000643182 -8.16504e-08 -0.000878793
  hidden rotation_62 -0.00624349 0.998574 0.0530277 7.44075e-07
  hidden linearVelocity_62 -0.0931753 -0.448877 -0.0048396
  hidden angularVelocity_62 0.144872 -0.00590263 -3.10813
  hidden translation_65 0.0198759 0.007 -0.0412406
  hidden rotation_65 2.83213e-08 -7.08302e-10 1 -3.14159
  hidden linearVelocity_65 -0.121102 -0.465601 -0.00610753
  hidden angularVelocity_65 0.144872 -0.00590262 -3.10813
  translation -0.0150146 0.782425 -0.0131255
  rotation 0.992688 -0.0495981 0.110052 -1.5772
  controller "my_controller"
  bodySlot [
    Receiver {
      name "Robot_Receiver"
    }
  ]
  leftFootSlot [
    InertialUnit {
    }
    Gyro {
      name ""
    }
  ]
  rightFootSlot [
    DEF Right_Foot_Gyro Gyro {
      rotation 1 0 0 1.5708
      name "Right_Foot_Gyro"
    }
    InertialUnit {
      name "Right_Foot_IU"
    }
  ]
  leftHandSlot [
    Transform {
      translation 0.06 0 0
      children [
        BallJoint {
          jointParameters BallJointParameters {
            springConstant 1
          }
          endPoint Connector {
            isLocked TRUE
            autoLock TRUE
            distanceTolerance 0.05
            axisTolerance 3.14159
            rotationTolerance 3.14159
            numberOfRotations 0
            snap FALSE
          }
        }
      ]
    }
  ]
  rightHandSlot [
    Transform {
      translation 0.06 0 0
      children [
        BallJoint {
          jointParameters BallJointParameters {
            springConstant 1
          }
          endPoint Connector {
            isLocked TRUE
            autoLock TRUE
            distanceTolerance 0.05
            axisTolerance 3.14159
            rotationTolerance 3.14159
            numberOfRotations 0
            snap FALSE
          }
        }
      ]
    }
  ]
}
FloorLight {
  translation -2.00175 -8.88178e-16 1.89667
}
FloorLight {
  translation 2.00366 2.22044e-15 -2.13347
}
DEF Swing Robot {
  translation 0 2.2 0
  rotation 1 0 0 -1.5708
  children [
    DEF RArm Transform {
      translation 0 0.25 -0.06
      children [
        HingeJoint {
          jointParameters HingeJointParameters {
            position -0.186568
            axis 0 1 0
            anchor 0 1 0
            minStop -3.1416
            maxStop 3.1416
            dampingConstant 1
          }
          endPoint Solid {
            translation -0.0182688 0.00959632 -0.754794
            rotation -0.999986 0.00391651 -0.00364085 -1.57463
            children [
              Transform {
                translation 0 -0.75 0
                children [
                  DEF SeatShape Solid {
                    translation 0 0 0.25
                    children [
                      Emitter {
                        name "SeatEmitter"
                      }
                      DEF Seat_IU InertialUnit {
                        name "Seat_IU"
                      }
                      Gyro {
                        name "Seat_Gyro"
                      }
                      DEF Right_bar Transform {
                        translation 0 0.04 0.1
                        children [
                          SolidBox {
                            size 0.1 0.05 0.01
                            physics Physics {
                            }
                          }
                        ]
                      }
                      DEF Left_bar Transform {
                        translation 0 0.04 -0.1
                        children [
                          SolidBox {
                            size 0.1 0.05 0.01
                            physics Physics {
                            }
                          }
                        ]
                      }
                      DEF Front_bar Transform {
                        translation 0.065 0.08 0
                        children [
                          SolidBox {
                            size 0.05 0.01 0.5
                            physics Physics {
                            }
                          }
                        ]
                      }
                      DEF C1 Connector {
                        translation 0 0 0.25
                        rotation 1 0 0 -1.5708
                        isLocked TRUE
                        autoLock TRUE
                        distanceTolerance 0.05
                        numberOfRotations 0
                        snap FALSE
                      }
                      DEF SeatCon Connector {
                        translation 0 0 0.25
                        rotation 1 0 0 -1.5708
                        autoLock TRUE
                        numberOfRotations 0
                      }
                      Shape {
                        appearance Appearance {
                          material Material {
                          }
                        }
                        geometry DEF SSeat Box {
                          size 0.1 0.01 0.5
                        }
                      }
                    ]
                    boundingObject USE SSeat
                    physics Physics {
                    }
                  }
                ]
              }
              DEF RVBar Shape {
                appearance Appearance {
                  material Material {
                  }
                }
                geometry Cylinder {
                  height 1.5
                  radius 0.05
                }
              }
            ]
            boundingObject USE RVBar
            physics Physics {
              centerOfMass [
                0 0 0
              ]
            }
            linearVelocity 0.0109808 -0.000211314 -5.7638e-05
            angularVelocity 1.86138e-05 3.63407e-06 0.01365
          }
        }
      ]
    }
    DEF LArm Transform {
      translation 0 -0.25 -0.06
      children [
        HingeJoint {
          jointParameters HingeJointParameters {
            position -0.186415
            axis 0 1 0
            anchor 0 1 0
            minStop -3.1416
            maxStop 3.1416
            dampingConstant 1
          }
          endPoint Solid {
            translation -0.0176122 0.002264 -0.767724
            rotation -0.999986 0.00372221 -0.00368082 -1.5749
            children [
              DEF C1 Connector {
                translation 0 -0.75 0
                rotation 1 0 0 1.5708
                isLocked TRUE
                autoLock TRUE
                distanceTolerance 0.05
                numberOfRotations 0
                snap FALSE
              }
              DEF SVBar2 Shape {
                appearance Appearance {
                  material Material {
                  }
                }
                geometry Cylinder {
                  height 1.5
                  radius 0.05
                }
              }
            ]
            boundingObject USE SVBar2
            physics Physics {
              centerOfMass [
                0 0 0
              ]
            }
            linearVelocity 0.0105217 -0.000245465 -3.36287e-05
            angularVelocity 1.32443e-05 1.54087e-05 0.0136792
          }
        }
      ]
    }
    DEF SHBarShape Shape {
      appearance DEF SwingApp Appearance {
        material Material {
          diffuseColor 0.7 0.4 0.8
        }
        texture ImageTexture {
        }
      }
      geometry DEF SHBar Cylinder {
        height 0.5
        radius 0.05
      }
    }
  ]
  name "Swing"
  boundingObject USE SHBarShape
  controller "swingcontroller"
  selfCollision TRUE
}
