#VRML_SIM V8.3.2 utf8
WorldInfo {
  basicTimeStep 16
}
Viewpoint {
  orientation -0.0992056 0.964512 0.244693 2.37106
  position 28.4156 21.6885 -27.3615
}
Background {
  skyColor [
    0.4 0.7 1
  ]
}
Ceiling {
  translation 0 3 0
  size 5 5
}
DirectionalLight {
  ambientIntensity 1
  direction -0.1 -0.5 -0.3
}
RectangleArena {
  floorSize 5 5
}
Nao {
  hidden position_0_0 -1.11297e-09
  hidden position2_0_0 1.4544e-07
  hidden position_0_1 0.398444
  hidden position2_0_1 -0.983524
  hidden position_0_2 0.400001
  hidden position2_0_2 0.965711
  hidden position_0_3 -2.97218e-07
  hidden position_0_4 1.11065e-06
  hidden translation_11 -1.77642e-06 -3.22228e-07 0.126475
  hidden rotation_11 0.096337 0.99532 -0.00761657 1.46124e-07
  hidden translation_18 -2.27233e-05 -0.0982673 0.100022
  hidden rotation_18 -0.140908 0.367529 -0.919276 1.0555
  hidden position_18_0 -0.0481307
  hidden translation_19 0.105208 -0.0151696 4.34543e-05
  hidden rotation_19 -1 9.2263e-05 0.000127719 0.048144
  hidden position_19_0 1.37869
  hidden translation_20 0.0003683 -0.000311913 3.80377e-05
  hidden rotation_20 2.88571e-06 1.56214e-06 1 1.37869
  hidden position_20_0 0.00430459
  hidden translation_21 0.0557157 -0.000421295 4.08049e-05
  hidden rotation_21 0.999976 0.000340738 0.0069529 0.00429278
  hidden position_21_0 2.65657e-05
  hidden position_21_1 -2.32642e-11
  hidden position_21_2 3.54181e-10
  hidden translation_22 0.0687702 -0.0134216 -0.00495024
  hidden rotation_22 2.43598e-05 -1 -6.29125e-05 -0.959982
  hidden position_22_1 -1.99112e-09
  hidden translation_24 0.014 5.67062e-10 -3.52207e-08
  hidden rotation_24 1.61162e-09 -1 -3.42156e-09 -0.96
  hidden position_24_0 8.75192e-11
  hidden translation_25 0.014 2.15324e-09 -1.08293e-08
  hidden rotation_25 -2.53177e-12 -1 -4.86099e-12 -0.96
  hidden translation_26 0.069 0.013 -0.00500006
  hidden rotation_26 -3.61737e-11 -1 -2.58594e-11 -0.96
  hidden position_26_0 1.45011e-10
  hidden translation_27 0.014 5.48748e-10 -3.52226e-08
  hidden rotation_27 -1.3868e-11 -1 -1.69197e-11 -0.96
  hidden position_27_0 8.75394e-11
  hidden translation_28 0.014 2.15283e-09 -1.08293e-08
  hidden rotation_28 -2.53117e-12 -1 -4.86189e-12 -0.96
  hidden translation_29 0.049 -4.08086e-09 -0.026
  hidden rotation_29 -0.0109196 0.998632 0.0511283 3.85257e-10
  hidden position_29_0 4.13375e-11
  hidden translation_30 0.014 -1.27739e-09 -4.28375e-09
  hidden rotation_30 2.53575e-12 1 -4.84263e-12 -0.96
  hidden translation_31 -3.27705e-05 0.0982651 0.100067
  hidden rotation_31 0.209836 0.344711 0.914955 1.04222
  hidden position_31_0 0.0545946
  hidden translation_32 0.105194 0.0151925 6.21883e-05
  hidden rotation_32 1 0.000183008 -0.000204456 0.05461
  hidden position_32_0 -1.37054
  hidden translation_33 0.00022427 0.00015946 5.4084e-05
  hidden rotation_33 6.2106e-07 7.96089e-06 -1 1.37054
  hidden position_33_0 -0.0754384
  hidden translation_34 0.05584 0.0002514 4.36365e-05
  hidden rotation_34 -1 0.000148793 -0.000335459 0.0754274
  hidden position_34_0 -2.54373e-05
  hidden position_34_1 -4.8751e-12
  hidden position_34_2 4.04739e-10
  hidden translation_35 0.068894 -0.012752 -0.00493033
  hidden rotation_35 -1.43702e-05 -1 4.19903e-05 -0.959983
  hidden position_35_1 1.7428e-09
  hidden translation_37 0.014 -1.54883e-09 -3.46433e-08
  hidden rotation_37 -2.83291e-09 -1 -2.63307e-09 -0.96
  hidden position_37_0 8.84345e-11
  hidden translation_38 0.014 -2.63683e-09 -1.04318e-08
  hidden rotation_38 3.01827e-12 -1 5.80561e-12 -0.96
  hidden translation_39 0.0690001 0.013 -0.00500007
  hidden rotation_39 4.31214e-11 -1 3.08561e-11 -0.96
  hidden position_39_0 1.56384e-10
  hidden translation_40 0.014 -1.54185e-09 -3.46623e-08
  hidden rotation_40 1.65629e-11 -1 2.02016e-11 -0.96
  hidden position_40_0 8.84496e-11
  hidden translation_41 0.014 -2.63781e-09 -1.04458e-08
  hidden rotation_41 3.02019e-12 -1 5.80602e-12 -0.96
  hidden translation_42 0.049 1.91656e-09 -0.026
  hidden rotation_42 0.0128866 0.998073 -0.0607033 3.88214e-10
  hidden position_42_0 4.40937e-11
  hidden translation_43 0.014 1.17401e-09 -4.42621e-09
  hidden rotation_43 -3.0201e-12 1 5.8042e-12 -0.96
  hidden translation_44 2.5902e-05 -0.0499987 -0.0849889
  hidden rotation_44 -0.739628 0.672778 0.0178974 2.58934e-06
  hidden position_44_0 1.28386e-06
  hidden translation_45 2.80027e-05 1.39109e-06 1.37393e-05
  hidden rotation_45 -0.205263 0.89361 -0.399159 1.38848e-06
  hidden position_45_0 -0.799999
  hidden translation_46 -5.30176e-06 1.45577e-06 2.27319e-05
  hidden rotation_46 2.30041e-06 1 -1.01804e-06 -0.799999
  hidden position_46_0 1
  hidden translation_47 -2.76547e-05 -2.92347e-07 -0.0999971
  hidden rotation_47 -1.49254e-09 1 -6.73083e-08 1
  hidden position_47_0 3.71977e-07
  hidden translation_48 -8.98383e-06 -1.45127e-07 -0.10291
  hidden rotation_48 0.0794016 0.993884 -0.0767512 3.70173e-07
  hidden position_48_0 8.48503e-08
  hidden translation_49 -5.00089e-06 -8.26663e-08 -6.12965e-06
  hidden rotation_49 0.00587602 0.996433 -0.0841796 3.2361e-07
  hidden translation_50 0.0199967 -0.007 -0.0410049
  hidden rotation_50 8.35275e-11 -4.81226e-13 1 -3.14159
  hidden translation_54 3.28264e-05 0.0500007 -0.0850094
  hidden rotation_54 -0.521219 0.758562 -0.391042 2.37971e-06
  hidden position_54_0 1.74028e-08
  hidden translation_55 3.49288e-05 8.00343e-07 -6.7193e-06
  hidden rotation_55 -0.0248723 0.869534 -0.493247 2.58673e-06
  hidden position_55_0 -0.799999
  hidden translation_56 -4.72545e-06 8.67268e-07 1.14003e-06
  hidden rotation_56 2.31374e-06 1 2.2377e-07 -0.799999
  hidden position_56_0 1
  hidden translation_57 -2.28074e-05 -4.7545e-07 -0.10001
  hidden rotation_57 -4.17952e-07 1 -3.48207e-07 1
  hidden position_57_0 3.71974e-07
  hidden translation_58 -8.98356e-06 -1.45171e-07 -0.10291
  hidden rotation_58 -0.0931425 0.99342 0.0666483 3.69661e-07
  hidden position_58_0 -7.52407e-08
  hidden translation_59 -5.00099e-06 -8.26749e-08 -6.12949e-06
  hidden rotation_59 -0.0204083 0.997142 0.072743 3.23376e-07
  hidden translation_60 0.0199967 0.007 -0.0410049
  hidden rotation_60 8.35025e-11 -4.80005e-13 1 -3.14159
  translation 0.0236777 0.791835 -0.000942376
  rotation 0.963121 0.188061 -0.192432 -1.606
  controller "my_controller"
  leftHandSlot [
    Transform {
      translation 0.06 0 0
      children [
        BallJoint {
          jointParameters BallJointParameters {
            springConstant 1
          }
          endPoint Connector {
            isLocked TRUE
            autoLock TRUE
            distanceTolerance 0.05
            axisTolerance 3.14159
            rotationTolerance 3.14159
            numberOfRotations 0
            snap FALSE
          }
        }
      ]
    }
  ]
  rightHandSlot [
    Transform {
      translation 0.06 0 0
      children [
        BallJoint {
          jointParameters BallJointParameters {
            springConstant 1
          }
          endPoint Connector {
            isLocked TRUE
            autoLock TRUE
            distanceTolerance 0.05
            axisTolerance 3.14159
            rotationTolerance 3.14159
            numberOfRotations 0
            snap FALSE
          }
        }
      ]
    }
  ]
}
FloorLight {
  translation -2.00175 -8.88178e-16 1.89667
}
FloorLight {
  translation 2.00366 2.22044e-15 -2.13347
}
DEF Swing Robot {
  translation 0 2.2 0
  rotation 1 0 0 -1.5708
  children [
    DEF RArm Transform {
      translation 0 0.25 -0.06
      children [
        HingeJoint {
          jointParameters HingeJointParameters {
            position -0.194773
            axis 0 1 0
            anchor 0 1 0
            minStop -3.1416
            maxStop 3.1416
            dampingConstant 1
          }
          endPoint Solid {
            translation -0.0115984 0.00738904 -0.758284
            rotation -0.999938 0.00790152 -0.00783412 -1.57551
            children [
              Transform {
                translation 0 -0.75 0
                children [
                  DEF SeatShape Solid {
                    translation 0 0 0.25
                    children [
                      DEF C1 Connector {
                        translation 0 0 0.25
                        rotation 1 0 0 -1.5708
                        isLocked TRUE
                        autoLock TRUE
                        distanceTolerance 0.05
                        numberOfRotations 0
                        snap FALSE
                      }
                      DEF SeatCon Connector {
                        translation 0 0 0.25
                        rotation 1 0 0 -1.5708
                        autoLock TRUE
                        numberOfRotations 0
                      }
                      Shape {
                        appearance Appearance {
                          material Material {
                          }
                        }
                        geometry DEF SSeat Box {
                          size 0.1 0.01 0.5
                        }
                      }
                    ]
                    boundingObject USE SSeat
                    physics Physics {
                    }
                  }
                ]
              }
              DEF RVBar Shape {
                appearance Appearance {
                  material Material {
                  }
                }
                geometry Cylinder {
                  height 1.5
                  radius 0.05
                }
              }
            ]
            boundingObject USE RVBar
            physics Physics {
              centerOfMass [
                0 0 0
              ]
            }
            linearVelocity -0.000278165 7.50801e-07 -6.41585e-07
            angularVelocity 1.18433e-06 -6.59678e-08 -0.000352467
          }
        }
      ]
    }
    DEF LArm Transform {
      translation 0 -0.25 -0.06
      children [
        HingeJoint {
          jointParameters HingeJointParameters {
            position -0.19431
            axis 0 1 0
            anchor 0 1 0
            minStop -3.1416
            maxStop 3.1416
            dampingConstant 1
          }
          endPoint Solid {
            translation -0.0119551 0.00377862 -0.758869
            rotation -0.999942 0.00768929 -0.00760239 -1.57317
            children [
              DEF C1 Connector {
                translation 0 -0.75 0
                rotation 1 0 0 1.5708
                isLocked TRUE
                autoLock TRUE
                distanceTolerance 0.05
                numberOfRotations 0
                snap FALSE
              }
              DEF SVBar2 Shape {
                appearance Appearance {
                  material Material {
                  }
                }
                geometry Cylinder {
                  height 1.5
                  radius 0.05
                }
              }
            ]
            boundingObject USE SVBar2
            physics Physics {
              centerOfMass [
                0 0 0
              ]
            }
            linearVelocity -0.000267725 6.45858e-06 -1.60056e-07
            angularVelocity -1.96775e-07 -1.25733e-07 -0.000352401
          }
        }
      ]
    }
    DEF SHBarShape Shape {
      appearance DEF SwingApp Appearance {
        material Material {
          diffuseColor 0.7 0.4 0.8
        }
        texture ImageTexture {
        }
      }
      geometry DEF SHBar Cylinder {
        height 0.5
        radius 0.05
      }
    }
  ]
  name "Swing"
  boundingObject USE SHBarShape
  selfCollision TRUE
}
