#VRML_SIM V8.3.2 utf8
WorldInfo {
  basicTimeStep 16
}
Viewpoint {
  orientation 0.741994 0.657543 0.130699 5.71656
  position -5.09145 7.83707 13.5648
}
Background {
  skyColor [
    0.4 0.7 1
  ]
}
Ceiling {
  translation 0 3 0
  size 5 5
}
Nao {
  hidden position_0_0 2.06511e-09
  hidden position2_0_0 1.30417e-08
  hidden position_0_1 0.736769
  hidden position2_0_1 -4.03514e-07
  hidden position_0_2 0.73682
  hidden position2_0_2 -4.30696e-07
  hidden position_0_3 -5.73077e-06
  hidden position_0_4 -5.05975e-06
  hidden linearVelocity_0 -0.290483 -0.0579437 -5.69618e-05
  hidden angularVelocity_0 4.54439e-05 4.39571e-05 -0.222542
  hidden translation_12 -3.77814e-05 7.03734e-07 0.126854
  hidden rotation_12 0.220099 0.963472 0.152575 1.35351e-08
  hidden linearVelocity_12 -0.263553 -0.0494548 -4.97981e-05
  hidden angularVelocity_12 4.54434e-05 4.39571e-05 -0.222542
  hidden translation_19 0.000343135 -0.0979996 0.100047
  hidden rotation_19 -8.43394e-07 1 -3.07172e-07 0.736769
  hidden position_19_0 -2.33877e-07
  hidden linearVelocity_19 -0.291605 -0.104506 -0.000159835
  hidden angularVelocity_19 -4.11833e-05 0.0071604 -3.35609
  hidden translation_20 0.106071 -0.0149999 0.000274512
  hidden rotation_20 0.00546103 0.999977 -0.00396847 6.85171e-07
  hidden position_20_0 2.55751e-07
  hidden linearVelocity_20 -0.38542 -0.298714 -0.000572644
  hidden angularVelocity_20 -4.25844e-05 0.00716093 -3.35609
  hidden translation_21 0.000891183 1.2815e-07 0.000280304
  hidden rotation_21 0.00278667 0.999841 0.0176348 7.53336e-07
  hidden position_21_0 9.43882e-08
  hidden linearVelocity_21 -0.455817 -0.466692 -0.00092994
  hidden angularVelocity_21 -4.20164e-05 0.00716245 -3.35609
  hidden translation_22 0.0570334 1.72332e-07 0.000368352
  hidden rotation_22 -0.00822223 0.999931 0.00840409 2.56897e-07
  hidden position_22_0 1.03139e-10
  hidden position_22_1 1.03133e-10
  hidden position_22_2 3.51327e-10
  hidden linearVelocity_22 -0.537938 -0.67354 -0.00137005
  hidden angularVelocity_22 -4.14763e-05 0.00716225 -3.35609
  hidden translation_23 0.0697135 -0.013 -0.00502258
  hidden rotation_23 7.84169e-13 -1 5.64874e-13 -0.96
  hidden position_23_0 1.8863e-10
  hidden linearVelocity_23 -0.631454 -0.775464 -0.00158594
  hidden angularVelocity_23 -4.14763e-05 0.00716225 -3.35609
  hidden translation_24 0.0142196 -7.5344e-08 -2.39332e-05
  hidden rotation_24 3.03534e-13 -1 3.68809e-13 -0.96
  hidden position_24_0 8.56622e-11
  hidden linearVelocity_24 -0.673311 -0.766602 -0.00156625
  hidden angularVelocity_24 -4.14763e-05 0.00716225 -3.35609
  hidden translation_25 0.0142195 -8.29182e-08 -2.39118e-05
  hidden rotation_25 5.37345e-14 -1 1.05756e-13 -0.96
  hidden linearVelocity_25 -0.690058 -0.72723 -0.00148189
  hidden angularVelocity_25 -4.14763e-05 0.00716225 -3.35609
  hidden translation_26 0.0697136 0.013 -0.00502239
  hidden rotation_26 7.82817e-13 -1 5.68871e-13 -0.96
  hidden position_26_0 1.88634e-10
  hidden linearVelocity_26 -0.631441 -0.775463 -0.00158594
  hidden angularVelocity_26 -4.14763e-05 0.00716225 -3.35609
  hidden translation_27 0.0142196 -7.5344e-08 -2.39332e-05
  hidden rotation_27 3.04375e-13 -1 3.6929e-13 -0.96
  hidden position_27_0 8.56547e-11
  hidden linearVelocity_27 -0.673299 -0.766601 -0.00156625
  hidden angularVelocity_27 -4.14763e-05 0.00716225 -3.35609
  hidden translation_28 0.0142195 -8.29182e-08 -2.39118e-05
  hidden rotation_28 5.51771e-14 -1 1.06011e-13 -0.96
  hidden linearVelocity_28 -0.690046 -0.727229 -0.00148189
  hidden angularVelocity_28 -4.14763e-05 0.00716225 -3.35609
  hidden translation_29 0.0495014 -1.4198e-07 -0.0263858
  hidden rotation_29 0.000258555 0.999999 -0.00122619 3.51327e-10
  hidden position_29_0 4.97482e-11
  hidden linearVelocity_29 -0.657964 -0.698375 -0.00142087
  hidden angularVelocity_29 -4.14763e-05 0.00716225 -3.35609
  hidden translation_30 0.0141685 6.24984e-08 0.000142769
  hidden rotation_30 -5.52372e-14 1 1.06087e-13 -0.96
  hidden linearVelocity_30 -0.658302 -0.741159 -0.00151221
  hidden angularVelocity_30 -4.14763e-05 0.00716225 -3.35609
  hidden translation_31 0.00035945 0.0980004 0.100041
  hidden rotation_31 -1.14519e-06 1 -2.00148e-07 0.73682
  hidden position_31_0 1.7424e-07
  hidden linearVelocity_31 -0.291521 -0.104545 -0.000159915
  hidden angularVelocity_31 -4.15509e-05 0.00715894 -3.35549
  hidden translation_32 0.106082 0.0150001 0.000278545
  hidden rotation_32 0.00170938 0.999997 -0.00197989 5.13191e-07
  hidden position_32_0 -1.99336e-07
  hidden linearVelocity_32 -0.385315 -0.298747 -0.000572693
  hidden angularVelocity_32 -4.29642e-05 0.00715946 -3.35549
  hidden translation_33 0.000898091 1.28217e-07 0.000283335
  hidden rotation_33 -0.00262283 0.99876 -0.0497076 5.6286e-07
  hidden position_33_0 1.68945e-07
  hidden linearVelocity_33 -0.455709 -0.466717 -0.000929954
  hidden angularVelocity_33 -4.24016e-05 0.00716099 -3.35549
  hidden translation_34 0.0570384 1.72235e-07 0.000370433
  hidden rotation_34 0.0867942 0.996161 0.0113641 2.00169e-07
  hidden position_34_0 1.81746e-10
  hidden position_34_1 1.81755e-10
  hidden position_34_2 2.99201e-10
  hidden linearVelocity_34 -0.537833 -0.673542 -0.00136999
  hidden angularVelocity_34 -4.18193e-05 0.00716077 -3.35549
  hidden translation_35 0.0697135 -0.013 -0.0050225
  hidden rotation_35 7.87385e-13 -1 5.65415e-13 -0.96
  hidden position_35_0 2.58177e-10
  hidden linearVelocity_35 -0.631339 -0.775443 -0.00158582
  hidden angularVelocity_35 -4.18193e-05 0.00716077 -3.35549
  hidden translation_36 0.0142195 -7.53138e-08 -2.39025e-05
  hidden rotation_36 2.98365e-13 -1 3.67847e-13 -0.96
  hidden position_36_0 7.63487e-11
  hidden linearVelocity_36 -0.673189 -0.766579 -0.00156613
  hidden angularVelocity_36 -4.18193e-05 0.00716077 -3.35549
  hidden translation_37 0.0142195 -8.2894e-08 -2.38925e-05
  hidden rotation_37 5.64994e-14 -1 1.06673e-13 -0.96
  hidden linearVelocity_37 -0.689931 -0.727213 -0.00148178
  hidden angularVelocity_37 -4.18193e-05 0.00716077 -3.35549
  hidden translation_38 0.0697136 0.013 -0.00502232
  hidden rotation_38 7.82276e-13 -1 5.66557e-13 -0.96
  hidden position_38_0 2.58159e-10
  hidden linearVelocity_38 -0.631327 -0.775442 -0.00158582
  hidden angularVelocity_38 -4.18193e-05 0.00716077 -3.35549
  hidden translation_39 0.0142195 -7.53138e-08 -2.39025e-05
  hidden rotation_39 3.04616e-13 -1 3.70221e-13 -0.96
  hidden position_39_0 7.63556e-11
  hidden linearVelocity_39 -0.673177 -0.766579 -0.00156612
  hidden angularVelocity_39 -4.18193e-05 0.00716077 -3.35549
  hidden translation_40 0.0142195 -8.2894e-08 -2.38925e-05
  hidden rotation_40 5.42154e-14 -1 1.05891e-13 -0.96
  hidden linearVelocity_40 -0.689918 -0.727212 -0.00148177
  hidden angularVelocity_40 -4.18193e-05 0.00716077 -3.35549
  hidden translation_41 0.0495014 -1.41886e-07 -0.0263858
  hidden rotation_41 0.000305455 0.999999 -0.00144158 2.992e-10
  hidden position_41_0 6.66905e-11
  hidden linearVelocity_41 -0.65784 -0.698365 -0.00142078
  hidden angularVelocity_41 -4.18193e-05 0.00716077 -3.35549
  hidden translation_42 0.0141684 6.24841e-08 0.000142776
  hidden rotation_42 -5.41553e-14 1 1.05456e-13 -0.96
  hidden linearVelocity_42 -0.658181 -0.741142 -0.0015121
  hidden angularVelocity_42 -4.18193e-05 0.00716077 -3.35549
  hidden translation_43 3.15169e-05 -0.0500113 -0.085144
  hidden rotation_43 0.0692685 0.994746 -0.0753783 -5.79777e-06
  hidden position_43_0 8.25229e-06
  hidden linearVelocity_43 -0.312209 -0.0645357 -6.03437e-05
  hidden angularVelocity_43 4.54934e-05 4.36243e-05 -0.222542
  hidden translation_44 -6.18729e-06 -1.0859e-05 6.92804e-05
  hidden rotation_44 -0.127099 0.990531 0.0519138 -6.5537e-06
  hidden position_44_0 -1.05219
  hidden linearVelocity_44 -0.31942 -0.0652123 -6.00017e-05
  hidden angularVelocity_44 0.000120057 6.90327e-05 -0.222542
  hidden translation_45 0.000166475 -1.0593e-05 0.000123714
  hidden rotation_45 4.97774e-07 1 -1.21004e-07 -1.05219
  hidden position_45_0 0.818779
  hidden linearVelocity_45 -0.319121 -0.0800414 -6.2268e-05
  hidden angularVelocity_45 0.000119988 7.31472e-05 -0.224428
  hidden translation_46 -0.000498958 1.4693e-06 -0.101257
  hidden rotation_46 -6.25486e-07 1 1.02976e-06 0.818779
  hidden position_46_0 -2.20421e-07
  hidden linearVelocity_46 -0.571618 -0.310821 -0.000550463
  hidden angularVelocity_46 -5.86701e-05 0.0146071 -6.6268
  hidden translation_47 0.000223293 1.5006e-06 -0.104041
  hidden rotation_47 0.729488 0.683706 0.019837 -2.29682e-07
  hidden position_47_0 -4.46101e-07
  hidden linearVelocity_47 -0.84147 -0.473134 -0.000905422
  hidden angularVelocity_47 -5.86336e-05 0.0146071 -6.6268
  hidden translation_48 0.000881857 1.67047e-06 -0.000749191
  hidden rotation_48 0.627805 0.778064 0.0218249 -2.02704e-07
  hidden linearVelocity_48 -0.955913 -0.763926 -0.00154506
  hidden angularVelocity_48 -5.87671e-05 0.014607 -6.6268
  hidden translation_49 0.0199274 -0.00699825 -0.041209
  hidden rotation_49 2.31214e-07 -4.49827e-09 1 -3.14159
  hidden linearVelocity_49 -1.02395 -0.76835 -0.00155412
  hidden angularVelocity_49 -5.87671e-05 0.014607 -6.6268
  hidden translation_53 3.18122e-05 0.0499851 -0.0851444
  hidden rotation_53 0.155805 0.967048 0.201355 -5.67631e-06
  hidden position_53_0 7.16389e-06
  hidden linearVelocity_53 -0.312174 -0.0645315 -6.0343e-05
  hidden angularVelocity_53 4.534e-05 4.35693e-05 -0.222542
  hidden translation_54 -5.94632e-06 -1.44757e-05 6.84757e-05
  hidden rotation_54 0.0533531 0.996691 0.061324 -6.21002e-06
  hidden position_54_0 -1.05274
  hidden linearVelocity_54 -0.319374 -0.0652068 -5.99943e-05
  hidden angularVelocity_54 0.000119556 6.88909e-05 -0.222542
  hidden translation_55 0.000167311 -1.42282e-05 0.000121934
  hidden rotation_55 9.06314e-07 1 4.35491e-08 -1.05274
  hidden position_55_0 0.818779
  hidden linearVelocity_55 -0.319068 -0.0800402 -6.22563e-05
  hidden angularVelocity_55 0.000119323 7.31316e-05 -0.224495
  hidden translation_56 -0.000499815 -2.18773e-06 -0.101256
  hidden rotation_56 -7.54898e-07 1 1.0431e-06 0.818779
  hidden position_56_0 -1.47261e-07
  hidden linearVelocity_56 -0.571447 -0.310957 -0.000551049
  hidden angularVelocity_56 -4.35392e-05 0.0145995 -6.62687
  hidden translation_57 0.000222041 -2.1565e-06 -0.104041
  hidden rotation_57 -0.889225 0.341409 0.304498 -1.87668e-07
  hidden position_57_0 4.03142e-07
  hidden linearVelocity_57 -0.841219 -0.473413 -0.00090675
  hidden angularVelocity_57 -4.35758e-05 0.0145995 -6.62687
  hidden translation_58 0.000880636 -1.9867e-06 -0.000749163
  hidden rotation_58 -0.62479 0.680511 0.382808 -1.49516e-07
  hidden linearVelocity_58 -0.955507 -0.764262 -0.00154644
  hidden angularVelocity_58 -4.34437e-05 0.0145996 -6.62687
  hidden translation_59 0.0199262 0.00699809 -0.0412089
  hidden rotation_59 2.34076e-07 4.52753e-09 1 -3.14159
  hidden linearVelocity_59 -1.02354 -0.768716 -0.00155572
  hidden angularVelocity_59 -4.34437e-05 0.0145996 -6.62687
  translation 0.273982 0.793827 -0.000523599
  rotation 0.973781 0.161029 -0.160685 -1.59509
  controller "my_controller"
  bodySlot [
    Connector {
      translation 0 0 -0.12
      rotation 0 1 0 3.14159
      isLocked TRUE
      autoLock TRUE
      distanceTolerance 0.05
      axisTolerance 3
      rotationTolerance 3
      numberOfRotations 0
      snap FALSE
    }
  ]
}
DirectionalLight {
  ambientIntensity 1
  direction -0.1 -0.5 -0.3
}
RectangleArena {
  floorSize 5 5
}
FloorLight {
  translation -2.00175 -8.88178e-16 1.89667
}
FloorLight {
  translation 2.00366 2.22044e-15 -2.13347
}
DEF Swing Robot {
  translation 0 2.2 0
  rotation 1 0 0 -1.5708
  children [
    DEF RArm Transform {
      translation 0 0.25 -0.06
      children [
        HingeJoint {
          jointParameters HingeJointParameters {
            position -0.42116
            axis 0 1 0
            anchor 0 1 0
            minStop -3.1416
            maxStop 3.1416
            dampingConstant 1
          }
          endPoint Solid {
            translation 0.15959 0.0014022 -0.743772
            rotation -0.985542 0.119688 -0.119921 -1.58761
            children [
              Transform {
                translation 0 -0.75 0
                children [
                  DEF SeatShape Solid {
                    translation 0 0 0.25
                    children [
                      DEF C1 Connector {
                        translation 0 0 0.25
                        rotation 1 0 0 -1.5708
                        isLocked TRUE
                        autoLock TRUE
                        distanceTolerance 0.05
                        numberOfRotations 0
                        snap FALSE
                      }
                      Connector {
                        rotation 1 0 0 -1.5708
                        isLocked TRUE
                        autoLock TRUE
                        distanceTolerance 0.05
                        axisTolerance 3
                        rotationTolerance 3
                        numberOfRotations 0
                        snap FALSE
                      }
                      DEF SeatCon Connector {
                        translation 0 0 0.25
                        rotation 1 0 0 -1.5708
                        autoLock TRUE
                        numberOfRotations 0
                      }
                      Shape {
                        appearance Appearance {
                          material Material {
                          }
                        }
                        geometry DEF SSeat Box {
                          size 0.1 0.01 0.5
                        }
                      }
                    ]
                    boundingObject USE SSeat
                    physics Physics {
                    }
                  }
                ]
              }
              DEF RVBar Shape {
                appearance Appearance {
                  material Material {
                  }
                }
                geometry Cylinder {
                  height 1.5
                  radius 0.05
                }
              }
            ]
            boundingObject USE RVBar
            physics Physics {
              centerOfMass [
                0 0 0
              ]
            }
            linearVelocity -0.171984 -0.0377019 -3.33722e-05
            angularVelocity 3.73665e-05 2.92266e-05 -0.222578
          }
        }
      ]
    }
    DEF LArm Transform {
      translation 0 -0.25 -0.06
      children [
        HingeJoint {
          jointParameters HingeJointParameters {
            position -0.42084
            axis 0 1 0
            anchor 0 1 0
            minStop -3.1416
            maxStop 3.1416
            dampingConstant 1
          }
          endPoint Solid {
            translation 0.158578 0.000190168 -0.740517
            rotation -0.985555 0.119725 -0.119778 -1.58582
            children [
              DEF C1 Connector {
                translation 0 -0.75 0
                rotation 1 0 0 1.5708
                isLocked TRUE
                autoLock TRUE
                distanceTolerance 0.05
                numberOfRotations 0
                snap FALSE
              }
              DEF SVBar2 Shape {
                appearance Appearance {
                  material Material {
                  }
                }
                geometry Cylinder {
                  height 1.5
                  radius 0.05
                }
              }
            ]
            boundingObject USE SVBar2
            physics Physics {
              centerOfMass [
                0 0 0
              ]
            }
            linearVelocity -0.16465 -0.035812 -3.10897e-05
            angularVelocity 3.42729e-05 3.00304e-05 -0.222568
          }
        }
      ]
    }
    DEF SHBarShape Shape {
      appearance DEF SwingApp Appearance {
        material Material {
          diffuseColor 0.7 0.4 0.8
        }
        texture ImageTexture {
        }
      }
      geometry DEF SHBar Cylinder {
        height 0.5
        radius 0.05
      }
    }
  ]
  name "Swing"
  boundingObject USE SHBarShape
  selfCollision TRUE
}
