#VRML_SIM V8.3.2 utf8
WorldInfo {
  basicTimeStep 16
}
Viewpoint {
  orientation 0.160688 -0.924214 -0.346422 3.96924
  position 17.3021 20.2213 -13.8047
}
Background {
  skyColor [
    0.4 0.7 1
  ]
}
Ceiling {
  translation 0 3 0
  size 5 5
}
Nao {
  hidden position_0_0 -3.66472e-08
  hidden position2_0_0 -0.000164339
  hidden position_0_1 -1.56267
  hidden position2_0_1 -1.53233e-06
  hidden position_0_2 -1.56258
  hidden position2_0_2 -6.66318e-07
  hidden position_0_3 -2.0913e-05
  hidden position_0_4 -2.00981e-05
  hidden linearVelocity_0 -0.0795801 0.00818429 1.91781e-05
  hidden angularVelocity_0 5.43597e-05 1.97069e-05 -0.0577184
  hidden translation_11 -5.78312e-05 5.15055e-07 0.126986
  hidden rotation_11 -5.39961e-05 1 0.00018506 -0.000164517
  hidden linearVelocity_11 -0.0722646 0.00865648 2.62043e-05
  hidden angularVelocity_11 5.43586e-05 1.97068e-05 -0.0577185
  hidden translation_18 -0.000443174 -0.0980297 0.10022
  hidden rotation_18 1.39957e-06 1 0.000136329 -0.153343
  hidden position_18_0 -1.42577e-06
  hidden linearVelocity_18 -0.0758948 0.00706726 2.03373e-05
  hidden angularVelocity_18 -0.000179049 -6.7487e-06 -0.0774628
  hidden translation_19 0.105538 -0.0150197 0.000368752
  hidden rotation_19 -0.785093 0.539831 -0.303663 1.18137e-05
  hidden position_19_0 6.51344e-06
  hidden linearVelocity_19 -0.0749062 0.00219794 1.73245e-05
  hidden angularVelocity_19 -0.000179068 -9.40488e-06 -0.0774691
  hidden translation_20 0.000328051 -2.83645e-05 0.000374261
  hidden rotation_20 -0.271712 0.962124 0.0221346 7.06215e-06
  hidden position_20_0 -0.000101027
  hidden linearVelocity_20 -0.073865 -0.00185206 1.36808e-05
  hidden angularVelocity_20 -0.000186242 1.45065e-05 -0.0774753
  hidden translation_21 0.0565006 -2.82836e-05 0.000482397
  hidden rotation_21 -0.995872 0.0881436 -0.0216689 8.91391e-05
  hidden position_21_0 0.009404
  hidden position_21_1 -6.36756e-11
  hidden position_21_2 7.28919e-10
  hidden linearVelocity_21 -0.0724874 -0.00676821 8.30516e-06
  hidden angularVelocity_21 -0.000231952 4.97024e-07 -0.0774784
  hidden translation_22 0.0694891 -0.0130135 -0.00500668
  hidden rotation_22 2.64555e-06 -1 1.26525e-07 -0.950602
  hidden position_22_0 2.34907e-11
  hidden linearVelocity_22 -0.0724901 -0.00962437 7.21459e-06
  hidden angularVelocity_22 -2.28198e-05 2.06089e-05 -0.0596385
  hidden translation_24 0.0140873 -1.45495e-05 -0.00023391
  hidden rotation_24 -2.72548e-09 -1 1.31195e-07 -0.96
  hidden position_24_0 6.86746e-11
  hidden linearVelocity_24 -0.0734035 -0.0102181 7.35847e-06
  hidden angularVelocity_24 -2.28198e-05 2.06089e-05 -0.0596385
  hidden translation_25 0.0142744 -2.70949e-06 -6.15965e-05
  hidden rotation_25 -6.18512e-09 -1 -6.81775e-10 -0.96
  hidden linearVelocity_25 -0.0740698 -0.00985445 7.73904e-06
  hidden angularVelocity_25 -2.28198e-05 2.06089e-05 -0.0596385
  hidden translation_26 0.069506 0.0129847 -0.00498159
  hidden rotation_26 2.0813e-07 -1 2.94688e-07 -0.96
  hidden position_26_0 9.68726e-11
  hidden linearVelocity_26 -0.0727469 -0.00990492 9.0608e-06
  hidden angularVelocity_26 -0.000231952 4.97024e-07 -0.0774784
  hidden translation_27 0.0140764 -1.47832e-05 -0.000244434
  hidden rotation_27 -2.18482e-09 -1 1.3353e-07 -0.96
  hidden position_27_0 6.88206e-11
  hidden linearVelocity_27 -0.073635 -0.0103143 1.17164e-05
  hidden angularVelocity_27 -0.000231952 4.97024e-07 -0.0774784
  hidden translation_28 0.0142749 -2.7525e-06 -6.45504e-05
  hidden rotation_28 -5.95233e-09 -1 -5.08792e-10 -0.96
  hidden linearVelocity_28 -0.0744963 -0.00983381 1.42984e-05
  hidden angularVelocity_28 -0.000231952 4.97024e-07 -0.0774784
  hidden translation_29 0.0495912 -1.46927e-07 -0.0264413
  hidden rotation_29 -6.19984e-05 1 0.000563652 7.28911e-10
  hidden position_29_0 1.02978e-10
  hidden linearVelocity_29 -0.0743127 -0.00891595 1.3755e-05
  hidden angularVelocity_29 -0.000231952 4.97024e-07 -0.0774784
  hidden translation_30 0.0141939 6.39327e-08 0.000169289
  hidden rotation_30 5.15106e-14 1 -1.00286e-13 -0.96
  hidden linearVelocity_30 -0.073714 -0.00969653 1.19573e-05
  hidden angularVelocity_30 -0.000231952 4.97024e-07 -0.0774784
  hidden translation_31 -0.000440251 0.0979618 0.100228
  hidden rotation_31 -1.31393e-06 1 4.66507e-06 -0.153223
  hidden position_31_0 1.08791e-06
  hidden linearVelocity_31 -0.0759113 0.00720608 1.97876e-05
  hidden angularVelocity_31 -0.000179711 2.77836e-06 -0.077719
  hidden translation_32 0.105536 0.0149737 0.000373264
  hidden rotation_32 -0.694953 0.594872 -0.40394 1.06993e-05
  hidden position_32_0 -0.0128262
  hidden linearVelocity_32 -0.074926 0.00235973 1.59319e-05
  hidden angularVelocity_32 -0.000176173 8.39916e-06 -0.0777244
  hidden translation_33 0.000322868 -3.96109e-05 0.00037776
  hidden rotation_33 -3.39067e-05 0.000528558 -1 0.0128203
  hidden position_33_0 4.0947e-05
  hidden linearVelocity_33 -0.0738841 -0.00169447 1.22379e-05
  hidden angularVelocity_33 -0.000165757 -1.3666e-05 -0.0777297
  hidden translation_34 0.0564941 -3.54332e-05 0.000484935
  hidden rotation_34 0.975248 0.212812 -0.0600267 3.75619e-05
  hidden position_34_0 0.00949466
  hidden position_34_1 -6.35563e-11
  hidden position_34_2 6.78635e-10
  hidden linearVelocity_34 -0.0725052 -0.00662116 9.08398e-06
  hidden angularVelocity_34 -4.33053e-06 3.09355e-05 -0.0777326
  hidden translation_35 0.0659826 -0.0130381 -0.000137272
  hidden rotation_35 1.06124e-06 -1 7.58486e-06 -0.950528
  hidden position_35_0 2.34264e-10
  hidden linearVelocity_35 -0.0722818 -0.00919658 6.54639e-06
  hidden angularVelocity_35 -1.23708e-05 1.93099e-06 -0.0596388
  hidden translation_37 0.0200826 -1.45272e-05 -0.000237261
  hidden rotation_37 -1.84946e-09 -1 1.3172e-07 -0.96
  hidden position_37_0 6.86954e-11
  hidden linearVelocity_37 -0.0734281 -0.0100616 6.75593e-06
  hidden angularVelocity_37 -1.23708e-05 1.93099e-06 -0.0596388
  hidden translation_38 0.0142747 -2.71073e-06 -6.24037e-05
  hidden rotation_38 -6.08429e-09 -1 -6.10496e-10 -0.96
  hidden linearVelocity_38 -0.0740944 -0.00969784 6.90596e-06
  hidden angularVelocity_38 -1.23708e-05 1.93099e-06 -0.0596388
  hidden translation_39 0.0695007 0.0129847 -0.00498125
  hidden rotation_39 2.0858e-07 -1 2.94383e-07 -0.96
  hidden position_39_0 9.70203e-11
  hidden linearVelocity_39 -0.0727632 -0.00977683 7.84215e-06
  hidden angularVelocity_39 -4.33053e-06 3.09355e-05 -0.0777326
  hidden translation_40 0.0140737 -1.47653e-05 -0.00024804
  hidden rotation_40 -1.90531e-09 -1 1.33738e-07 -0.96
  hidden position_40_0 6.88357e-11
  hidden linearVelocity_40 -0.0736543 -0.010187 7.72849e-06
  hidden angularVelocity_40 -4.33053e-06 3.09355e-05 -0.0777326
  hidden translation_41 0.0142754 -2.75504e-06 -6.53501e-05
  hidden rotation_41 -5.7358e-09 -1 -3.55259e-10 -0.96
  hidden linearVelocity_41 -0.0745185 -0.00970482 7.9686e-06
  hidden angularVelocity_41 -4.33053e-06 3.09355e-05 -0.0777326
  hidden translation_42 0.0495912 -1.28329e-07 -0.0264413
  hidden rotation_42 0.000284942 0.999999 -0.00165008 6.78635e-10
  hidden position_42_0 1.19944e-10
  hidden linearVelocity_42 -0.0743368 -0.00877522 8.32857e-06
  hidden angularVelocity_42 -4.33053e-06 3.09355e-05 -0.0777326
  hidden translation_43 0.0141937 6.93918e-08 0.000169294
  hidden rotation_43 -1.38348e-13 1 2.71723e-13 -0.96
  hidden linearVelocity_43 -0.0737362 -0.00955846 7.9833e-06
  hidden angularVelocity_43 -4.33053e-06 3.09355e-05 -0.0777326
  hidden translation_44 0.000170131 -0.050599 -0.0848479
  hidden rotation_44 0.422499 0.720827 0.549457 -5.16725e-05
  hidden position_44_0 1.0431e-05
  hidden linearVelocity_44 -0.0853913 0.00786392 1.51132e-05
  hidden angularVelocity_44 5.15514e-05 1.86211e-05 -0.0577191
  hidden translation_45 4.40851e-05 -6.47797e-06 0.000359161
  hidden rotation_45 -0.0751163 0.997076 -0.0140352 -2.35322e-05
  hidden position_45_0 -1.1
  hidden linearVelocity_45 -0.0871867 0.00816001 1.50778e-05
  hidden angularVelocity_45 7.47423e-05 1.92178e-05 -0.0577194
  hidden translation_46 0.000181943 -6.2163e-06 0.000427583
  hidden rotation_46 -1.6202e-06 1 3.46076e-07 -1.1
  hidden position_46_0 1
  hidden linearVelocity_46 -0.0878207 0.00440484 1.47359e-05
  hidden angularVelocity_46 7.20021e-05 1.74944e-05 -0.05772
  hidden translation_47 -0.00105369 1.14764e-06 -0.101595
  hidden rotation_47 4.13044e-07 1 1.27074e-06 1
  hidden position_47_0 6.00449e-08
  hidden linearVelocity_47 -0.091731 0.00110345 8.82687e-06
  hidden angularVelocity_47 7.20032e-05 1.74948e-05 -0.05772
  hidden translation_48 0.000309576 1.48198e-06 -0.104533
  hidden rotation_48 -0.751597 0.652859 -0.0942192 1.85367e-07
  hidden position_48_0 -4.93592e-07
  hidden linearVelocity_48 -0.0945118 0.000795943 5.24985e-06
  hidden angularVelocity_48 7.20028e-05 1.74949e-05 -0.05772
  hidden translation_49 0.00124256 1.65605e-06 -0.00108057
  hidden rotation_49 -0.869 0.480516 -0.118084 1.43005e-07
  hidden linearVelocity_49 -0.0965139 -0.00112858 2.17131e-06
  hidden angularVelocity_49 7.16699e-05 1.74313e-05 -0.05772
  hidden translation_50 0.0198263 -0.00699855 -0.0415079
  hidden rotation_50 2.35231e-07 -4.32331e-09 1 -3.14159
  hidden linearVelocity_50 -0.0970911 -0.000912867 1.51593e-06
  hidden angularVelocity_50 7.16699e-05 1.74313e-05 -0.05772
  hidden translation_54 0.000245789 0.0505487 -0.0843144
  hidden rotation_54 -0.397065 0.822675 -0.406872 -6.2625e-05
  hidden position_54_0 -6.81208e-06
  hidden linearVelocity_54 -0.0853654 0.00798166 1.42702e-05
  hidden angularVelocity_54 5.08324e-05 1.86876e-05 -0.0577166
  hidden translation_55 5.32039e-05 -8.67467e-06 0.000326972
  hidden rotation_55 0.023478 0.999724 -0.000230572 -2.24162e-05
  hidden position_55_0 -1.1
  hidden linearVelocity_55 -0.0871628 0.0083549 1.35852e-05
  hidden angularVelocity_55 3.54269e-05 1.59945e-05 -0.0577153
  hidden translation_56 0.000192732 -8.4301e-06 0.000395157
  hidden rotation_56 -9.75654e-07 1 6.73778e-07 -1.1
  hidden position_56_0 1
  hidden linearVelocity_56 -0.087797 0.00466318 1.30631e-05
  hidden angularVelocity_56 3.18986e-05 1.43635e-05 -0.0577143
  hidden translation_57 -0.00105267 -3.15143e-06 -0.101602
  hidden rotation_57 -1.2701e-08 1 1.18438e-06 1
  hidden position_57_0 1.33354e-07
  hidden linearVelocity_57 -0.091707 0.00136172 1.00472e-05
  hidden angularVelocity_57 3.19027e-05 1.43647e-05 -0.0577143
  hidden translation_58 0.000308413 -2.17606e-06 -0.104533
  hidden rotation_58 0.535383 0.827118 -0.170999 2.58912e-07
  hidden position_58_0 2.6741e-07
  hidden linearVelocity_58 -0.0944872 0.00105141 8.41723e-06
  hidden angularVelocity_58 3.19038e-05 1.43652e-05 -0.0577143
  hidden translation_59 0.0012414 -2.00193e-06 -0.00108046
  hidden rotation_59 0.507833 0.81053 -0.291798 1.53942e-07
  hidden linearVelocity_59 -0.0964896 -0.000868472 6.83906e-06
  hidden angularVelocity_59 3.1407e-05 1.42704e-05 -0.0577143
  hidden translation_60 0.0198287 0.00699841 -0.0414848
  hidden rotation_60 -1.1104e-07 -2.62095e-08 1 -3.14159
  hidden linearVelocity_60 -0.0970661 -0.000647228 6.57607e-06
  hidden angularVelocity_60 3.1407e-05 1.42704e-05 -0.0577143
  translation -0.0561813 0.772175 0.00197453
  rotation -0.998026 -0.0380813 0.049948 1.5734
  controller "my_controller"
  leftHandSlot [
    DEF LeftConnector Connector {
      boundingObject Box {
        size 0.1 0.1 0.1
      }
      physics Physics {
      }
      isLocked TRUE
      distanceTolerance 0.1
      axisTolerance 3.14
      rotationTolerance 3.14
      numberOfRotations 0
      snap FALSE
    }
  ]
  rightHandSlot [
    DEF RightConnector Connector {
      boundingObject Box {
        size 0.1 0.1 0.1
      }
      physics Physics {
      }
      isLocked TRUE
      distanceTolerance 0.1
      axisTolerance 3.14159
      rotationTolerance 3.14
      numberOfRotations 0
      snap FALSE
    }
  ]
}
DirectionalLight {
  ambientIntensity 1
  direction -0.1 -0.5 -0.3
}
RectangleArena {
  floorSize 5 5
}
FloorLight {
  translation -2.00175 -8.88178e-16 1.89667
}
FloorLight {
  translation 2.00366 2.22044e-15 -2.13347
}
DEF Swing Robot {
  translation 0 2.2 0
  rotation 1 0 0 -1.5708
  children [
    DEF RArm Transform {
      translation 0 0.25 -0.06
      children [
        HingeJoint {
          jointParameters HingeJointParameters {
            position -0.182633
            axis 0 1 0
            anchor 0 1 0
            minStop -3.1416
            maxStop 3.1416
            dampingConstant 1
          }
          endPoint Solid {
            translation -0.0207268 0.00570358 -0.754141
            rotation -0.999997 0.00185484 -0.00179706 -1.57342
            children [
              Transform {
                translation 0 -0.75 0
                children [
                  DEF SeatShape Solid {
                    translation 0 0 0.25
                    children [
                      DEF Left_Hand_Bar Connector {
                        translation 0.2 0.25 -0.1
                        isLocked TRUE
                        distanceTolerance 0.1
                        axisTolerance 3.14
                        rotationTolerance 3.14
                        numberOfRotations 0
                        snap FALSE
                      }
                      DEF Right_Hand_Bar Connector {
                        translation 0.2 0.25 0.1
                        isLocked TRUE
                        distanceTolerance 0.1
                        rotationTolerance 3.14
                        numberOfRotations 0
                        snap FALSE
                      }
                      DEF C1 Connector {
                        translation 0 0 0.25
                        rotation 1 0 0 -1.5708
                        isLocked TRUE
                        autoLock TRUE
                        distanceTolerance 0.05
                        numberOfRotations 0
                        snap FALSE
                      }
                      DEF SeatCon Connector {
                        translation 0 0 0.25
                        rotation 1 0 0 -1.5708
                        autoLock TRUE
                        numberOfRotations 0
                      }
                      Shape {
                        appearance Appearance {
                          material Material {
                          }
                        }
                        geometry DEF SSeat Box {
                          size 0.1 0.01 0.5
                        }
                      }
                    ]
                    boundingObject USE SSeat
                    physics Physics {
                    }
                  }
                ]
              }
              DEF RVBar Shape {
                appearance Appearance {
                  material Material {
                  }
                }
                geometry Cylinder {
                  height 1.5
                  radius 0.05
                }
              }
            ]
            boundingObject USE RVBar
            physics Physics {
              centerOfMass [
                0 0 0
              ]
            }
            linearVelocity -0.0468212 0.00121209 2.43067e-07
            angularVelocity -1.00681e-06 1.01229e-06 -0.0596699
          }
        }
      ]
    }
    DEF LArm Transform {
      translation 0 -0.25 -0.06
      children [
        HingeJoint {
          jointParameters HingeJointParameters {
            position -0.182233
            axis 0 1 0
            anchor 0 1 0
            minStop -3.1416
            maxStop 3.1416
            dampingConstant 1
          }
          endPoint Solid {
            translation -0.0209812 0.0022406 -0.754177
            rotation -0.999997 0.00165104 -0.00160418 -1.57101
            children [
              DEF C1 Connector {
                translation 0 -0.75 0
                rotation 1 0 0 1.5708
                isLocked TRUE
                autoLock TRUE
                distanceTolerance 0.05
                numberOfRotations 0
                snap FALSE
              }
              DEF SVBar2 Shape {
                appearance Appearance {
                  material Material {
                  }
                }
                geometry Cylinder {
                  height 1.5
                  radius 0.05
                }
              }
            ]
            boundingObject USE SVBar2
            physics Physics {
              centerOfMass [
                0 0 0
              ]
            }
            linearVelocity -0.044999 0.00123369 2.73378e-07
            angularVelocity -7.89213e-07 1.17562e-06 -0.0596695
          }
        }
      ]
    }
    DEF SHBarShape Shape {
      appearance DEF SwingApp Appearance {
        material Material {
          diffuseColor 0.7 0.4 0.8
        }
        texture ImageTexture {
        }
      }
      geometry DEF SHBar Cylinder {
        height 0.5
        radius 0.05
      }
    }
  ]
  name "Swing"
  boundingObject USE SHBarShape
  selfCollision TRUE
}
