#VRML_SIM V8.3.2 utf8
WorldInfo {
  basicTimeStep 16
}
Viewpoint {
  orientation 0.00111102 -0.997383 -0.0722899 3.25668
  position 3.17765 5.31184 -29.1649
}
Background {
  skyColor [
    0.4 0.7 1
  ]
}
Ceiling {
  translation 0 3 0
  size 5 5
}
Nao {
  hidden position_0_0 -3.66389e-08
  hidden position2_0_0 -0.000164304
  hidden position_0_1 -1.56643
  hidden position2_0_1 -1.75677e-06
  hidden position_0_2 -1.56643
  hidden position2_0_2 -2.28598e-07
  hidden position_0_3 -1.91152e-05
  hidden position_0_4 -1.8567e-05
  hidden linearVelocity_0 -0.0624398 0.00368502 6.32157e-07
  hidden angularVelocity_0 -2.90412e-05 -8.89487e-06 -0.047424
  hidden translation_11 -5.73503e-05 5.08832e-07 0.126991
  hidden rotation_11 -5.5817e-05 1 0.000185049 -0.000164482
  hidden linearVelocity_11 -0.0564279 0.004058 -3.11199e-06
  hidden angularVelocity_11 -2.90408e-05 -8.89481e-06 -0.047424
  hidden translation_18 -0.000441842 -0.0980334 0.100267
  hidden rotation_18 -1.82328e-06 1 0.000134738 -0.157107
  hidden position_18_0 8.90312e-06
  hidden linearVelocity_18 -0.0594675 0.00303836 -7.22261e-08
  hidden angularVelocity_18 -1.83312e-05 -1.42371e-05 -0.0472
  hidden translation_19 0.105547 -0.0150234 0.000414726
  hidden rotation_19 0.0827346 0.922046 -0.378136 9.4653e-06
  hidden position_19_0 3.89874e-06
  hidden linearVelocity_19 -0.0588314 0.000106912 1.23442e-06
  hidden angularVelocity_19 2.426e-05 -1.13213e-05 -0.0472004
  hidden translation_20 0.000337117 -3.20534e-05 0.00041973
  hidden rotation_20 -0.0863601 0.996251 0.00514114 9.18664e-06
  hidden position_20_0 -1.25948e-05
  hidden linearVelocity_20 -0.0581638 -0.00232334 2.02653e-06
  hidden angularVelocity_20 2.11755e-05 2.76754e-05 -0.0472004
  hidden translation_21 0.0565095 -3.20176e-05 0.000527264
  hidden rotation_21 -0.0368926 0.990452 -0.132828 1.28721e-05
  hidden position_21_0 -5.99152e-06
  hidden position_21_1 -6.75426e-11
  hidden position_21_2 6.54432e-10
  hidden linearVelocity_21 -0.0572909 -0.00528002 1.6574e-06
  hidden angularVelocity_21 -1.6288e-05 1.07107e-05 -0.0471998
  hidden translation_22 0.0695108 -0.0130163 -0.00497649
  hidden rotation_22 6.44621e-07 -1 -4.35519e-07 -0.960006
  hidden position_22_0 -8.45037e-11
  hidden linearVelocity_22 -0.0574446 -0.00720406 2.13019e-06
  hidden angularVelocity_22 -8.28741e-06 5.12344e-06 -0.0471996
  hidden translation_24 0.0140872 -1.45492e-05 -0.000233887
  hidden rotation_24 -2.45492e-09 -1 1.31355e-07 -0.96
  hidden position_24_0 5.15584e-11
  hidden linearVelocity_24 -0.0579853 -0.00745463 2.19772e-06
  hidden angularVelocity_24 -8.27685e-06 5.12658e-06 -0.0471996
  hidden translation_25 0.0142744 -2.7097e-06 -6.15849e-05
  hidden rotation_25 -6.18511e-09 -1 -6.81748e-10 -0.96
  hidden linearVelocity_25 -0.0585104 -0.00716257 2.3215e-06
  hidden angularVelocity_25 -8.27685e-06 5.12658e-06 -0.0471996
  hidden translation_26 0.0695059 0.0129847 -0.00498155
  hidden rotation_26 2.0813e-07 -1 2.94688e-07 -0.96
  hidden position_26_0 7.24765e-11
  hidden linearVelocity_26 -0.0574474 -0.00718947 1.27758e-06
  hidden angularVelocity_26 -1.6288e-05 1.07107e-05 -0.0471998
  hidden translation_27 0.0140764 -1.47831e-05 -0.000244415
  hidden rotation_27 -2.18473e-09 -1 1.3353e-07 -0.96
  hidden position_27_0 5.15913e-11
  hidden linearVelocity_27 -0.0579882 -0.00743933 1.40733e-06
  hidden angularVelocity_27 -1.6288e-05 1.07107e-05 -0.0471998
  hidden translation_28 0.0142749 -2.75271e-06 -6.45363e-05
  hidden rotation_28 -5.95232e-09 -1 -5.08765e-10 -0.96
  hidden linearVelocity_28 -0.0585132 -0.00714713 1.6548e-06
  hidden angularVelocity_28 -1.6288e-05 1.07107e-05 -0.0471998
  hidden translation_29 0.0495911 -1.46244e-07 -0.0264412
  hidden rotation_29 -4.3507e-05 1 0.000498979 6.54424e-10
  hidden position_29_0 9.5664e-11
  hidden linearVelocity_29 -0.0584017 -0.00658951 1.74303e-06
  hidden angularVelocity_29 -1.6288e-05 1.07107e-05 -0.0471998
  hidden translation_30 0.0141939 6.42328e-08 0.000169277
  hidden rotation_30 4.05263e-14 1 -7.9024e-14 -0.96
  hidden linearVelocity_30 -0.0580365 -0.00706469 1.50912e-06
  hidden angularVelocity_30 -1.6288e-05 1.07107e-05 -0.0471998
  hidden translation_31 -0.000438966 0.0979648 0.100276
  hidden rotation_31 2.30817e-08 1 1.64683e-06 -0.157077
  hidden position_31_0 9.64528e-06
  hidden linearVelocity_31 -0.0594772 0.00313615 -1.60676e-06
  hidden angularVelocity_31 -3.45973e-05 -3.20289e-06 -0.0471994
  hidden translation_32 0.105545 0.0149767 0.000419796
  hidden rotation_32 0.0838729 0.899789 -0.428187 9.62015e-06
  hidden position_32_0 -0.0128237
  hidden linearVelocity_32 -0.058844 0.000227847 -2.09139e-06
  hidden angularVelocity_32 -1.23102e-05 9.87279e-06 -0.0471996
  hidden translation_33 0.00033202 -3.66022e-05 0.000423787
  hidden rotation_33 -0.000102499 0.000707472 -1 0.0128199
  hidden position_33_0 4.45878e-06
  hidden linearVelocity_33 -0.0581769 -0.00220034 -2.30412e-06
  hidden angularVelocity_33 -1.03869e-05 -2.53387e-05 -0.0471996
  hidden translation_34 0.056503 -3.22899e-05 0.000530363
  hidden rotation_34 0.0358831 0.984594 -0.171134 1.3048e-05
  hidden position_34_0 -5.99683e-06
  hidden position_34_1 -6.75095e-11
  hidden position_34_2 6.0419e-10
  hidden linearVelocity_34 -0.0573049 -0.00515851 -1.47939e-06
  hidden angularVelocity_34 1.57743e-05 -1.13232e-05 -0.0471994
  hidden translation_35 0.0660509 -0.0130338 -7.32005e-05
  hidden rotation_35 8.30291e-07 -1 7.93115e-06 -0.960023
  hidden position_35_0 2.40386e-10
  hidden linearVelocity_35 -0.0572763 -0.00686039 -1.4861e-06
  hidden angularVelocity_35 7.57287e-06 -5.88898e-06 -0.0471994
  hidden translation_37 0.0200825 -1.45271e-05 -0.000237238
  hidden rotation_37 -1.83834e-09 -1 1.31678e-07 -0.96
  hidden position_37_0 5.15783e-11
  hidden linearVelocity_37 -0.058003 -0.00732416 -1.5447e-06
  hidden angularVelocity_37 7.57136e-06 -5.88861e-06 -0.0471994
  hidden translation_38 0.0142747 -2.71066e-06 -6.23921e-05
  hidden rotation_38 -6.08431e-09 -1 -6.1052e-10 -0.96
  hidden linearVelocity_38 -0.058528 -0.00703201 -1.66535e-06
  hidden angularVelocity_38 7.57136e-06 -5.88861e-06 -0.0471994
  hidden translation_39 0.0695006 0.0129847 -0.0049812
  hidden rotation_39 2.0858e-07 -1 2.94383e-07 -0.96
  hidden position_39_0 7.26033e-11
  hidden linearVelocity_39 -0.0574593 -0.00707455 -1.07077e-06
  hidden angularVelocity_39 1.57743e-05 -1.13232e-05 -0.0471994
  hidden translation_40 0.0140737 -1.47652e-05 -0.000248021
  hidden rotation_40 -1.90536e-09 -1 1.33738e-07 -0.96
  hidden position_40_0 5.16065e-11
  hidden linearVelocity_40 -0.0580001 -0.00732418 -1.19144e-06
  hidden angularVelocity_40 1.57743e-05 -1.13232e-05 -0.0471994
  hidden translation_41 0.0142754 -2.75498e-06 -6.53359e-05
  hidden rotation_41 -5.73582e-09 -1 -3.55283e-10 -0.96
  hidden linearVelocity_41 -0.0585251 -0.0070319 -1.43701e-06
  hidden angularVelocity_41 1.57743e-05 -1.13232e-05 -0.0471994
  hidden translation_42 0.0495911 -1.28256e-07 -0.0264412
  hidden rotation_42 0.000290796 0.999999 -0.00165555 6.0419e-10
  hidden position_42_0 1.12587e-10
  hidden linearVelocity_42 -0.0584157 -0.00646756 -1.536e-06
  hidden angularVelocity_42 1.57743e-05 -1.13232e-05 -0.0471994
  hidden translation_43 0.0141937 6.93477e-08 0.000169281
  hidden rotation_43 -1.23082e-13 1 2.41565e-13 -0.96
  hidden linearVelocity_43 -0.0580505 -0.00694278 -1.2999e-06
  hidden angularVelocity_43 1.57743e-05 -1.13232e-05 -0.0471994
  hidden translation_44 0.000166096 -0.0505988 -0.0849077
  hidden rotation_44 0.437181 0.699203 0.565675 -5.08076e-05
  hidden position_44_0 8.40199e-06
  hidden linearVelocity_44 -0.067258 0.00341508 3.43455e-06
  hidden angularVelocity_44 -2.90617e-05 -8.47715e-06 -0.0474243
  hidden translation_45 4.00096e-05 -6.28542e-06 0.000298671
  hidden rotation_45 -0.0703007 0.997435 -0.0134953 -2.15062e-05
  hidden position_45_0 -1.1
  hidden linearVelocity_45 -0.0687749 0.0036416 4.12483e-06
  hidden angularVelocity_45 -2.96148e-05 -8.44332e-06 -0.0474243
  hidden translation_46 0.000177594 -6.02004e-06 0.000365952
  hidden rotation_46 -1.25553e-06 1 1.67421e-07 -1.1
  hidden position_46_0 1
  hidden linearVelocity_46 -0.0693454 0.000536542 4.82496e-06
  hidden angularVelocity_46 -2.96017e-05 -8.36001e-06 -0.0474242
  hidden translation_47 -0.00104912 1.1432e-06 -0.101593
  hidden rotation_47 4.02486e-07 1 1.27935e-06 1
  hidden position_47_0 6.74744e-09
  hidden linearVelocity_47 -0.0725646 -0.00216865 7.30717e-06
  hidden angularVelocity_47 -2.96014e-05 -8.36018e-06 -0.0474242
  hidden translation_48 0.000310048 1.47891e-06 -0.104531
  hidden rotation_48 -0.901971 0.420241 -0.0992291 1.62314e-07
  hidden position_48_0 -4.51271e-07
  hidden linearVelocity_48 -0.07485 -0.00241616 8.77521e-06
  hidden angularVelocity_48 -2.96013e-05 -8.3603e-06 -0.0474242
  hidden translation_49 0.00124276 1.65529e-06 -0.00107914
  hidden rotation_49 -0.969362 0.21177 -0.124462 1.25207e-07
  hidden linearVelocity_49 -0.0764988 -0.00399329 1.00632e-05
  hidden angularVelocity_49 -2.90935e-05 -8.26436e-06 -0.0474243
  hidden translation_50 0.0198264 -0.00699855 -0.0415073
  hidden rotation_50 2.35228e-07 -4.32328e-09 1 -3.14159
  hidden linearVelocity_50 -0.0769726 -0.00381463 1.03222e-05
  hidden angularVelocity_50 -2.90935e-05 -8.26436e-06 -0.0474243
  hidden translation_54 0.000243808 0.0505492 -0.084366
  hidden rotation_54 -0.397457 0.815632 -0.420444 -6.14232e-05
  hidden position_54_0 -8.59003e-06
  hidden linearVelocity_54 -0.0672365 0.00345569 3.38295e-06
  hidden angularVelocity_54 -2.9248e-05 -5.87187e-06 -0.047421
  hidden translation_55 5.11793e-05 -8.16094e-06 0.000274623
  hidden rotation_55 0.0293998 0.999567 0.00114427 -2.06431e-05
  hidden position_55_0 -1.1
  hidden linearVelocity_55 -0.0687559 0.00369383 4.03767e-06
  hidden angularVelocity_55 -2.92668e-05 -5.80765e-06 -0.047421
  hidden translation_56 0.000190433 -7.91254e-06 0.000341667
  hidden rotation_56 -6.19702e-07 1 4.87879e-07 -1.1
  hidden position_56_0 1
  hidden linearVelocity_56 -0.0693278 0.000590701 4.50995e-06
  hidden angularVelocity_56 -2.91908e-05 -5.73404e-06 -0.0474159
  hidden translation_57 -0.0010481 -3.15567e-06 -0.1016
  hidden rotation_57 -3.23449e-09 1 1.17622e-06 1
  hidden position_57_0 8.0066e-08
  hidden linearVelocity_57 -0.0725465 -0.00211433 6.8146e-06
  hidden angularVelocity_57 -2.91905e-05 -5.73359e-06 -0.0474159
  hidden translation_58 0.000308885 -2.17902e-06 -0.104531
  hidden rotation_58 0.655536 0.726553 -0.205897 2.2206e-07
  hidden position_58_0 3.09944e-07
  hidden linearVelocity_58 -0.0748312 -0.00236386 8.24926e-06
  hidden angularVelocity_58 -2.91905e-05 -5.73334e-06 -0.0474159
  hidden translation_59 0.0012416 -2.00265e-06 -0.00107903
  hidden rotation_59 0.660787 0.654673 -0.367101 1.26139e-07
  hidden linearVelocity_59 -0.0764801 -0.00393748 9.44069e-06
  hidden angularVelocity_59 -2.88386e-05 -5.66652e-06 -0.0474159
  hidden translation_60 0.0198288 0.00699841 -0.0414842
  hidden rotation_60 -1.11043e-07 -2.62095e-08 1 -3.14159
  hidden linearVelocity_60 -0.0769531 -0.00375483 9.70605e-06
  hidden angularVelocity_60 -2.88386e-05 -5.66652e-06 -0.0474159
  translation -0.0702072 0.774507 0.00215795
  rotation -0.998115 -0.0370557 0.0489132 1.57344
  controller "my_controller"
  leftHandSlot [
    DEF LeftConnector Connector {
      isLocked TRUE
      distanceTolerance 0.1
      axisTolerance 3.14
      rotationTolerance 3.14
      numberOfRotations 0
      snap FALSE
    }
  ]
  rightHandSlot [
    DEF RightConnector Connector {
      isLocked TRUE
      distanceTolerance 0.1
      axisTolerance 3.14159
      rotationTolerance 3.14
      numberOfRotations 0
      snap FALSE
    }
  ]
}
DirectionalLight {
  ambientIntensity 1
  direction -0.1 -0.5 -0.3
}
RectangleArena {
  floorSize 5 5
}
FloorLight {
  translation -2.00175 -8.88178e-16 1.89667
}
FloorLight {
  translation 2.00366 2.22044e-15 -2.13347
}
DEF Swing Robot {
  translation 0 2.2 0
  rotation 1 0 0 -1.5708
  children [
    DEF RArm Transform {
      translation 0 0.25 -0.06
      children [
        HingeJoint {
          jointParameters HingeJointParameters {
            position -0.174917
            axis 0 1 0
            anchor 0 1 0
            minStop -3.1416
            maxStop 3.1416
            dampingConstant 1
          }
          endPoint Solid {
            translation -0.0265429 0.00561293 -0.753723
            rotation -0.999996 -0.00199331 0.00206045 -1.5733
            children [
              Transform {
                translation 0 -0.75 0
                children [
                  DEF SeatShape Solid {
                    translation 0 0 0.25
                    children [
                      DEF Left_Hand_Bar Connector {
                        translation 0.2 0.25 -0.1
                        isLocked TRUE
                        distanceTolerance 0.1
                        axisTolerance 3.14
                        rotationTolerance 3.14
                        numberOfRotations 0
                        snap FALSE
                      }
                      DEF Right_Hand_Bar Connector {
                        translation 0.2 0.25 0.1
                        isLocked TRUE
                        distanceTolerance 0.1
                        rotationTolerance 3.14
                        numberOfRotations 0
                        snap FALSE
                      }
                      DEF C1 Connector {
                        translation 0 0 0.25
                        rotation 1 0 0 -1.5708
                        isLocked TRUE
                        autoLock TRUE
                        distanceTolerance 0.05
                        numberOfRotations 0
                        snap FALSE
                      }
                      DEF SeatCon Connector {
                        translation 0 0 0.25
                        rotation 1 0 0 -1.5708
                        autoLock TRUE
                        numberOfRotations 0
                      }
                      Shape {
                        appearance Appearance {
                          material Material {
                          }
                        }
                        geometry DEF SSeat Box {
                          size 0.1 0.01 0.5
                        }
                      }
                    ]
                    boundingObject USE SSeat
                    physics Physics {
                    }
                  }
                ]
              }
              DEF RVBar Shape {
                appearance Appearance {
                  material Material {
                  }
                }
                geometry Cylinder {
                  height 1.5
                  radius 0.05
                }
              }
            ]
            boundingObject USE RVBar
            physics Physics {
              centerOfMass [
                0 0 0
              ]
            }
            linearVelocity -0.0370183 0.00125823 3.27203e-07
            angularVelocity -4.10349e-07 -4.05599e-07 -0.0471994
          }
        }
      ]
    }
    DEF LArm Transform {
      translation 0 -0.25 -0.06
      children [
        HingeJoint {
          jointParameters HingeJointParameters {
            position -0.174516
            axis 0 1 0
            anchor 0 1 0
            minStop -3.1416
            maxStop 3.1416
            dampingConstant 1
          }
          endPoint Solid {
            translation -0.0267978 0.00214854 -0.753736
            rotation -0.999995 -0.00220744 0.00225411 -1.57089
            children [
              DEF C1 Connector {
                translation 0 -0.75 0
                rotation 1 0 0 1.5708
                isLocked TRUE
                autoLock TRUE
                distanceTolerance 0.05
                numberOfRotations 0
                snap FALSE
              }
              DEF SVBar2 Shape {
                appearance Appearance {
                  material Material {
                  }
                }
                geometry Cylinder {
                  height 1.5
                  radius 0.05
                }
              }
            ]
            boundingObject USE SVBar2
            physics Physics {
              centerOfMass [
                0 0 0
              ]
            }
            linearVelocity -0.0355759 0.00126449 3.15174e-07
            angularVelocity -4.28371e-07 -2.76514e-07 -0.047199
          }
        }
      ]
    }
    DEF SHBarShape Shape {
      appearance DEF SwingApp Appearance {
        material Material {
          diffuseColor 0.7 0.4 0.8
        }
        texture ImageTexture {
        }
      }
      geometry DEF SHBar Cylinder {
        height 0.5
        radius 0.05
      }
    }
  ]
  name "Swing"
  boundingObject USE SHBarShape
  selfCollision TRUE
}
