#VRML_SIM V8.3.2 utf8
WorldInfo {
  basicTimeStep 16
}
Viewpoint {
  orientation 0.741994 0.657543 0.130699 5.71656
  position -5.09145 7.83707 13.5648
}
Background {
  skyColor [
    0.4 0.7 1
  ]
}
Ceiling {
  translation 0 3 0
  size 5 5
}
Nao {
  hidden position_0_0 2.05432e-09
  hidden position2_0_0 5.77662e-08
  hidden position_0_1 1.26965e-06
  hidden position2_0_1 -5.70517e-08
  hidden position_0_2 1.27059e-06
  hidden position2_0_2 -2.99656e-08
  hidden position_0_3 1.21396e-06
  hidden position_0_4 1.89849e-06
  hidden linearVelocity_0 -3.04679 -0.733608 -0.000277684
  hidden angularVelocity_0 0.000198129 0.000155133 -2.35675
  hidden translation_12 -3.72602e-05 7.10994e-07 0.126857
  hidden rotation_12 0.0436017 0.998418 0.0355071 5.78567e-08
  hidden linearVelocity_12 -2.76567 -0.632568 -0.000247484
  hidden angularVelocity_12 0.00019813 0.000155134 -2.35675
  hidden translation_19 2.43002e-05 -0.0979996 0.100165
  hidden rotation_19 0.079953 0.994891 -0.0616416 1.27617e-06
  hidden position_19_0 -6.77788e-08
  hidden linearVelocity_19 -2.90185 -0.725279 -0.000265005
  hidden angularVelocity_19 0.000198205 0.000155152 -2.35675
  hidden translation_20 0.105183 -0.0149999 6.35656e-06
  hidden rotation_20 0.0293028 0.999562 -0.0040478 5.19683e-07
  hidden position_20_0 7.64108e-08
  hidden linearVelocity_20 -2.85343 -0.865335 -0.000270205
  hidden angularVelocity_20 0.000196465 0.000154443 -2.35675
  hidden translation_21 0.000154082 1.29018e-07 1.4359e-05
  hidden rotation_21 0.00423097 0.999951 -0.0089299 5.74852e-07
  hidden position_21_0 2.82916e-08
  hidden linearVelocity_21 -2.80623 -0.981259 -0.000273896
  hidden angularVelocity_21 0.000196725 0.000153783 -2.35675
  hidden translation_22 0.05614 1.70207e-07 2.5455e-05
  hidden rotation_22 -0.019848 0.999678 0.0157866 1.90871e-07
  hidden position_22_0 -3.4928e-11
  hidden position_22_1 -3.49353e-11
  hidden position_22_2 2.54422e-10
  hidden linearVelocity_22 -2.74586 -1.12179 -0.000278083
  hidden angularVelocity_22 0.000197362 0.000154043 -2.35675
  hidden translation_23 0.0691192 -0.013 -0.00502489
  hidden rotation_23 5.49674e-13 -1 3.94113e-13 -0.96
  hidden position_23_0 8.87903e-11
  hidden linearVelocity_23 -2.74201 -1.21678 -0.000283994
  hidden angularVelocity_23 0.000197362 0.000154043 -2.35675
  hidden translation_24 0.0140362 -6.64027e-08 -1.04976e-05
  hidden rotation_24 2.12624e-13 -1 2.58455e-13 -0.96
  hidden position_24_0 6.03887e-11
  hidden linearVelocity_24 -2.76669 -1.23277 -0.0002871
  hidden angularVelocity_24 0.000197362 0.000154043 -2.35675
  hidden translation_25 0.0140362 -7.57009e-08 -1.04786e-05
  hidden rotation_25 3.66645e-14 -1 7.32689e-14 -0.96
  hidden linearVelocity_25 -2.79394 -1.22172 -0.000288648
  hidden angularVelocity_25 0.000197362 0.000154043 -2.35675
  hidden translation_26 0.0691193 0.013 -0.00502472
  hidden rotation_26 5.48119e-13 -1 3.98711e-13 -0.96
  hidden position_26_0 8.87974e-11
  hidden linearVelocity_26 -2.74188 -1.21677 -0.000283982
  hidden angularVelocity_26 0.000197362 0.000154043 -2.35675
  hidden translation_27 0.0140362 -6.64027e-08 -1.04976e-05
  hidden rotation_27 2.13826e-13 -1 2.59116e-13 -0.96
  hidden position_27_0 6.03799e-11
  hidden linearVelocity_27 -2.76656 -1.23276 -0.000287088
  hidden angularVelocity_27 0.000197362 0.000154043 -2.35675
  hidden translation_28 0.0140362 -7.57009e-08 -1.04786e-05
  hidden rotation_28 3.87081e-14 -1 7.34492e-14 -0.96
  hidden linearVelocity_28 -2.79381 -1.22171 -0.000288636
  hidden angularVelocity_28 0.000197362 0.000154043 -2.35675
  hidden translation_29 0.0490729 -1.21465e-07 -0.0260796
  hidden rotation_29 0.000249864 0.999999 -0.00118344 2.54422e-10
  hidden position_29_0 2.43004e-11
  hidden linearVelocity_29 -2.79225 -1.19211 -0.000286563
  hidden angularVelocity_29 0.000197362 0.000154043 -2.35675
  hidden translation_30 0.0140325 5.82231e-08 1.9034e-05
  hidden rotation_30 -3.85729e-14 1 7.41404e-14 -0.96
  hidden linearVelocity_30 -2.77166 -1.2131 -0.000286224
  hidden angularVelocity_30 0.000197362 0.000154043 -2.35675
  hidden translation_31 3.96507e-05 0.0980004 0.100172
  hidden rotation_31 -0.0540074 0.998247 -0.0242047 1.27283e-06
  hidden position_31_0 3.40453e-07
  hidden linearVelocity_31 -2.90089 -0.725224 -0.000264922
  hidden angularVelocity_31 0.000198055 0.000155117 -2.35675
  hidden translation_32 0.105193 0.0150001 1.02165e-05
  hidden rotation_32 0.0368624 0.999318 -0.00194894 3.47643e-07
  hidden position_32_0 -3.78386e-07
  hidden linearVelocity_32 -2.85223 -0.865279 -0.000270103
  hidden angularVelocity_32 0.000199795 0.000155826 -2.35675
  hidden translation_33 0.000160961 1.29097e-07 1.72775e-05
  hidden rotation_33 -0.00207404 0.993855 -0.110672 3.86095e-07
  hidden position_33_0 1.02401e-07
  hidden linearVelocity_33 -2.805 -0.981213 -0.000273755
  hidden angularVelocity_33 0.000200582 0.000153894 -2.35675
  hidden translation_34 0.056145 1.70094e-07 2.7448e-05
  hidden rotation_34 0.0726184 0.997334 0.00720725 1.33669e-07
  hidden position_34_0 7.85913e-11
  hidden position_34_1 7.86091e-11
  hidden position_34_2 2.02284e-10
  hidden linearVelocity_34 -2.74465 -1.12176 -0.000277849
  hidden angularVelocity_34 0.00020126 0.000154169 -2.35675
  hidden translation_35 0.0691192 -0.013 -0.00502485
  hidden rotation_35 5.52747e-13 -1 3.94865e-13 -0.96
  hidden position_35_0 1.58332e-10
  hidden linearVelocity_35 -2.7408 -1.21674 -0.000283755
  hidden angularVelocity_35 0.00020126 0.000154169 -2.35675
  hidden translation_36 0.0140362 -6.6393e-08 -1.04795e-05
  hidden rotation_36 2.07034e-13 -1 2.57703e-13 -0.96
  hidden position_36_0 5.10758e-11
  hidden linearVelocity_36 -2.76548 -1.23273 -0.000286902
  hidden angularVelocity_36 0.00020126 0.000154169 -2.35675
  hidden translation_37 0.0140362 -7.56881e-08 -1.04718e-05
  hidden rotation_37 4.03911e-14 -1 7.48016e-14 -0.96
  hidden linearVelocity_37 -2.79273 -1.22169 -0.000288494
  hidden angularVelocity_37 0.00020126 0.000154169 -2.35675
  hidden translation_38 0.0691193 0.013 -0.00502469
  hidden rotation_38 5.48112e-13 -1 3.96037e-13 -0.96
  hidden position_38_0 1.58324e-10
  hidden linearVelocity_38 -2.74067 -1.21673 -0.000283743
  hidden angularVelocity_38 0.00020126 0.000154169 -2.35675
  hidden translation_39 0.0140362 -6.6393e-08 -1.04795e-05
  hidden rotation_39 2.13135e-13 -1 2.59416e-13 -0.96
  hidden position_39_0 5.10774e-11
  hidden linearVelocity_39 -2.76535 -1.23272 -0.00028689
  hidden angularVelocity_39 0.00020126 0.000154169 -2.35675
  hidden translation_40 0.0140362 -7.56881e-08 -1.04718e-05
  hidden rotation_40 3.8107e-14 -1 7.40202e-14 -0.96
  hidden linearVelocity_40 -2.7926 -1.22168 -0.000288482
  hidden angularVelocity_40 0.00020126 0.000154169 -2.35675
  hidden translation_41 0.0490729 -1.21426e-07 -0.0260796
  hidden rotation_41 0.000317627 0.999999 -0.00149135 2.02283e-10
  hidden position_41_0 4.12335e-11
  hidden linearVelocity_41 -2.79104 -1.19207 -0.000286406
  hidden angularVelocity_41 0.00020126 0.000154169 -2.35675
  hidden translation_42 0.0140325 5.82125e-08 1.90375e-05
  hidden rotation_42 -3.78516e-14 1 7.35093e-14 -0.96
  hidden linearVelocity_42 -2.77045 -1.21306 -0.000286034
  hidden angularVelocity_42 0.00020126 0.000154169 -2.35675
  hidden translation_43 1.86086e-05 -0.0500112 -0.0852695
  hidden rotation_43 -0.314338 0.8537 -0.415196 1.29844e-06
  hidden position_43_0 3.50045e-07
  hidden linearVelocity_43 -3.27422 -0.812436 -0.000296559
  hidden angularVelocity_43 0.000199365 0.000151523 -2.35675
  hidden translation_44 -1.90616e-05 -1.08036e-05 -5.80322e-05
  hidden rotation_44 -0.0219634 0.972293 -0.232731 1.40209e-06
  hidden position_44_0 -1.1
  hidden linearVelocity_44 -3.35069 -0.822641 -0.00029828
  hidden angularVelocity_44 0.000202951 0.000152607 -2.35675
  hidden translation_45 0.000152283 -1.05407e-05 2.42123e-06
  hidden rotation_45 4.85659e-07 1 -1.26566e-07 -1.1
  hidden position_45_0 1
  hidden linearVelocity_45 -3.33566 -0.978825 -0.000301718
  hidden angularVelocity_45 0.000202922 0.000152267 -2.35676
  hidden translation_46 -7.79834e-05 1.50791e-06 -0.10023
  hidden rotation_46 2.58006e-08 1 -2.66677e-08 1
  hidden position_46_0 -2.5734e-07
  hidden linearVelocity_46 -3.44894 -1.1495 -0.000322499
  hidden angularVelocity_46 0.000202962 0.000152269 -2.35676
  hidden translation_47 3.17952e-06 1.53849e-06 -0.103012
  hidden rotation_47 0.674026 0.738598 0.0126981 -2.61219e-07
  hidden position_47_0 -4.10022e-07
  hidden linearVelocity_47 -3.55154 -1.1908 -0.000333975
  hidden angularVelocity_47 0.000202986 0.000152271 -2.35676
  hidden translation_48 8.88182e-05 1.67649e-06 -7.27253e-05
  hidden rotation_48 0.541036 0.840895 0.0132395 -2.30317e-07
  hidden linearVelocity_48 -3.6074 -1.2853 -0.00034488
  hidden angularVelocity_48 0.000202665 0.000152091 -2.35676
  hidden translation_49 0.0199869 -0.00699824 -0.040989
  hidden rotation_49 2.32299e-07 -4.49824e-09 1 -3.14159
  hidden linearVelocity_49 -3.63126 -1.28306 -0.000346778
  hidden angularVelocity_49 0.000202665 0.000152091 -2.35676
  hidden translation_53 1.74587e-05 0.0499852 -0.0852693
  hidden rotation_53 -0.523186 0.848054 -0.084148 1.6462e-06
  hidden position_53_0 -7.05145e-07
  hidden linearVelocity_53 -3.27382 -0.812398 -0.000296494
  hidden angularVelocity_53 0.000198295 0.000154019 -2.35675
  hidden translation_54 -2.02655e-05 -1.44278e-05 -5.81674e-05
  hidden rotation_54 -0.426546 0.884124 -0.190745 1.88362e-06
  hidden position_54_0 -1.1
  hidden linearVelocity_54 -3.35018 -0.822589 -0.000298166
  hidden angularVelocity_54 0.000201414 0.00015496 -2.35676
  hidden translation_55 0.000151728 -1.41832e-05 1.19991e-06
  hidden rotation_55 8.37519e-07 1 5.26798e-08 -1.1
  hidden position_55_0 1
  hidden linearVelocity_55 -3.33513 -0.978771 -0.000301757
  hidden angularVelocity_55 0.000201258 0.000154612 -2.35676
  hidden translation_56 -7.86473e-05 -2.14929e-06 -0.100229
  hidden rotation_56 -6.06582e-08 1 -2.76165e-08 1
  hidden position_56_0 -1.84203e-07
  hidden linearVelocity_56 -3.44842 -1.14944 -0.000322625
  hidden angularVelocity_56 0.000201213 0.00015461 -2.35677
  hidden translation_57 1.94401e-06 -2.11885e-06 -0.103012
  hidden rotation_57 -0.834998 0.475388 0.2771 -2.10267e-07
  hidden position_57_0 3.67163e-07
  hidden linearVelocity_57 -3.55103 -1.19075 -0.000334068
  hidden angularVelocity_57 0.000201189 0.000154609 -2.35677
  hidden translation_58 8.75991e-05 -1.98078e-06 -7.26868e-05
  hidden rotation_58 -0.52699 0.782166 0.332412 -1.76047e-07
  hidden linearVelocity_58 -3.60686 -1.28524 -0.000345045
  hidden angularVelocity_58 0.000201506 0.000154786 -2.35677
  hidden translation_59 0.0199857 0.0069981 -0.0409889
  hidden rotation_59 2.35161e-07 4.52756e-09 1 -3.14159
  hidden linearVelocity_59 -3.63069 -1.28299 -0.000346926
  hidden angularVelocity_59 0.000201506 0.000154786 -2.35677
  translation 0.301126 0.799658 -0.00040641
  rotation 0.970526 0.170571 -0.170251 -1.59848
  controller "my_controller"
  bodySlot [
    Connector {
      translation 0 0 -0.12
      rotation 0 1 0 3.14159
      isLocked TRUE
      autoLock TRUE
      distanceTolerance 0.05
      numberOfRotations 0
      snap FALSE
    }
  ]
}
DirectionalLight {
  ambientIntensity 1
  direction -0.1 -0.5 -0.3
}
RectangleArena {
  floorSize 5 5
}
FloorLight {
  translation -2.00175 -8.88178e-16 1.89667
}
FloorLight {
  translation 2.00366 2.22044e-15 -2.13347
}
DEF Swing Robot {
  translation 0 2.2 0
  rotation 1 0 0 -1.5708
  children [
    DEF RArm Transform {
      translation 0 0.25 -0.06
      children [
        HingeJoint {
          jointParameters HingeJointParameters {
            position -0.441388
            axis 0 1 0
            anchor 0 1 0
            minStop -3.1416
            maxStop 3.1416
            dampingConstant 1
          }
          endPoint Solid {
            translation 0.174542 0.00131814 -0.740172
            rotation -0.983062 0.129468 -0.129716 -1.59002
            children [
              Transform {
                translation 0 -0.75 0
                children [
                  DEF SeatShape Solid {
                    translation 0 0 0.25
                    children [
                      DEF C1 Connector {
                        translation 0 0 0.25
                        rotation 1 0 0 -1.5708
                        isLocked TRUE
                        autoLock TRUE
                        distanceTolerance 0.05
                        numberOfRotations 0
                        snap FALSE
                      }
                      Connector {
                        rotation 1 0 0 -1.5708
                        isLocked TRUE
                        autoLock TRUE
                        distanceTolerance 0.05
                        numberOfRotations 0
                        snap FALSE
                      }
                      DEF SeatCon Connector {
                        translation 0 0 0.25
                        rotation 1 0 0 -1.5708
                        autoLock TRUE
                        numberOfRotations 0
                      }
                      Shape {
                        appearance Appearance {
                          material Material {
                          }
                        }
                        geometry DEF SSeat Box {
                          size 0.1 0.01 0.5
                        }
                      }
                    ]
                    boundingObject USE SSeat
                    physics Physics {
                    }
                  }
                ]
              }
              DEF RVBar Shape {
                appearance Appearance {
                  material Material {
                  }
                }
                geometry Cylinder {
                  height 1.5
                  radius 0.05
                }
              }
            ]
            boundingObject USE RVBar
            physics Physics {
              centerOfMass [
                0 0 0
              ]
            }
            linearVelocity -1.80168 -0.470182 -0.000166872
            angularVelocity 0.000173164 0.000166478 -2.3567
          }
        }
      ]
    }
    DEF LArm Transform {
      translation 0 -0.25 -0.06
      children [
        HingeJoint {
          jointParameters HingeJointParameters {
            position -0.441069
            axis 0 1 0
            anchor 0 1 0
            minStop -3.1416
            maxStop 3.1416
            dampingConstant 1
          }
          endPoint Solid {
            translation 0.173463 0.000104926 -0.736915
            rotation -0.983074 0.129524 -0.129574 -1.58823
            children [
              DEF C1 Connector {
                translation 0 -0.75 0
                rotation 1 0 0 1.5708
                isLocked TRUE
                autoLock TRUE
                distanceTolerance 0.05
                numberOfRotations 0
                snap FALSE
              }
              DEF SVBar2 Shape {
                appearance Appearance {
                  material Material {
                  }
                }
                geometry Cylinder {
                  height 1.5
                  radius 0.05
                }
              }
            ]
            boundingObject USE SVBar2
            physics Physics {
              centerOfMass [
                0 0 0
              ]
            }
            linearVelocity -1.72497 -0.447283 -0.000162494
            angularVelocity 0.000180605 0.000175734 -2.35667
          }
        }
      ]
    }
    DEF SHBarShape Shape {
      appearance DEF SwingApp Appearance {
        material Material {
          diffuseColor 0.7 0.4 0.8
        }
        texture ImageTexture {
        }
      }
      geometry DEF SHBar Cylinder {
        height 0.5
        radius 0.05
      }
    }
  ]
  name "Swing"
  boundingObject USE SHBarShape
  selfCollision TRUE
}
