#VRML_SIM V8.3.2 utf8
WorldInfo {
  basicTimeStep 16
}
Viewpoint {
  orientation 0.741994 0.657543 0.130699 5.71656
  position -5.09145 7.83707 13.5648
}
Background {
  skyColor [
    0.4 0.7 1
  ]
}
Ceiling {
  translation 0 3 0
  size 5 5
}
Nao {
  hidden position_0_0 2.07423e-09
  hidden position2_0_0 1.89006e-08
  hidden position_0_1 1.81697e-06
  hidden position2_0_1 -6.23789e-08
  hidden position_0_2 1.81805e-06
  hidden position2_0_2 -2.70837e-08
  hidden position_0_3 -5.85988e-06
  hidden position_0_4 -4.98488e-06
  hidden linearVelocity_0 -0.0303646 0.00434077 2.554e-06
  hidden angularVelocity_0 -1.38047e-05 -2.39132e-05 -0.0229999
  hidden translation_12 -3.78462e-05 7.00977e-07 0.126853
  hidden rotation_12 0.159646 0.981282 0.107696 1.92601e-08
  hidden linearVelocity_12 -0.027448 0.00424831 8.87447e-07
  hidden angularVelocity_12 -1.38047e-05 -2.39132e-05 -0.0229999
  hidden translation_19 2.38901e-05 -0.0979996 0.100161
  hidden rotation_19 0.07073 0.996431 -0.0460616 1.82348e-06
  hidden position_19_0 -2.04811e-07
  hidden linearVelocity_19 -0.0290209 0.00389702 2.20224e-06
  hidden angularVelocity_19 -1.38053e-05 -2.39133e-05 -0.0229999
  hidden translation_20 0.105183 -0.0149999 3.75575e-06
  hidden rotation_20 0.01688 0.99985 -0.00376013 6.56523e-07
  hidden position_20_0 -7.49644e-08
  hidden linearVelocity_20 -0.0290853 0.00245102 3.74124e-06
  hidden angularVelocity_20 -1.51815e-05 -2.39095e-05 -0.0229999
  hidden translation_21 0.000154198 1.24573e-07 1.22836e-05
  hidden rotation_21 0.00395919 0.999479 -0.0320404 7.25489e-07
  hidden position_21_0 8.04865e-08
  hidden linearVelocity_21 -0.0290737 0.00122838 5.03995e-06
  hidden angularVelocity_21 -1.51857e-05 -2.54189e-05 -0.0229999
  hidden translation_22 0.0561403 1.67231e-07 2.3999e-05
  hidden rotation_22 0.0166977 0.999781 0.0126011 2.42466e-07
  hidden position_22_0 -4.30273e-11
  hidden position_22_1 -4.30222e-11
  hidden position_22_2 3.29374e-10
  hidden linearVelocity_22 -0.0290306 -0.000265355 6.65959e-06
  hidden angularVelocity_22 -1.46854e-05 -2.54203e-05 -0.0229999
  hidden translation_23 0.0691195 -0.013 -0.00502498
  hidden rotation_23 8.03359e-13 -1 5.78391e-13 -0.96
  hidden position_23_0 1.21658e-10
  hidden linearVelocity_23 -0.0293376 -0.00114187 7.82341e-06
  hidden angularVelocity_23 -1.46854e-05 -2.54203e-05 -0.0229999
  hidden translation_24 0.0140363 -6.65901e-08 -1.05325e-05
  hidden rotation_24 3.10146e-13 -1 3.76683e-13 -0.96
  hidden position_24_0 7.86752e-11
  hidden linearVelocity_24 -0.0296192 -0.0011984 8.06683e-06
  hidden angularVelocity_24 -1.46854e-05 -2.54203e-05 -0.0229999
  hidden translation_25 0.0140363 -7.58939e-08 -1.05094e-05
  hidden rotation_25 5.40952e-14 -1 1.07199e-13 -0.96
  hidden linearVelocity_25 -0.0298271 -0.00100008 7.98178e-06
  hidden angularVelocity_25 -1.46854e-05 -2.54203e-05 -0.0229999
  hidden translation_26 0.0691196 0.013 -0.00502481
  hidden rotation_26 8.01544e-13 -1 5.82901e-13 -0.96
  hidden position_26_0 1.2166e-10
  hidden linearVelocity_26 -0.0293356 -0.00114266 7.82302e-06
  hidden angularVelocity_26 -1.46854e-05 -2.54203e-05 -0.0229999
  hidden translation_27 0.0140363 -6.65901e-08 -1.05325e-05
  hidden rotation_27 3.11227e-13 -1 3.78065e-13 -0.96
  hidden position_27_0 7.86681e-11
  hidden linearVelocity_27 -0.0296173 -0.00119919 8.06644e-06
  hidden angularVelocity_27 -1.46854e-05 -2.54203e-05 -0.0229999
  hidden translation_28 0.0140363 -7.58939e-08 -1.05094e-05
  hidden rotation_28 5.6259e-14 -1 1.07514e-13 -0.96
  hidden linearVelocity_28 -0.0298251 -0.00100087 7.98139e-06
  hidden angularVelocity_28 -1.46854e-05 -2.54203e-05 -0.0229999
  hidden translation_29 0.049073 -1.21816e-07 -0.0260798
  hidden rotation_29 0.000280932 0.999999 -0.00133907 3.29373e-10
  hidden position_29_0 3.36355e-11
  hidden linearVelocity_29 -0.0297049 -0.000737301 7.61346e-06
  hidden angularVelocity_29 -1.46854e-05 -2.54203e-05 -0.0229999
  hidden translation_30 0.0140326 5.83555e-08 1.90663e-05
  hidden rotation_30 -5.60393e-14 1 1.08427e-13 -0.96
  hidden linearVelocity_30 -0.0295933 -0.00100205 7.83365e-06
  hidden angularVelocity_30 -1.46854e-05 -2.54203e-05 -0.0229999
  hidden translation_31 3.92418e-05 0.0980004 0.100168
  hidden rotation_31 -0.0525381 0.998501 -0.0153376 1.82079e-06
  hidden position_31_0 4.77543e-07
  hidden linearVelocity_31 -0.0290071 0.00389128 2.19989e-06
  hidden angularVelocity_31 -1.38042e-05 -2.3913e-05 -0.0229999
  hidden translation_32 0.105193 0.0150001 7.61634e-06
  hidden rotation_32 0.035605 0.999364 -0.00192502 4.84732e-07
  hidden position_32_0 -5.29614e-07
  hidden linearVelocity_32 -0.0290683 0.0024438 3.73808e-06
  hidden angularVelocity_32 -1.24276e-05 -2.39168e-05 -0.0229999
  hidden translation_33 0.000161077 1.24653e-07 1.52022e-05
  hidden rotation_33 -0.00225067 0.993878 -0.110464 5.37323e-07
  hidden position_33_0 1.54186e-07
  hidden linearVelocity_33 -0.0290562 0.00122083 5.03934e-06
  hidden angularVelocity_33 -1.24317e-05 -2.54258e-05 -0.0229999
  hidden translation_34 0.0561453 1.67118e-07 2.59919e-05
  hidden rotation_34 0.0751691 0.997164 0.00373033 1.8545e-07
  hidden position_34_0 3.55733e-11
  hidden position_34_1 3.55955e-11
  hidden position_34_2 2.77237e-10
  hidden linearVelocity_34 -0.0290136 -0.000272804 6.66569e-06
  hidden angularVelocity_34 -1.18975e-05 -2.54273e-05 -0.0229999
  hidden translation_35 0.0691195 -0.013 -0.00502494
  hidden rotation_35 8.06056e-13 -1 5.79137e-13 -0.96
  hidden position_35_0 1.912e-10
  hidden linearVelocity_35 -0.0293204 -0.00114941 7.79308e-06
  hidden angularVelocity_35 -1.18975e-05 -2.54273e-05 -0.0229999
  hidden translation_36 0.0140363 -6.65804e-08 -1.05144e-05
  hidden rotation_36 3.04195e-13 -1 3.76983e-13 -0.96
  hidden position_36_0 6.93624e-11
  hidden linearVelocity_36 -0.0296021 -0.00120594 8.00241e-06
  hidden angularVelocity_36 -1.18975e-05 -2.54273e-05 -0.0229999
  hidden translation_37 0.0140363 -7.5881e-08 -1.05026e-05
  hidden rotation_37 5.86632e-14 -1 1.09062e-13 -0.96
  hidden linearVelocity_37 -0.02981 -0.00100762 7.892e-06
  hidden angularVelocity_37 -1.18975e-05 -2.54273e-05 -0.0229999
  hidden translation_38 0.0691196 0.013 -0.00502478
  hidden rotation_38 8.01124e-13 -1 5.80338e-13 -0.96
  hidden position_38_0 1.91184e-10
  hidden linearVelocity_38 -0.0293184 -0.00115012 7.79285e-06
  hidden angularVelocity_38 -1.18975e-05 -2.54273e-05 -0.0229999
  hidden translation_39 0.0140363 -6.65804e-08 -1.05144e-05
  hidden rotation_39 3.10747e-13 -1 3.78426e-13 -0.96
  hidden position_39_0 6.93633e-11
  hidden linearVelocity_39 -0.0296001 -0.00120666 8.00218e-06
  hidden angularVelocity_39 -1.18975e-05 -2.54273e-05 -0.0229999
  hidden translation_40 0.0140363 -7.5881e-08 -1.05026e-05
  hidden rotation_40 5.56579e-14 -1 1.08386e-13 -0.96
  hidden linearVelocity_40 -0.029808 -0.00100833 7.89177e-06
  hidden angularVelocity_40 -1.18975e-05 -2.54273e-05 -0.0229999
  hidden translation_41 0.049073 -1.21777e-07 -0.0260798
  hidden rotation_41 0.000335719 0.999999 -0.001593 2.77236e-10
  hidden position_41_0 5.0568e-11
  hidden linearVelocity_41 -0.0296877 -0.0007448 7.53823e-06
  hidden angularVelocity_41 -1.18975e-05 -2.54273e-05 -0.0229999
  hidden translation_42 0.0140326 5.83448e-08 1.90698e-05
  hidden rotation_42 -5.56416e-14 1 1.07808e-13 -0.96
  hidden linearVelocity_42 -0.0295762 -0.00100955 7.77217e-06
  hidden angularVelocity_42 -1.18975e-05 -2.54273e-05 -0.0229999
  hidden translation_43 0.000119605 -0.050014 -0.0852199
  hidden rotation_43 0.0919079 0.994921 -0.0410436 -5.95071e-06
  hidden position_43_0 8.23197e-06
  hidden linearVelocity_43 -0.0327526 0.00446469 2.7986e-06
  hidden angularVelocity_43 -1.39351e-05 -2.36787e-05 -0.0230001
  hidden translation_44 8.19682e-05 -1.36247e-05 -7.41535e-06
  hidden rotation_44 -0.0824697 0.994605 0.0629328 -6.53287e-06
  hidden position_44_0 -1.0315
  hidden linearVelocity_44 -0.0335217 0.00466876 1.58869e-06
  hidden angularVelocity_44 6.32106e-05 -2.38231e-05 -0.023
  hidden translation_45 0.000253729 -1.33587e-05 4.37819e-05
  hidden rotation_45 6.68207e-07 1 -1.41154e-07 -1.0315
  hidden position_45_0 1.49996
  hidden linearVelocity_45 -0.0339682 0.00341712 1.06438e-06
  hidden angularVelocity_45 6.07965e-05 -3.12365e-05 -0.0195824
  hidden translation_46 -0.000256483 5.43465e-07 -0.100258
  hidden rotation_46 2.07602e-08 1 -6.65493e-09 1.49996
  hidden position_46_0 -2.35163e-07
  hidden linearVelocity_46 -0.0353688 0.00305299 -2.74325e-06
  hidden angularVelocity_46 6.08984e-05 -3.024e-05 -0.0199789
  hidden translation_47 3.91981e-06 1.53225e-06 -0.103015
  hidden rotation_47 0.701917 0.71224 0.00512828 -2.41336e-07
  hidden position_47_0 -3.9445e-07
  hidden linearVelocity_47 -0.0361625 0.00355486 -5.91871e-06
  hidden angularVelocity_47 6.08979e-05 -3.02402e-05 -0.0199789
  hidden translation_48 8.94297e-05 1.67271e-06 -7.42798e-05
  hidden rotation_48 0.562299 0.82692 0.00491817 -2.15935e-07
  hidden linearVelocity_48 -0.0370908 0.00347043 -8.61492e-06
  hidden angularVelocity_48 6.11042e-05 -3.03457e-05 -0.0199789
  hidden translation_49 0.0199871 -0.00699824 -0.0409897
  hidden rotation_49 2.32355e-07 -4.49823e-09 1 -3.14159
  hidden linearVelocity_49 -0.037194 0.00364563 -9.19717e-06
  hidden angularVelocity_49 6.11041e-05 -3.03457e-05 -0.0199789
  hidden translation_53 0.000117275 0.0499824 -0.0852171
  hidden rotation_53 0.181222 0.954651 0.236219 -5.63686e-06
  hidden position_53_0 -8.66069e-06
  hidden linearVelocity_53 -0.0327375 0.00445587 2.46624e-07
  hidden angularVelocity_53 -1.33899e-05 -2.35042e-05 -0.0229997
  hidden translation_54 7.95834e-05 -1.72128e-05 -4.99341e-06
  hidden rotation_54 0.31011 0.948358 0.066694 -6.5327e-06
  hidden position_54_0 -1.03637
  hidden linearVelocity_54 -0.0334956 0.00465275 -2.72375e-06
  hidden angularVelocity_54 -9.37317e-05 -2.30535e-05 -0.0229998
  hidden translation_55 0.000251957 -1.69651e-05 4.58959e-05
  hidden rotation_55 1.06729e-06 1 1.4145e-08 -1.03637
  hidden position_55_0 1.49996
  hidden linearVelocity_55 -0.0339412 0.00336873 -2.59766e-06
  hidden angularVelocity_55 -9.5275e-05 -2.92299e-05 -0.020076
  hidden translation_56 -0.000247803 -3.09349e-06 -0.100256
  hidden rotation_56 -5.29328e-08 1 1.35683e-08 1.49996
  hidden position_56_0 -1.61726e-07
  hidden linearVelocity_56 -0.0353796 0.00298139 3.04424e-06
  hidden angularVelocity_56 -9.4805e-05 -2.85268e-05 -0.0204725
  hidden translation_57 2.67318e-06 -2.12504e-06 -0.103015
  hidden rotation_57 -0.861974 0.401969 0.308905 -1.95713e-07
  hidden position_57_0 3.82691e-07
  hidden linearVelocity_57 -0.0361958 0.00349173 6.12603e-06
  hidden angularVelocity_57 -9.48045e-05 -2.85266e-05 -0.0204725
  hidden translation_58 8.82059e-05 -1.98452e-06 -7.42456e-05
  hidden rotation_58 -0.562404 0.740866 0.367179 -1.65094e-07
  hidden linearVelocity_58 -0.037146 0.00340032 1.06521e-05
  hidden angularVelocity_58 -9.47391e-05 -2.85591e-05 -0.0204725
  hidden translation_59 0.0199859 0.0069981 -0.0409896
  hidden rotation_59 2.35217e-07 4.52753e-09 1 -3.14159
  hidden linearVelocity_59 -0.0372521 0.00357911 1.08973e-05
  hidden angularVelocity_59 -9.47391e-05 -2.85591e-05 -0.0204725
  translation -0.177245 0.777589 -0.000534658
  rotation 0.999997 -0.00126235 0.00192748 -1.56861
  controller "my_controller"
  bodySlot [
    Connector {
      translation 0 0 -0.12
      rotation 0 1 0 3.14159
      isLocked TRUE
      autoLock TRUE
      distanceTolerance 0.05
      rotationTolerance 3.14
      numberOfRotations 0
      snap FALSE
    }
  ]
}
DirectionalLight {
  ambientIntensity 1
  direction -0.1 -0.5 -0.3
}
RectangleArena {
  floorSize 5 5
}
FloorLight {
  translation -2.00175 -8.88178e-16 1.89667
}
FloorLight {
  translation 2.00366 2.22044e-15 -2.13347
}
DEF Swing Robot {
  translation 0 2.2 0
  rotation 1 0 0 -1.5708
  children [
    DEF RArm Transform {
      translation 0 0.25 -0.06
      children [
        HingeJoint {
          jointParameters HingeJointParameters {
            position -0.0907873
            axis 0 1 0
            anchor 0 1 0
            minStop -3.1416
            maxStop 3.1416
            dampingConstant 1
          }
          endPoint Solid {
            translation -0.0902966 0.00140285 -0.755316
            rotation -0.998064 -0.0439098 0.0440377 -1.57498
            children [
              Transform {
                translation 0 -0.75 0
                children [
                  DEF SeatShape Solid {
                    translation 0 0 0.25
                    children [
                      DEF C1 Connector {
                        translation 0 0 0.25
                        rotation 1 0 0 -1.5708
                        isLocked TRUE
                        autoLock TRUE
                        distanceTolerance 0.05
                        numberOfRotations 0
                        snap FALSE
                      }
                      Connector {
                        rotation 1 0 0 -1.5708
                        isLocked TRUE
                        autoLock TRUE
                        distanceTolerance 0.05
                        numberOfRotations 0
                        snap FALSE
                      }
                      DEF SeatCon Connector {
                        translation 0 0 0.25
                        rotation 1 0 0 -1.5708
                        autoLock TRUE
                        numberOfRotations 0
                      }
                      Shape {
                        appearance Appearance {
                          material Material {
                          }
                        }
                        geometry DEF SSeat Box {
                          size 0.1 0.01 0.5
                        }
                      }
                    ]
                    boundingObject USE SSeat
                    physics Physics {
                    }
                  }
                ]
              }
              DEF RVBar Shape {
                appearance Appearance {
                  material Material {
                  }
                }
                geometry Cylinder {
                  height 1.5
                  radius 0.05
                }
              }
            ]
            boundingObject USE RVBar
            physics Physics {
              centerOfMass [
                0 0 0
              ]
            }
            linearVelocity -0.0180318 0.00221498 2.0106e-06
            angularVelocity -3.13056e-06 -5.15263e-06 -0.0229449
          }
        }
      ]
    }
    DEF LArm Transform {
      translation 0 -0.25 -0.06
      children [
        HingeJoint {
          jointParameters HingeJointParameters {
            position -0.0904695
            axis 0 1 0
            anchor 0 1 0
            minStop -3.1416
            maxStop 3.1416
            dampingConstant 1
          }
          endPoint Solid {
            translation -0.0901923 0.000190859 -0.751909
            rotation -0.998047 -0.0441621 0.0441798 -1.57323
            children [
              DEF C1 Connector {
                translation 0 -0.75 0
                rotation 1 0 0 1.5708
                isLocked TRUE
                autoLock TRUE
                distanceTolerance 0.05
                numberOfRotations 0
                snap FALSE
              }
              DEF SVBar2 Shape {
                appearance Appearance {
                  material Material {
                  }
                }
                geometry Cylinder {
                  height 1.5
                  radius 0.05
                }
              }
            ]
            boundingObject USE SVBar2
            physics Physics {
              centerOfMass [
                0 0 0
              ]
            }
            linearVelocity -0.0172557 0.00214799 1.94734e-06
            angularVelocity -3.23405e-06 -5.06768e-06 -0.0229445
          }
        }
      ]
    }
    DEF SHBarShape Shape {
      appearance DEF SwingApp Appearance {
        material Material {
          diffuseColor 0.7 0.4 0.8
        }
        texture ImageTexture {
        }
      }
      geometry DEF SHBar Cylinder {
        height 0.5
        radius 0.05
      }
    }
  ]
  name "Swing"
  boundingObject USE SHBarShape
  selfCollision TRUE
}
