#VRML_SIM V8.3.2 utf8
WorldInfo {
  basicTimeStep 16
}
Viewpoint {
  orientation -0.30394 0.944549 -0.124285 5.51825
  position -10.3882 -3.4501 11.5
}
Background {
  skyColor [
    0.4 0.7 1
  ]
}
Ceiling {
  translation 0 3 0
  size 5 5
}
Nao {
  hidden position_0_0 1.8653e-09
  hidden position2_0_0 1.23473e-07
  hidden position_0_1 5.08268e-07
  hidden position2_0_1 -5.35424e-08
  hidden position_0_2 5.09104e-07
  hidden position2_0_2 -2.99863e-08
  hidden position_0_3 6.56018e-08
  hidden position_0_4 7.91166e-07
  hidden linearVelocity_0 0.300458 -0.0102154 -2.04159e-06
  hidden angularVelocity_0 1.42188e-06 -7.99072e-06 0.22661
  hidden linearVelocity_12 0.271871 -0.0123654 -1.93863e-06
  hidden angularVelocity_12 1.42182e-06 -7.99073e-06 0.22661
  hidden position_19_0 1.26308e-07
  hidden linearVelocity_19 0.286835 -0.00727894 -1.85289e-06
  hidden angularVelocity_19 1.42154e-06 -7.98993e-06 0.22661
  hidden position_20_0 -1.38597e-07
  hidden linearVelocity_20 0.28594 0.00691291 -1.34709e-06
  hidden angularVelocity_20 2.77598e-06 -7.85667e-06 0.22661
  hidden position_21_0 -4.47365e-08
  hidden linearVelocity_21 0.284542 0.018842 -8.78197e-07
  hidden angularVelocity_21 2.92286e-06 -9.34968e-06 0.22661
  hidden position_22_0 -3.93102e-11
  hidden position_22_1 -3.9308e-11
  hidden position_22_2 1.49823e-10
  hidden linearVelocity_22 0.282556 0.0333849 -2.54342e-07
  hidden angularVelocity_22 2.39711e-06 -9.40146e-06 0.22661
  hidden position_23_0 3.3789e-11
  hidden linearVelocity_23 0.284631 0.0422682 9.22389e-08
  hidden angularVelocity_23 2.39711e-06 -9.40146e-06 0.22661
  hidden position_24_0 3.44302e-11
  hidden linearVelocity_24 0.287323 0.0431153 9.89299e-08
  hidden angularVelocity_24 2.39711e-06 -9.40146e-06 0.22661
  hidden linearVelocity_25 0.28956 0.0413961 3.95878e-09
  hidden angularVelocity_25 2.39711e-06 -9.40146e-06 0.22661
  hidden position_26_0 3.37915e-11
  hidden linearVelocity_26 0.28462 0.0422712 9.24791e-08
  hidden angularVelocity_26 2.39711e-06 -9.40146e-06 0.22661
  hidden position_27_0 3.44265e-11
  hidden linearVelocity_27 0.287312 0.0431183 9.91701e-08
  hidden angularVelocity_27 2.39711e-06 -9.40146e-06 0.22661
  hidden linearVelocity_28 0.289549 0.0413991 4.19902e-09
  hidden angularVelocity_28 2.39711e-06 -9.40146e-06 0.22661
  hidden position_29_0 9.42566e-12
  hidden linearVelocity_29 0.288646 0.0387004 -9.82113e-08
  hidden angularVelocity_29 2.39711e-06 -9.40146e-06 0.22661
  hidden linearVelocity_30 0.28728 0.0411691 1.86498e-08
  hidden angularVelocity_30 2.39711e-06 -9.40146e-06 0.22661
  hidden position_31_0 1.46347e-07
  hidden linearVelocity_31 0.286754 -0.00725508 -1.85152e-06
  hidden angularVelocity_31 1.42225e-06 -7.99158e-06 0.22661
  hidden position_32_0 -1.62469e-07
  hidden linearVelocity_32 0.285839 0.00694373 -1.34524e-06
  hidden angularVelocity_32 2.77695e-06 -7.85832e-06 0.22661
  hidden position_33_0 2.85733e-08
  hidden linearVelocity_33 0.284438 0.0188749 -8.76131e-07
  hidden angularVelocity_33 2.92378e-06 -9.35113e-06 0.22661
  hidden position_34_0 1.1355e-10
  hidden position_34_1 1.13566e-10
  hidden position_34_2 9.77096e-11
  hidden linearVelocity_34 0.282455 0.0334181 -2.48936e-07
  hidden angularVelocity_34 3.4539e-06 -9.29901e-06 0.22661
  hidden position_35_0 1.03348e-10
  hidden linearVelocity_35 0.284529 0.0423016 8.38954e-08
  hidden angularVelocity_35 3.4539e-06 -9.29901e-06 0.22661
  hidden position_36_0 2.51237e-11
  hidden linearVelocity_36 0.287221 0.0431487 7.76462e-08
  hidden angularVelocity_36 3.4539e-06 -9.29901e-06 0.22661
  hidden linearVelocity_37 0.289459 0.0414295 -2.6966e-08
  hidden angularVelocity_37 3.4539e-06 -9.29901e-06 0.22661
  hidden position_38_0 1.03344e-10
  hidden linearVelocity_38 0.284518 0.0423046 8.41875e-08
  hidden angularVelocity_38 3.4539e-06 -9.29901e-06 0.22661
  hidden position_39_0 2.51257e-11
  hidden linearVelocity_39 0.28721 0.0431517 7.79383e-08
  hidden angularVelocity_39 3.4539e-06 -9.29901e-06 0.22661
  hidden linearVelocity_40 0.289448 0.0414325 -2.66739e-08
  hidden angularVelocity_40 3.4539e-06 -9.29901e-06 0.22661
  hidden position_41_0 2.6361e-11
  hidden linearVelocity_41 0.288545 0.0387338 -1.23632e-07
  hidden angularVelocity_41 3.4539e-06 -9.29901e-06 0.22661
  hidden linearVelocity_42 0.287178 0.0412025 -1.53587e-09
  hidden angularVelocity_42 3.4539e-06 -9.29901e-06 0.22661
  hidden position_43_0 1.51926e-06
  hidden linearVelocity_43 0.323508 -0.00874788 -2.05235e-06
  hidden angularVelocity_43 1.4177e-06 -7.99985e-06 0.22661
  hidden position_44_0 -1.1
  hidden linearVelocity_44 0.33084 -0.00976176 -2.06574e-06
  hidden angularVelocity_44 4.06296e-06 -7.74689e-06 0.22661
  hidden position_45_0 1
  hidden linearVelocity_45 0.333448 0.00506885 -1.52337e-06
  hidden angularVelocity_45 4.05877e-06 -7.75434e-06 0.22661
  hidden position_46_0 -3.21417e-07
  hidden linearVelocity_46 0.348293 0.0179523 -1.34817e-06
  hidden angularVelocity_46 4.05871e-06 -7.75326e-06 0.22661
  hidden position_47_0 -3.54836e-07
  hidden linearVelocity_47 0.358839 0.019145 -1.49592e-06
  hidden angularVelocity_47 4.05866e-06 -7.75257e-06 0.22661
  hidden linearVelocity_48 0.366424 0.0264541 -1.37093e-06
  hidden angularVelocity_48 3.73471e-06 -7.817e-06 0.22661
  hidden translation_49 0.0199997 -0.00699817 -0.0409604
  hidden rotation_49 2.32488e-07 -4.49798e-09 1 -3.14159
  hidden linearVelocity_49 0.368573 0.0256354 -1.43449e-06
  hidden angularVelocity_49 3.73471e-06 -7.817e-06 0.22661
  hidden position_53_0 4.99481e-07
  hidden linearVelocity_53 0.323475 -0.00873942 -2.14124e-06
  hidden angularVelocity_53 1.42317e-06 -7.99632e-06 0.22661
  hidden position_54_0 -1.1
  hidden linearVelocity_54 0.330797 -0.00975101 -2.21594e-06
  hidden angularVelocity_54 -1.4059e-06 -8.27524e-06 0.22661
  hidden position_55_0 1
  hidden linearVelocity_55 0.333403 0.00507993 -1.66542e-06
  hidden angularVelocity_55 -1.40529e-06 -8.2757e-06 0.22661
  hidden position_56_0 -2.48263e-07
  hidden linearVelocity_56 0.348249 0.0179631 -1.10246e-06
  hidden angularVelocity_56 -1.40523e-06 -8.27695e-06 0.22661
  hidden position_57_0 3.11927e-07
  hidden linearVelocity_57 0.358796 0.0191551 -9.93446e-07
  hidden angularVelocity_57 -1.40518e-06 -8.27765e-06 0.22661
  hidden linearVelocity_58 0.366379 0.0264646 -6.89818e-07
  hidden angularVelocity_58 -1.08223e-06 -8.21353e-06 0.22661
  hidden translation_59 0.0199985 0.00699817 -0.0409604
  hidden rotation_59 2.3535e-07 4.52782e-09 1 -3.14159
  hidden linearVelocity_59 0.368524 0.0256465 -7.09247e-07
  hidden angularVelocity_59 -1.08223e-06 -8.21353e-06 0.22661
  translation -0.033855 0.771156 -0.000105606
  rotation 0.997405 0.0511963 -0.050613 -1.57148
  controller "my_controller"
  bodySlot [
    Connector {
      translation 0 0 -0.12
      rotation 0 1 0 3.14159
      isLocked TRUE
      autoLock TRUE
      distanceTolerance 0.05
      numberOfRotations 0
      snap FALSE
    }
  ]
}
DirectionalLight {
  ambientIntensity 1
  direction -0.1 -0.5 -0.3
}
RectangleArena {
  floorSize 5 5
}
FloorLight {
  translation -2.00175 -8.88178e-16 1.89667
}
FloorLight {
  translation 2.00366 2.22044e-15 -2.13347
}
DEF Swing Robot {
  translation 0 2.2 0
  rotation 1 0 0 -1.5708
  children [
    DEF RArm Transform {
      translation 0 0.25 -0.06
      children [
        HingeJoint {
          jointParameters HingeJointParameters {
            position -0.196065
            axis 0 1 0
            anchor 0 1 0
            minStop -3.1416
            maxStop 3.1416
            dampingConstant 1
          }
          endPoint Solid {
            translation -0.0107874 0.0011351 -0.7576
            rotation -0.999928 0.00851552 -0.00849552 -1.57276
            children [
              Transform {
                translation 0 -0.75 0
                children [
                  DEF SeatShape Solid {
                    translation 0 0 0.25
                    children [
                      DEF C1 Connector {
                        translation 0 0 0.25
                        rotation 1 0 0 -1.5708
                        isLocked TRUE
                        autoLock TRUE
                        distanceTolerance 0.05
                        numberOfRotations 0
                      }
                      Connector {
                        rotation 1 0 0 -1.5708
                        isLocked TRUE
                        autoLock TRUE
                        distanceTolerance 0.05
                        numberOfRotations 0
                        snap FALSE
                      }
                      DEF SeatCon Connector {
                        translation 0 0 0.25
                        rotation 1 0 0 -1.5708
                        autoLock TRUE
                        numberOfRotations 0
                      }
                      Shape {
                        appearance Appearance {
                          material Material {
                          }
                        }
                        geometry DEF SSeat Box {
                          size 0.1 0.01 0.5
                        }
                      }
                    ]
                    boundingObject USE SSeat
                    physics Physics {
                    }
                  }
                ]
              }
              DEF RVBar Shape {
                appearance Appearance {
                  material Material {
                  }
                }
                geometry Cylinder {
                  height 1.5
                  radius 0.05
                }
              }
            ]
            boundingObject USE RVBar
            physics Physics {
              centerOfMass [
                0 0 0
              ]
            }
            linearVelocity 0.178577 -0.00269092 -1.08778e-06
            angularVelocity 1.36725e-06 -8.40591e-06 0.226608
          }
        }
      ]
    }
    DEF LArm Transform {
      translation 0 -0.25 -0.06
      children [
        HingeJoint {
          jointParameters HingeJointParameters {
            position -0.195748
            axis 0 1 0
            anchor 0 1 0
            minStop -3.1416
            maxStop 3.1416
            dampingConstant 1
          }
          endPoint Solid {
            translation -0.0110218 3.61969e-05 -0.754548
            rotation -0.99993 0.0083554 -0.00835204 -1.57114
            children [
              DEF C1 Connector {
                translation 0 -0.75 0
                rotation 1 0 0 1.5708
                isLocked TRUE
                autoLock TRUE
                distanceTolerance 0.03
                numberOfRotations 0
              }
              DEF SVBar2 Shape {
                appearance Appearance {
                  material Material {
                  }
                }
                geometry Cylinder {
                  height 1.5
                  radius 0.05
                }
              }
            ]
            boundingObject USE SVBar2
            physics Physics {
              centerOfMass [
                0 0 0
              ]
            }
            linearVelocity 0.170963 -0.00284584 -1.05937e-06
            angularVelocity 1.20955e-06 -4.72202e-06 0.2266
          }
        }
      ]
    }
    DEF SHBarShape Shape {
      appearance DEF SwingApp Appearance {
        material Material {
          diffuseColor 0.7 0.4 0.8
        }
        texture ImageTexture {
        }
      }
      geometry DEF SHBar Cylinder {
        height 0.5
        radius 0.05
      }
    }
  ]
  name "Swing"
  boundingObject USE SHBarShape
  selfCollision TRUE
}
