#VRML_SIM V8.3.2 utf8
WorldInfo {
  basicTimeStep 16
}
Viewpoint {
  orientation 0.126897 -0.990778 -0.0475075 5.72552
  position 9.8938 2.35342 16.0127
}
Background {
  skyColor [
    0.4 0.7 1
  ]
}
Ceiling {
  translation 0 3 0
  size 5 5
}
Nao {
  hidden position_0_0 2.09329e-09
  hidden position2_0_0 -6.5737e-08
  hidden position_0_1 0.13454
  hidden position2_0_1 -8.08927e-07
  hidden position_0_2 0.134519
  hidden position2_0_2 -8.04369e-07
  hidden position_0_3 -1.97e-05
  hidden position_0_4 -1.90361e-05
  hidden linearVelocity_0 0.155543 -0.0151564 3.51866e-05
  hidden angularVelocity_0 -5.88131e-05 -8.13709e-05 0.117519
  hidden translation_12 -3.89327e-05 6.80941e-07 0.126845
  hidden rotation_12 -0.0616582 0.997592 -0.0317664 -6.58967e-08
  hidden linearVelocity_12 0.140633 -0.0153144 2.7619e-05
  hidden angularVelocity_12 -5.88129e-05 -8.13711e-05 0.117519
  hidden translation_19 0.000405645 -0.0979996 0.100205
  hidden rotation_19 -1.50002e-06 1 -4.64619e-06 0.13454
  hidden position_19_0 -4.5629e-07
  hidden linearVelocity_19 0.146418 0.0119089 8.96795e-05
  hidden angularVelocity_19 -0.00107604 -0.00379199 1.71915
  hidden translation_20 0.106683 -0.0149999 0.000148695
  hidden rotation_20 -0.0141373 0.999895 -0.00327046 9.06889e-07
  hidden position_20_0 3.32759e-07
  hidden linearVelocity_20 0.157299 0.124129 0.000344398
  hidden angularVelocity_20 -0.00107672 -0.00379191 1.71915
  hidden translation_21 0.00141213 1.1585e-07 0.000201681
  hidden rotation_21 0.00247474 0.999951 0.00962492 9.92273e-07
  hidden position_21_0 1.79511e-07
  hidden linearVelocity_21 0.161439 0.21925 0.000557101
  hidden angularVelocity_21 -0.00107682 -0.00379269 1.71915
  hidden translation_22 0.0576705 1.62249e-07 0.000285978
  hidden rotation_22 0.00585657 0.999982 0.00113646 3.41753e-07
  hidden position_22_0 2.76629e-10
  hidden position_22_1 2.76619e-10
  hidden position_22_2 5.00778e-10
  hidden linearVelocity_22 0.164297 0.335556 0.000815802
  hidden angularVelocity_22 -0.00107658 -0.00379271 1.71915
  hidden translation_23 0.0700648 -0.013 -0.00520988
  hidden rotation_23 1.30415e-12 -1 9.74847e-13 -0.96
  hidden position_23_0 3.50341e-10
  hidden linearVelocity_23 0.191724 0.402461 0.000980985
  hidden angularVelocity_23 -0.00107658 -0.00379271 1.71915
  hidden translation_24 0.0143235 -7.44382e-08 -9.00594e-05
  hidden rotation_24 5.0567e-13 -1 6.22515e-13 -0.96
  hidden position_24_0 1.25165e-10
  hidden linearVelocity_24 0.213857 0.405687 0.00100216
  hidden angularVelocity_24 -0.00107658 -0.00379271 1.71915
  hidden translation_25 0.0143234 -8.17732e-08 -9.00336e-05
  hidden rotation_25 9.05192e-14 -1 1.80032e-13 -0.96
  hidden linearVelocity_25 0.229193 0.389406 0.000975936
  hidden angularVelocity_25 -0.00107658 -0.00379271 1.71915
  hidden translation_26 0.0700649 0.013 -0.00520968
  hidden rotation_26 1.30298e-12 -1 9.78995e-13 -0.96
  hidden position_26_0 3.50354e-10
  hidden linearVelocity_26 0.191719 0.402462 0.000980983
  hidden angularVelocity_26 -0.00107658 -0.00379271 1.71915
  hidden translation_27 0.0143235 -7.44382e-08 -9.00594e-05
  hidden rotation_27 5.06691e-13 -1 6.21914e-13 -0.96
  hidden position_27_0 1.25157e-10
  hidden linearVelocity_27 0.213851 0.405688 0.00100216
  hidden angularVelocity_27 -0.00107658 -0.00379271 1.71915
  hidden translation_28 0.0143234 -8.17732e-08 -9.00336e-05
  hidden rotation_28 9.07597e-14 -1 1.80678e-13 -0.96
  hidden linearVelocity_28 0.229188 0.389407 0.000975934
  hidden angularVelocity_28 -0.00107658 -0.00379271 1.71915
  hidden translation_29 0.0496569 -1.40438e-07 -0.0267024
  hidden rotation_29 0.000286143 0.999999 -0.00146524 5.00778e-10
  hidden position_29_0 9.16162e-11
  hidden linearVelocity_29 0.218672 0.36945 0.000925179
  hidden angularVelocity_29 -0.00107658 -0.00379271 1.71915
  hidden translation_30 0.014288 6.15546e-08 0.000172598
  hidden rotation_30 -9.30437e-14 1 1.8067e-13 -0.96
  hidden linearVelocity_30 0.211098 0.390495 0.000966854
  hidden angularVelocity_30 -0.00107658 -0.00379271 1.71915
  hidden translation_31 0.000422671 0.0980004 0.100209
  hidden rotation_31 -3.96595e-06 1 -4.95414e-06 0.134519
  hidden position_31_0 9.4925e-08
  hidden linearVelocity_31 0.146373 0.0119372 8.97103e-05
  hidden angularVelocity_31 -0.00107577 -0.00379121 1.71891
  hidden translation_32 0.106694 0.0150001 0.000152754
  hidden rotation_32 0.00257287 0.999993 -0.00287371 7.34924e-07
  hidden position_32_0 -1.22004e-07
  hidden linearVelocity_32 0.157236 0.124162 0.000344413
  hidden angularVelocity_32 -0.00107509 -0.0037913 1.71891
  hidden translation_33 0.00141904 1.16012e-07 0.000204733
  hidden rotation_33 -0.00299731 0.999392 -0.0347399 8.01694e-07
  hidden position_33_0 8.38121e-08
  hidden linearVelocity_33 0.161368 0.219283 0.000557097
  hidden angularVelocity_33 -0.00107519 -0.00379208 1.71891
  hidden translation_34 0.0576755 1.62291e-07 0.000288075
  hidden rotation_34 0.0462505 0.998845 0.0129855 2.84609e-07
  hidden position_34_0 3.55251e-10
  hidden position_34_1 3.55257e-10
  hidden position_34_2 4.48645e-10
  hidden linearVelocity_34 0.16422 0.335582 0.000815765
  hidden angularVelocity_34 -0.00107543 -0.00379206 1.71891
  hidden translation_35 0.0700648 -0.013 -0.00520977
  hidden rotation_35 1.3063e-12 -1 9.74201e-13 -0.96
  hidden position_35_0 4.19901e-10
  hidden linearVelocity_35 0.191641 0.402479 0.000980903
  hidden angularVelocity_35 -0.00107543 -0.00379206 1.71891
  hidden translation_36 0.0143234 -7.43772e-08 -9.00206e-05
  hidden rotation_36 5.0014e-13 -1 6.21854e-13 -0.96
  hidden position_36_0 1.15853e-10
  hidden linearVelocity_36 0.213771 0.405705 0.00100206
  hidden angularVelocity_36 -0.00107543 -0.00379206 1.71891
  hidden translation_37 0.0143234 -8.17477e-08 -9.00066e-05
  hidden rotation_37 9.31639e-14 -1 1.80963e-13 -0.96
  hidden linearVelocity_37 0.229105 0.389427 0.000975837
  hidden angularVelocity_37 -0.00107543 -0.00379206 1.71891
  hidden translation_38 0.0700649 0.013 -0.0052096
  hidden rotation_38 1.30109e-12 -1 9.74892e-13 -0.96
  hidden position_38_0 4.19875e-10
  hidden linearVelocity_38 0.191636 0.40248 0.000980901
  hidden angularVelocity_38 -0.00107543 -0.00379206 1.71891
  hidden translation_39 0.0143234 -7.43772e-08 -9.00206e-05
  hidden rotation_39 5.0621e-13 -1 6.24859e-13 -0.96
  hidden position_39_0 1.15858e-10
  hidden linearVelocity_39 0.213766 0.405706 0.00100206
  hidden angularVelocity_39 -0.00107543 -0.00379206 1.71891
  hidden translation_40 0.0143234 -8.17477e-08 -9.00066e-05
  hidden rotation_40 9.10001e-14 -1 1.79942e-13 -0.96
  hidden linearVelocity_40 0.2291 0.389427 0.000975835
  hidden angularVelocity_40 -0.00107543 -0.00379206 1.71891
  hidden translation_41 0.0496569 -1.4024e-07 -0.0267024
  hidden rotation_41 0.000324294 0.999999 -0.0016358 4.48644e-10
  hidden position_41_0 1.08556e-10
  hidden linearVelocity_41 0.218587 0.369473 0.000925095
  hidden angularVelocity_41 -0.00107543 -0.00379206 1.71891
  hidden translation_42 0.0142878 6.15537e-08 0.000172599
  hidden rotation_42 -9.13006e-14 1 1.79664e-13 -0.96
  hidden linearVelocity_42 0.211013 0.390515 0.000966765
  hidden angularVelocity_42 -0.00107543 -0.00379206 1.71891
  hidden translation_43 6.83107e-05 -0.0500109 -0.0849461
  hidden rotation_43 -0.0277222 0.989852 -0.139375 -1.96878e-05
  hidden position_43_0 -7.51526e-06
  hidden linearVelocity_43 0.167387 -0.0150785 3.67778e-05
  hidden angularVelocity_43 -5.87008e-05 -8.05601e-05 0.117518
  hidden translation_44 3.06714e-05 -1.05021e-05 0.000269334
  hidden rotation_44 0.0207081 0.999783 0.00232064 -2.22069e-05
  hidden position_44_0 -1.03871
  hidden linearVelocity_44 0.17099 -0.0157632 3.40971e-05
  hidden angularVelocity_44 -0.000136473 -8.31025e-05 0.117518
  hidden translation_45 0.00020698 -1.02315e-05 0.000323496
  hidden rotation_45 -4.82447e-07 1 1.10985e-07 -1.03871
  hidden position_45_0 0.343206
  hidden linearVelocity_45 0.173553 -0.0071784 4.02379e-05
  hidden angularVelocity_45 -0.000150151 -0.000133688 0.139411
  hidden translation_46 -0.00034467 1.08138e-06 -0.102596
  hidden rotation_46 -2.10208e-07 1 3.29996e-06 0.343206
  hidden position_46_0 -8.25809e-08
  hidden linearVelocity_46 0.327138 0.161416 0.00051662
  hidden angularVelocity_46 -0.00272348 -0.00961036 4.22488
  hidden translation_47 -3.69932e-05 1.47848e-06 -0.105247
  hidden rotation_47 0.98941 0.13672 0.048739 -1.50582e-07
  hidden position_47_0 -4.77222e-07
  hidden linearVelocity_47 0.494413 0.28701 0.000910806
  hidden angularVelocity_47 -0.00272353 -0.00961037 4.22488
  hidden translation_48 0.00140257 1.65334e-06 -0.00185415
  hidden rotation_48 0.919718 0.388748 0.0547074 -1.35243e-07
  hidden linearVelocity_48 0.550273 0.486908 0.00140202
  hidden angularVelocity_48 -0.00272312 -0.00961002 4.22488
  hidden translation_49 0.0197579 -0.00699825 -0.0414158
  hidden rotation_49 2.31586e-07 -4.49822e-09 1 -3.14159
  hidden linearVelocity_49 0.594929 0.494462 0.00144812
  hidden angularVelocity_49 -0.00272312 -0.00961002 4.22488
  hidden translation_53 7.72134e-05 0.0499855 -0.0849517
  hidden rotation_53 -0.000748135 0.99004 0.140786 -1.95136e-05
  hidden position_53_0 -8.58292e-06
  hidden linearVelocity_53 0.167377 -0.0150808 3.67803e-05
  hidden angularVelocity_53 -5.85368e-05 -8.08471e-05 0.117519
  hidden translation_54 3.95197e-05 -1.40972e-05 0.000263297
  hidden rotation_54 0.0618809 0.998077 0.00361984 -2.19417e-05
  hidden position_54_0 -1.04053
  hidden linearVelocity_54 0.17098 -0.0157688 3.40976e-05
  hidden angularVelocity_54 -0.000136773 -8.35871e-05 0.117519
  hidden translation_55 0.000216232 -1.38452e-05 0.000316683
  hidden rotation_55 -1.23861e-08 1 2.29833e-07 -1.04053
  hidden position_55_0 0.343205
  hidden linearVelocity_55 0.173506 -0.00723772 4.01317e-05
  hidden angularVelocity_55 -0.000149664 -0.000131601 0.138239
  hidden translation_56 -0.000344987 -2.57874e-06 -0.102595
  hidden rotation_56 -6.33403e-07 1 3.32266e-06 0.343205
  hidden position_56_0 -9.25128e-09
  hidden linearVelocity_56 0.326715 0.161532 0.000517339
  hidden angularVelocity_56 -0.002747 -0.00960179 4.2237
  hidden translation_57 -3.77802e-05 -2.1783e-06 -0.105247
  hidden rotation_57 0.852259 0.417724 -0.3149 1.73534e-07
  hidden position_57_0 2.96969e-07
  hidden linearVelocity_57 0.493714 0.287388 0.000912728
  hidden angularVelocity_57 -0.00274695 -0.00960178 4.2237
  hidden translation_58 0.00140146 -2.00379e-06 -0.00185348
  hidden rotation_58 0.826021 0.0364455 -0.562461 9.72926e-08
  hidden linearVelocity_58 0.549196 0.487323 0.00140386
  hidden angularVelocity_58 -0.00274737 -0.00960213 4.2237
  hidden translation_59 0.0197569 0.00699809 -0.0414156
  hidden rotation_59 2.34448e-07 4.52758e-09 1 -3.14159
  hidden linearVelocity_59 0.593826 0.494951 0.00145036
  hidden angularVelocity_59 -0.00274737 -0.00960213 4.2237
  translation -0.123062 0.771619 -0.000779688
  rotation 0.999665 0.0186413 -0.017969 -1.56883
  controller "my_controller"
  bodySlot [
    Connector {
      translation 0 0 -0.12
      rotation 0 1 0 3.14159
      isLocked TRUE
      autoLock TRUE
      distanceTolerance 0.05
      axisTolerance 3
      rotationTolerance 3
      numberOfRotations 0
      snap FALSE
    }
  ]
}
DirectionalLight {
  ambientIntensity 1
  direction -0.1 -0.5 -0.3
}
RectangleArena {
  floorSize 5 5
}
FloorLight {
  translation -2.00175 -8.88178e-16 1.89667
}
FloorLight {
  translation 2.00366 2.22044e-15 -2.13347
}
DEF Swing Robot {
  translation 0 2.2 0
  rotation 1 0 0 -1.5708
  children [
    DEF RArm Transform {
      translation 0 0.25 -0.06
      children [
        HingeJoint {
          jointParameters HingeJointParameters {
            position -0.130632
            axis 0 1 0
            anchor 0 1 0
            minStop -3.1416
            maxStop 3.1416
            dampingConstant 1
          }
          endPoint Solid {
            translation -0.0601907 0.00157284 -0.758762
            rotation -0.999418 -0.0240732 0.0241737 -1.57384
            children [
              Transform {
                translation 0 -0.75 0
                children [
                  DEF SeatShape Solid {
                    translation 0 0 0.25
                    children [
                      DEF C1 Connector {
                        translation 0 0 0.25
                        rotation 1 0 0 -1.5708
                        isLocked TRUE
                        autoLock TRUE
                        distanceTolerance 0.05
                        numberOfRotations 0
                        snap FALSE
                      }
                      Connector {
                        rotation 1 0 0 -1.5708
                        isLocked TRUE
                        autoLock TRUE
                        distanceTolerance 0.05
                        axisTolerance 3
                        rotationTolerance 3
                        numberOfRotations 0
                        snap FALSE
                      }
                      DEF SeatCon Connector {
                        translation 0 0 0.25
                        rotation 1 0 0 -1.5708
                        autoLock TRUE
                        numberOfRotations 0
                      }
                      Shape {
                        appearance Appearance {
                          material Material {
                          }
                        }
                        geometry DEF SSeat Box {
                          size 0.1 0.01 0.5
                        }
                      }
                    ]
                    boundingObject USE SSeat
                    physics Physics {
                    }
                  }
                  HingeJoint {
                    jointParameters HingeJointParameters {
                    }
                  }
                ]
              }
              DEF RVBar Shape {
                appearance Appearance {
                  material Material {
                  }
                }
                geometry Cylinder {
                  height 1.5
                  radius 0.05
                }
              }
            ]
            boundingObject USE RVBar
            physics Physics {
              centerOfMass [
                0 0 0
              ]
            }
            linearVelocity 0.0928745 -0.00735399 1.79852e-05
            angularVelocity -2.42814e-05 -1.23911e-05 0.117716
          }
        }
      ]
    }
    DEF LArm Transform {
      translation 0 -0.25 -0.06
      children [
        HingeJoint {
          jointParameters HingeJointParameters {
            position -0.130314
            axis 0 1 0
            anchor 0 1 0
            minStop -3.1416
            maxStop 3.1416
            dampingConstant 1
          }
          endPoint Solid {
            translation -0.0602311 0.000363269 -0.7554
            rotation -0.999409 -0.0242921 0.0243177 -1.57209
            children [
              DEF C1 Connector {
                translation 0 -0.75 0
                rotation 1 0 0 1.5708
                isLocked TRUE
                autoLock TRUE
                distanceTolerance 0.05
                numberOfRotations 0
                snap FALSE
              }
              DEF SVBar2 Shape {
                appearance Appearance {
                  material Material {
                  }
                }
                geometry Cylinder {
                  height 1.5
                  radius 0.05
                }
              }
            ]
            boundingObject USE SVBar2
            physics Physics {
              centerOfMass [
                0 0 0
              ]
            }
            linearVelocity 0.0888754 -0.00718594 1.65867e-05
            angularVelocity -2.21999e-05 -1.32528e-05 0.117707
          }
        }
      ]
    }
    DEF SHBarShape Shape {
      appearance DEF SwingApp Appearance {
        material Material {
          diffuseColor 0.7 0.4 0.8
        }
        texture ImageTexture {
        }
      }
      geometry DEF SHBar Cylinder {
        height 0.5
        radius 0.05
      }
    }
  ]
  name "Swing"
  boundingObject USE SHBarShape
  selfCollision TRUE
}
