#VRML_SIM V8.2.1 utf8
WorldInfo {
  info [
    "Aldebaran's Nao H25 V5.0"
    "Author: Yvan Bourquin - www.cyberbotics.com"
    "Date: 06 Feb 2012"
  ]
  title "Aldebaran Nao H25 V5.0"
  basicTimeStep 20
  FPS 20
  contactProperties [
    ContactProperties {
      material1 "NAO foot material"
      coulombFriction [
        7
      ]
      bounce 0.3
      bounceVelocity 0.003
    }
  ]
}
Viewpoint {
  orientation -0.00579008 -0.999371 -0.0349923 2.81383
  position -1.24383 0.885325 -2.43428
}
TexturedBackground {
}
TexturedBackgroundLight {
}
PointLight {
  ambientIntensity 1
  intensity 0.6
  location 2 0.9 0
}
Floor {
  size 25 25
  tileSize 0.8 0.8
  texture [
    "textures/checkered_marble.png"
    "textures/checkered_marble.jpg"
  ]
}
Nao {
  translation 0.103424 0.290107 2.42978e-12
  rotation -0.377964 -0.654654 -0.654654 3.86433
  controller "naoqisim"
  controllerArgs "9559"
  synchronization FALSE
}
DEF Swing Robot {
  translation 0 2 0
  children [
    DEF RArm Transform {
      translation 0 0 -0.25
      children [
        HingeJoint {
          jointParameters HingeJointParameters {
            axis 0 0 1
            minStop -3
            maxStop 3
          }
          endPoint Solid {
            translation 0 -0.755 0
            rotation 0 0 1 0
            children [
              Transform {
                translation 0 -0.755 0
                children [
                  HingeJoint {
                    jointParameters HingeJointParameters {
                      axis 0 0 1
                      minStop -3
                      maxStop 3
                    }
                    endPoint Solid {
                      translation 0 -0.06 0
                      rotation 0 0 1 0
                      children [
                        Transform {
                          translation 0 -0.06 0
                          children [
                            HingeJoint {
                              jointParameters HingeJointParameters {
                                axis 0 0 1
                                minStop -3
                                maxStop 3
                              }
                              endPoint Solid {
                                translation 0 -0.0925 0
                                rotation 0 0 1 0
                                children [
                                  Solid {
                                    translation 0 -0.0925 0.25
                                    children [
                                      Solid {
                                        translation -0.04 0.06 0
                                        children [
                                          Shape {
                                            appearance Appearance {
                                              material Material {
                                              }
                                            }
                                            geometry DEF Bar Box {
                                              size 0.01 0.01 0.5
                                            }
                                          }
                                        ]
                                        boundingObject USE Bar
                                        physics Physics {
                                          density -1
                                          mass 1
                                        }
                                      }
                                      Connector {
                                        translation 0 0 0.25
                                        rotation 1 0 0 -1.5708
                                        name "Seat-Arm"
                                        locked TRUE
                                        isLocked TRUE
                                        autoLock TRUE
                                        snap FALSE
                                      }
                                      Shape {
                                        appearance Appearance {
                                          material Material {
                                          }
                                        }
                                        geometry DEF Seat_Shape Box {
                                          size 0.1 0.01 0.5
                                        }
                                      }
                                    ]
                                    boundingObject USE Seat_Shape
                                    physics Physics {
                                      density -1
                                      mass 1.6
                                    }
                                  }
                                  Shape {
                                    appearance Appearance {
                                      material Material {
                                      }
                                    }
                                    geometry DEF Side_Arm_3 Box {
                                      size 0.01 0.185 0.01
                                    }
                                  }
                                ]
                                boundingObject USE Side_Arm_3
                                physics DEF Side_Arm_3_Phy Physics {
                                  density -1
                                  mass 0.2
                                }
                              }
                            }
                          ]
                        }
                        Shape {
                          appearance Appearance {
                            material Material {
                            }
                          }
                          geometry DEF Side_Arm_2 Box {
                            size 0.01 0.12 0.01
                          }
                        }
                      ]
                      boundingObject USE Side_Arm_2
                      physics DEF Side_Arm_2_Phy Physics {
                        density -1
                        mass 0.112
                      }
                    }
                  }
                ]
              }
              Shape {
                appearance Appearance {
                  material Material {
                  }
                }
                geometry DEF Side_Arm_1 Box {
                  size 0.01 1.51 0.01
                }
              }
            ]
            name "RightArm"
            boundingObject USE Side_Arm_1
            physics DEF Side_Arm_1_Phy Physics {
              density -1
              mass 1.231
            }
          }
        }
      ]
    }
    DEF LArm Transform {
      translation 0 0 0.25
      children [
        HingeJoint {
          jointParameters HingeJointParameters {
            axis 0 0 1
            anchor 0 0 1
            minStop -3
            maxStop 3
          }
          endPoint Solid {
            translation 0 -0.755 0
            rotation 0 0 1 0
            children [
              Transform {
                translation 0 -0.755 0
                children [
                  HingeJoint {
                    jointParameters HingeJointParameters {
                      axis 0 0 1
                      minStop -3
                      maxStop 3
                    }
                    endPoint Solid {
                      translation 0 -0.06 0
                      rotation 0 0 1 0
                      children [
                        Transform {
                          translation 0 -0.06 0
                          children [
                            HingeJoint {
                              jointParameters HingeJointParameters {
                                axis 0 0 1
                                minStop -3
                                maxStop 3
                              }
                              endPoint Solid {
                                translation 0 -0.0925 0
                                rotation 0 0 1 0
                                children [
                                  DEF Arm-Seat Connector {
                                    translation 0 -0.092 0
                                    rotation 1 0 0 1.5708
                                    name "Arm-Seat"
                                    locked TRUE
                                    isLocked TRUE
                                    autoLock TRUE
                                    snap FALSE
                                  }
                                  Shape {
                                    appearance Appearance {
                                      material Material {
                                      }
                                    }
                                    geometry USE Side_Arm_3
                                  }
                                ]
                                boundingObject USE Side_Arm_3
                                physics USE Side_Arm_3_Phy
                              }
                            }
                          ]
                        }
                        Shape {
                          appearance Appearance {
                            material Material {
                            }
                          }
                          geometry USE Side_Arm_2
                        }
                      ]
                      boundingObject USE Side_Arm_2
                      physics USE Side_Arm_2_Phy
                    }
                  }
                ]
              }
              Shape {
                appearance Appearance {
                  material Material {
                  }
                }
                geometry USE Side_Arm_1
              }
            ]
            name "Left_Arm"
            boundingObject USE Side_Arm_1
            physics USE Side_Arm_1_Phy
          }
        }
      ]
    }
    DEF Top_Bar Shape {
      appearance Appearance {
        material Material {
        }
      }
      geometry DEF Top_Bar_Geometry Box {
        size 0.01 0.01 0.5
      }
    }
  ]
  name "Swing"
  boundingObject USE Top_Bar_Geometry
}
