#VRML_SIM V8.5 utf8
WorldInfo {
  info [
    "Aldebaran's Nao H25 V5.0"
    "Author: Yvan Bourquin - www.cyberbotics.com"
    "Date: 06 Feb 2012"
  ]
  title "Aldebaran Nao H25 V5.0"
  basicTimeStep 20
  FPS 20
  contactProperties [
    ContactProperties {
      material1 "NAO foot material"
      coulombFriction [
        7
      ]
      bounce 0.3
      bounceVelocity 0.003
    }
  ]
}
Viewpoint {
  orientation 0.0016827275 0.99898626 0.044984737 3.2162947
  position -0.14336646 0.37220157 -1.2746598
}
TexturedBackground {
}
TexturedBackgroundLight {
}
PointLight {
  ambientIntensity 1
  intensity 0.6
  location 2 0.9 0
}
Floor {
  size 25 25
  tileSize 0.8 0.8
  texture [
    "textures/checkered_marble.jpg"
  ]
}
Nao {
  translation 0.093536297 0.28511075 0.0031877919
  rotation -0.37796386 -0.65465515 -0.65465254 3.8643285
  controller "naoqisim"
  controllerArgs "9559"
  synchronization FALSE
}
DEF Swing Robot {
  translation 0 2 0
  children [
    DEF RArm Transform {
      translation 0 0 -0.25
      children [
        HingeJoint {
          jointParameters HingeJointParameters {
            axis 0 0 1
            minStop -3
            maxStop 3
          }
          endPoint Solid {
            translation 2.8623506e-09 -0.9075 0
            rotation 0 0 1 0
            children [
              Solid {
                translation 0 -0.9075 0.25
                children [
                  Solid {
                    translation -0.04 0.06 0
                    children [
                      Shape {
                        appearance Appearance {
                          material Material {
                          }
                        }
                        geometry DEF Robot_Holder Box {
                          size 0.01 0.01 0.5
                        }
                      }
                    ]
                    boundingObject USE Robot_Holder
                    physics Physics {
                      density -1
                      mass 1
                    }
                  }
                  Connector {
                    rotation 1 0 0 -1.5707997
                    name "Seat Robot"
                    locked TRUE
                    isLocked TRUE
                    autoLock TRUE
                    snap FALSE
                  }
                  Connector {
                    translation 0 0 0.25
                    rotation 1 0 0 -1.5707997
                    locked TRUE
                    isLocked TRUE
                    autoLock TRUE
                    snap FALSE
                  }
                  Shape {
                    appearance Appearance {
                      material Material {
                      }
                    }
                    geometry DEF Seat_Shape Box {
                      size 0.1 0.01 0.5
                    }
                  }
                ]
                boundingObject USE Seat_Shape
                physics Physics {
                  density -1
                  mass 1.6
                }
              }
              Shape {
                appearance Appearance {
                  material Material {
                  }
                }
                geometry DEF Side_Arm Box {
                  size 0.01 1.815 0.01
                }
              }
            ]
            name "RightArm"
            boundingObject USE Side_Arm
            physics DEF Side_Arm_Phy Physics {
              density -1
              mass 1.543
            }
          }
        }
      ]
    }
    DEF LArm Transform {
      translation 0 0 0.25
      children [
        HingeJoint {
          jointParameters DEF Joint_Params HingeJointParameters {
            axis 0 0 1
            anchor 0 0 1
            minStop -3
            maxStop 3
          }
          endPoint Solid {
            translation 2.8623506e-09 -0.9075 0
            rotation 0 0 1 0
            children [
              DEF Arm-Seat Connector {
                translation 0 -0.907 0
                rotation 1 0 0 1.5707997
                name "Arm-Seat-Connector"
                locked TRUE
                isLocked TRUE
                autoLock TRUE
                snap FALSE
              }
              Shape {
                appearance Appearance {
                  material Material {
                  }
                }
                geometry USE Side_Arm
              }
            ]
            name "Left_Arm"
            boundingObject USE Side_Arm
            physics USE Side_Arm_Phy
          }
        }
      ]
    }
    DEF Top_Bar Shape {
      appearance Appearance {
        material Material {
        }
      }
      geometry DEF Top_Bar_Geometry Box {
        size 0.01 0.01 0.5
      }
    }
  ]
  name "Swing"
  boundingObject USE Top_Bar_Geometry
}
