#VRML_SIM V8.5 utf8
WorldInfo {
  info [
    "Aldebaran's Nao H25 V5.0"
    "Author: Yvan Bourquin - www.cyberbotics.com"
    "Date: 06 Feb 2012"
  ]
  title "Aldebaran Nao H25 V5.0"
  basicTimeStep 20
  FPS 20
  contactProperties [
    ContactProperties {
      material1 "NAO foot material"
      coulombFriction [
        7
      ]
      bounce 0.3
      bounceVelocity 0.003
    }
  ]
}
Viewpoint {
  orientation -0.067159802 -0.98071701 -0.18353122 2.4524742
  position -1.5737539 1.42155 -2.2536357
}
TexturedBackground {
}
TexturedBackgroundLight {
}
PointLight {
  ambientIntensity 1
  intensity 0.6
  location 2 0.9 0
}
Floor {
  size 25 25
  tileSize 0.8 0.8
  texture [
    "/Users/hargwit/Documents/Robot Simulation/Webots/textures/checkered_marble.jpg"
  ]
}
Nao {
  translation 0.017555574 0.51743126 0.0031868612
  rotation -3.3376157e-08 -0.7071082 -0.70710537 3.1415927
  controller "naoqisim"
  controllerArgs "9559"
  synchronization FALSE
  bodySlot [
    DEF Robot-Seat Connector {
      translation 0 0 -0.325
      rotation 0 1 0 3.1415927
      name "Robot-Seat-Connector"
      locked TRUE
      isLocked TRUE
      autoLock TRUE
      distanceTolerance 0.1
      snap FALSE
    }
  ]
}
DEF Swing Robot {
  translation 0 2 0
  children [
    DEF RArm Transform {
      translation 0 0 -0.25
      children [
        HingeJoint {
          jointParameters HingeJointParameters {
            axis 0 0 1
            minStop -3
            maxStop 3
          }
          endPoint Solid {
            translation 2.8623506e-09 -0.9075 0
            rotation 0 0 1 0
            children [
              Transform {
                translation 0 -0.9075 0.25
                rotation 1 0 0 0
                children [
                  DEF Seat-Arm Connector {
                    translation 0 0 0.25
                    rotation 1 0 0 -1.5707997
                    name "Seat-Arm-Connector"
                    locked TRUE
                    isLocked TRUE
                    autoLock TRUE
                    distanceTolerance 0.1
                    axisTolerance 0
                    rotationTolerance 0
                    snap FALSE
                  }
                  DEF Seat-Robot Connector {
                    rotation 1 0 0 -1.5707997
                    name "Seat Connector"
                    locked TRUE
                    isLocked TRUE
                    autoLock TRUE
                    distanceTolerance 0.1
                    snap FALSE
                  }
                  Shape {
                    appearance Appearance {
                      material Material {
                      }
                    }
                    geometry DEF Seat_Shaoe Box {
                      size 0.1 0.01 0.5
                    }
                  }
                ]
              }
              Shape {
                appearance Appearance {
                  material Material {
                  }
                }
                geometry DEF Side_Arm Box {
                  size 0.01 1.815 0.01
                }
              }
            ]
            name "RightArm"
            boundingObject USE Side_Arm
            physics Physics {
              density -1
              mass 2
            }
          }
        }
      ]
    }
    DEF LArm Transform {
      translation 0 0 0.25
      children [
        HingeJoint {
          jointParameters HingeJointParameters {
            axis 0 0 1
            anchor 0 0 1
            minStop -3
            maxStop 3
          }
          endPoint Solid {
            translation 2.8623506e-09 -0.9075 0
            rotation 0 0 1 0
            children [
              DEF Arm-Seat Connector {
                translation 0 -0.907 0
                rotation 1 0 0 1.5707997
                name "Arm-Seat-Connector"
                locked TRUE
                isLocked TRUE
                autoLock TRUE
                snap FALSE
              }
              Shape {
                appearance Appearance {
                  material Material {
                  }
                }
                geometry USE Side_Arm
              }
            ]
            name "Left_Arm"
            boundingObject USE Side_Arm
            physics DEF Arm_Physics Physics {
              density -1
              mass 2
            }
          }
        }
      ]
    }
    DEF Top_Bar Shape {
      appearance Appearance {
        material Material {
        }
      }
      geometry DEF Top_Bar_Geometry Box {
        size 0.01 0.01 0.5
      }
    }
  ]
  name "Swing"
  boundingObject USE Top_Bar_Geometry
}
