#VRML_SIM V8.5 utf8
WorldInfo {
  info [
    "Aldebaran's Nao H25 V5.0"
    "Author: Yvan Bourquin - www.cyberbotics.com"
    "Date: 06 Feb 2012"
  ]
  title "Aldebaran Nao H25 V5.0"
  basicTimeStep 20
  FPS 20
  contactProperties [
    ContactProperties {
      material1 "NAO foot material"
      coulombFriction [
        7
      ]
      bounce 0.3
      bounceVelocity 0.003
    }
  ]
}
Viewpoint {
  orientation 0.79192239 0.60506592 0.082183713 5.9434619
  position 0.00093764504 2.380527 4.4805202
}
TexturedBackground {
}
TexturedBackgroundLight {
}
PointLight {
  ambientIntensity 1
  intensity 0.6
  location 2 0.9 0
}
Floor {
  size 25 25
  tileSize 0.8 0.8
  texture [
    "/Users/hargwit/Documents/Robot Simulation/Webots/textures/checkered_marble.jpg"
  ]
}
Nao {
  translation -3.7382001 0.90187342 0.0031852452
  rotation -0.37796386 -0.65465515 -0.65465254 3.8643285
  controller "naoqisim"
  controllerArgs "9559"
  synchronization FALSE
  bodySlot [
    DEF Robot-Seat Connector {
      translation -0.021213197 0 -0.080960121
      rotation 0 1 0 4.1887901
      name "Robot-Seat-Connector"
      locked TRUE
      isLocked TRUE
      autoLock TRUE
      distanceTolerance 0.1
      snap FALSE
    }
  ]
}
DEF Swing Robot {
  translation 0 2 0
  children [
    DEF RArm Transform {
      translation 0 0 -0.25
      children [
        HingeJoint {
          jointParameters HingeJointParameters {
            position 1
            axis 0 0 1
            minStop -3
            maxStop 3
          }
          endPoint Solid {
            translation 0.76363492 -0.49032434 0
            rotation 0 0 1 1
            children [
              Solid {
                translation 0 -0.9075 0.25
                children [
                  Connector {
                    rotation 1 0 0 -1.5707997
                    name "Seat Robot"
                    locked TRUE
                    isLocked TRUE
                    autoLock TRUE
                    snap FALSE
                  }
                  Connector {
                    translation 0 0 0.25
                    rotation 1 0 0 -1.5707997
                    locked TRUE
                    isLocked TRUE
                    autoLock TRUE
                    snap FALSE
                  }
                  Shape {
                    appearance Appearance {
                      material Material {
                      }
                    }
                    geometry DEF Seat_Shape Box {
                      size 0.1 0.01 0.5
                    }
                  }
                ]
                boundingObject USE Seat_Shape
                physics Physics {
                  density -1
                  mass 2
                }
              }
              Shape {
                appearance Appearance {
                  material Material {
                  }
                }
                geometry DEF Side_Arm Box {
                  size 0.01 1.815 0.01
                }
              }
            ]
            name "RightArm"
            boundingObject USE Side_Arm
            physics Physics {
              density -1
              mass 2
            }
          }
        }
      ]
    }
    DEF LArm Transform {
      translation 0 0 0.25
      children [
        HingeJoint {
          jointParameters DEF Joint_Params HingeJointParameters {
            position 1
            axis 0 0 1
            anchor 0 0 1
            minStop -3
            maxStop 3
          }
          endPoint Solid {
            translation 0.76363492 -0.49032434 0
            rotation 0 0 1 1
            children [
              DEF Arm-Seat Connector {
                translation 0 -0.907 0
                rotation 1 0 0 1.5707997
                name "Arm-Seat-Connector"
                locked TRUE
                isLocked TRUE
                autoLock TRUE
                snap FALSE
              }
              Shape {
                appearance Appearance {
                  material Material {
                  }
                }
                geometry USE Side_Arm
              }
            ]
            name "Left_Arm"
            boundingObject USE Side_Arm
            physics DEF Arm_Physics Physics {
              density -1
              mass 2
            }
          }
        }
      ]
    }
    DEF Top_Bar Shape {
      appearance Appearance {
        material Material {
        }
      }
      geometry DEF Top_Bar_Geometry Box {
        size 0.01 0.01 0.5
      }
    }
  ]
  name "Swing"
  boundingObject USE Top_Bar_Geometry
}
